Workbook

Sheet _viitearvot
A1: ikäluokka | B1: sukupuoli | C1: testi | D1: taso5 | E1: taso4 | F1: taso3 | G1: taso2 | H1: taso1 | I1: avain | J1: t5_lookup | K1: t4_lookup | L1: t3_lookup | M1: t2_lookup
A2: P10 | B2: P | C2: lin5m | D2: 1.08 | E2: 1.11 | F2: 1.14 | G2: 1.18 | H2: 99 | I2: P10lin5m | J2: 1.08 | K2: 1.11 | L2: 1.14 | M2: 1.18
A3: P11 | B3: P | C3: lin5m | D3: 1.05 | E3: 1.09 | F3: 1.11 | G3: 1.15 | H3: 99 | I3: P11lin5m | J3: 1.05 | K3: 1.09 | L3: 1.11 | M3: 1.15
A4: P12 | B4: P | C4: lin5m | D4: 1.02 | E4: 1.05 | F4: 1.08 | G4: 1.12 | H4: 99 | I4: P12lin5m | J4: 1.02 | K4: 1.05 | L4: 1.08 | M4: 1.12
A5: P13 | B5: P | C5: lin5m | D5: 0.99 | E5: 1.02 | F5: 1.05 | G5: 1.09 | H5: 99 | I5: P13lin5m | J5: 0.99 | K5: 1.02 | L5: 1.05 | M5: 1.09
A6: P14 | B6: P | C6: lin5m | D6: 0.96 | E6: 0.99 | F6: 1.01 | G6: 1.05 | H6: 99 | I6: P14lin5m | J6: 0.96 | K6: 0.99 | L6: 1.01 | M6: 1.05
A7: P15 | B7: P | C7: lin5m | D7: 0.94 | E7: 0.97 | F7: 0.99 | G7: 1.03 | H7: 99 | I7: P15lin5m | J7: 0.94 | K7: 0.97 | L7: 0.99 | M7: 1.03
A8: P16 | B8: P | C8: lin5m | D8: 0.92 | E8: 0.95 | F8: 0.97 | G8: 1.01 | H8: 99 | I8: P16lin5m | J8: 0.92 | K8: 0.95 | L8: 0.97 | M8: 1.01
A9: P17 | B9: P | C9: lin5m | D9: 0.9 | E9: 0.93 | F9: 0.95 | G9: 0.99 | H9: 99 | I9: P17lin5m | J9: 0.9 | K9: 0.93 | L9: 0.95 | M9: 0.99
A10: P18 | B10: P | C10: lin5m | D10: 0.88 | E10: 0.91 | F10: 0.93 | G10: 0.97 | H10: 99 | I10: P18lin5m | J10: 0.88 | K10: 0.91 | L10: 0.93 | M10: 0.97
A11: P19 | B11: P | C11: lin5m | D11: 0.87 | E11: 0.89 | F11: 0.91 | G11: 0.95 | H11: 99 | I11: P19lin5m | J11: 0.87 | K11: 0.89 | L11: 0.91 | M11: 0.95
A12: P10 | B12: P | C12: lin10m | D12: 1.92 | E12: 1.97 | F12: 2.02 | G12: 2.08 | H12: 99 | I12: P10lin10m | J12: 1.92 | K12: 1.97 | L12: 2.02 | M12: 2.08
A13: P11 | B13: P | C13: lin10m | D13: 1.88 | E13: 1.93 | F13: 1.97 | G13: 2.02 | H13: 99 | I13: P11lin10m | J13: 1.88 | K13: 1.93 | L13: 1.97 | M13: 2.02
... A205: T15 | B205: T | C205: syotto | D205: 32.8 | E205: 38.5 | F205: 99 | G205: 99 | H205: 99 | I205: T15syotto | J205: 32.8 | K205: 38.5 | L205: 99 | M205: 99

Sheet H-H Testit
A1: TalentMaster™ — H-H-polun fyysistekniset testit (Eerikkilä/Palloliitto 2024) | AC = Bio-ikä → biologinen taso | AD = Taso-ero (bio - krono)
A2: 🔵 Pakollinen 🟢 Testitulos 🟡 Taso (krono, automaattinen) 🔵 AC: Bio-ikä (syötä Mirwald-pohjasta) 🟢 AD: Taso-ero bio vs krono
A3: Taso-ero (AD): +1 tai +2 = pelaaja suoriutuu yli oman ikätasonsa biologiseen ikään suhteutettuna. -1 tai -2 = suoriutuu alle. Positiivinen luku kertoo lahjakkuudesta suhteessa kehitysvaiheeseen.
A4: PalloID * | B4: Nimi * | C4: Syntymäaika * | D4: Sukupuoli * | E4: Joukkue * | F4: Testauspvm * | G4: Arvioija | H4: 5m (s) | I4: 10m (s) | J4: 20m (s) | K4: 30m (s) | L4: Kasirata (s) | M4: SM-juoksu (s) | N4: SM-pallo (s) | O4: CMJ (cm) | P4: Bronco (m/s) | Q4: Pujottelu (s) | R4: Syöttö (s) | S4: Taso 5m | T4: Taso 10m | U4: Taso 20m | V4: Taso 30m | W4: Taso Kasi | X4: Taso SM-j | Y4: Taso SM-p | Z4: Taso CMJ | AA4: Taso Bronco | AB4: Huomio | AC4: Bio-ikä (syötä tai auto) | AD4: Taso-ero (bio-krono)
S5: =IF(OR(H5="",D5=""),"",IF(H5<=IFERROR(VLOOKUP(CONCATENATE(D5,YEAR(TODAY())-YEAR(C5),"lin5m"),_viitearvot!$I$2:$M$205,2,FALSE()),99),5,IF(H5<=IFERROR(VLOOKUP(CONCATENATE(D5,YEAR(TODAY())-YEAR(C5),"lin5m"),_viitearvot!$I$2:$M$205,3,FALSE()),99),4,IF(H5<=IFERROR(VLOOKUP(CONCATENATE(D5,YEAR(TODAY())-YEAR(C5),"lin5m"),_viitearvot!$I$2:$M$205,4,FALSE()),99),3,IF(H5<=IFERROR(VLOOKUP(CONCATENATE(D5,YEAR(TODAY())-YEAR(C5),"lin5m"),_viitearvot!$I$2:$M$205,5,FALSE()),99),2,1))))) | T5: =IF(OR(I5="",D5=""),"",IF(I5<=IFERROR(VLOOKUP(CONCATENATE(D5,YEAR(TODAY())-YEAR(C5),"lin10m"),_viitearvot!$I$2:$M$205,2,FALSE()),99),5,IF(I5<=IFERROR(VLOOKUP(CONCATENATE(D5,YEAR(TODAY())-YEAR(C5),"lin10m"),_viitearvot!$I$2:$M$205,3,FALSE()),99),4,IF(I5<=IFERROR(VLOOKUP(CONCATENATE(D5,YEAR(TODAY())-YEAR(C5),"lin10m"),_viitearvot!$I$2:$M$205,4,FALSE()),99),3,IF(I5<=IFERROR(VLOOKUP(CONCATENATE(D5,YEAR(TODAY())-YEAR(C5),"lin10m"),_viitearvot!$I$2:$M$205,5,FALSE()),99),2,1))))) | U5: =IF(OR(J5="",D5=""),"",IF(J5<=IFERROR(VLOOKUP(CONCATENATE(D5,YEAR(TODAY())-YEAR(C5),"lin20m"),_viitearvot!$I$2:$M$205,2,FALSE()),99),5,IF(J5<=IFERROR(VLOOKUP(CONCATENATE(D5,YEAR(TODAY())-YEAR(C5),"lin20m"),_viitearvot!$I$2:$M$205,3,FALSE()),99),4,IF(J5<=IFERROR(VLOOKUP(CONCATENATE(D5,YEAR(TODAY())-YEAR(C5),"lin20m"),_viitearvot!$I$2:$M$205,4,FALSE()),99),3,IF(J5<=IFERROR(VLOOKUP(CONCATENATE(D5,YEAR(TODAY())-YEAR(C5),"lin20m"),_viitearvot!$I$2:$M$205,5,FALSE()),99),2,1))))) | V5: =IF(OR(K5="",D5=""),"",IF(K5<=IFERROR(VLOOKUP(CONCATENATE(D5,YEAR(TODAY())-YEAR(C5),"lin30m"),_viitearvot!$I$2:$M$205,2,FALSE()),99),5,IF(K5<=IFERROR(VLOOKUP(CONCATENATE(D5,YEAR(TODAY())-YEAR(C5),"lin30m"),_viitearvot!$I$2:$M$205,3,FALSE()),99),4,IF(K5<=IFERROR(VLOOKUP(CONCATENATE(D5,YEAR(TODAY())-YEAR(C5),"lin30m"),_viitearvot!$I$2:$M$205,4,FALSE()),99),3,IF(K5<=IFERROR(VLOOKUP(CONCATENATE(D5,YEAR(TODAY())-YEAR(C5),"lin30m"),_viitearvot!$I$2:$M$205,5,FALSE()),99),2,1))))) | W5: =IF(OR(L5="",D5=""),"",IF(L5<=IFERROR(VLOOKUP(CONCATENATE(D5,YEAR(TODAY())-YEAR(C5),"kasirata"),_viitearvot!$I$2:$M$205,2,FALSE()),99),5,IF(L5<=IFERROR(VLOOKUP(CONCATENATE(D5,YEAR(TODAY())-YEAR(C5),"kasirata"),_viitearvot!$I$2:$M$205,3,FALSE()),99),4,IF(L5<=IFERROR(VLOOKUP(CONCATENATE(D5,YEAR(TODAY())-YEAR(C5),"kasirata"),_viitearvot!$I$2:$M$205,4,FALSE()),99),3,IF(L5<=IFERROR(VLOOKUP(CONCATENATE(D5,YEAR(TODAY())-YEAR(C5),"kasirata"),_viitearvot!$I$2:$M$205,5,FALSE()),99),2,1))))) | X5: =IF(OR(M5="",D5=""),"",IF(M5<=IFERROR(VLOOKUP(CONCATENATE(D5,YEAR(TODAY())-YEAR(C5),"smjuoksu"),_viitearvot!$I$2:$M$205,2,FALSE()),99),5,IF(M5<=IFERROR(VLOOKUP(CONCATENATE(D5,YEAR(TODAY())-YEAR(C5),"smjuoksu"),_viitearvot!$I$2:$M$205,3,FALSE()),99),4,IF(M5<=IFERROR(VLOOKUP(CONCATENATE(D5,YEAR(TODAY())-YEAR(C5),"smjuoksu"),_viitearvot!$I$2:$M$205,4,FALSE()),99),3,IF(M5<=IFERROR(VLOOKUP(CONCATENATE(D5,YEAR(TODAY())-YEAR(C5),"smjuoksu"),_viitearvot!$I$2:$M$205,5,FALSE()),99),2,1))))) | Y5: =IF(OR(N5="",D5=""),"",IF(N5<=IFERROR(VLOOKUP(CONCATENATE(D5,YEAR(TODAY())-YEAR(C5),"smpallo"),_viitearvot!$I$2:$M$205,2,FALSE()),99),5,IF(N5<=IFERROR(VLOOKUP(CONCATENATE(D5,YEAR(TODAY())-YEAR(C5),"smpallo"),_viitearvot!$I$2:$M$205,3,FALSE()),99),4,IF(N5<=IFERROR(VLOOKUP(CONCATENATE(D5,YEAR(TODAY())-YEAR(C5),"smpallo"),_viitearvot!$I$2:$M$205,4,FALSE()),99),3,IF(N5<=IFERROR(VLOOKUP(CONCATENATE(D5,YEAR(TODAY())-YEAR(C5),"smpallo"),_viitearvot!$I$2:$M$205,5,FALSE()),99),2,1))))) | Z5: =IF(OR(O5="",D5=""),"",IF(O5>=IFERROR(VLOOKUP(CONCATENATE(D5,YEAR(TODAY())-YEAR(C5),"cmj"),_viitearvot!$I$2:$M$205,2,FALSE()),0),5,IF(O5>=IFERROR(VLOOKUP(CONCATENATE(D5,YEAR(TODAY())-YEAR(C5),"cmj"),_viitearvot!$I$2:$M$205,3,FALSE()),0),4,IF(O5>=IFERROR(VLOOKUP(CONCATENATE(D5,YEAR(TODAY())-YEAR(C5),"cmj"),_viitearvot!$I$2:$M$205,4,FALSE()),0),3,IF(O5>=IFERROR(VLOOKUP(CONCATENATE(D5,YEAR(TODAY())-YEAR(C5),"cmj"),_viitearvot!$I$2:$M$205,5,FALSE()),0),2,1))))) | AA5: =IF(OR(P5="",D5=""),"",IF(P5>=IFERROR(VLOOKUP(CONCATENATE(D5,YEAR(TODAY())-YEAR(C5),"bronco"),_viitearvot!$I$2:$M$205,2,FALSE()),0),5,IF(P5>=IFERROR(VLOOKUP(CONCATENATE(D5,YEAR(TODAY())-YEAR(C5),"bronco"),_viitearvot!$I$2:$M$205,3,FALSE()),0),4,IF(P5>=IFERROR(VLOOKUP(CONCATENATE(D5,YEAR(TODAY())-YEAR(C5),"bronco"),_viitearvot!$I$2:$M$205,4,FALSE()),0),3,IF(P5>=IFERROR(VLOOKUP(CONCATENATE(D5,YEAR(TODAY())-YEAR(C5),"bronco"),_viitearvot!$I$2:$M$205,5,FALSE()),0),2,1))))) | AD5: =IF(OR(AC5="",H5=""),"",(IF(D5="P",IF(H5<=IFERROR(VLOOKUP(CONCATENATE("P",ROUND(AC5,0),"lin5m"),_viitearvot!$A:$H,4,FALSE()),99),5,IF(H5<=IFERROR(VLOOKUP(CONCATENATE("P",ROUND(AC5,0),"lin5m"),_viitearvot!$A:$H,5,FALSE()),99),4,IF(H5<=IFERROR(VLOOKUP(CONCATENATE("P",ROUND(AC5,0),"lin5m"),_viitearvot!$A:$H,6,FALSE()),99),3,IF(H5<=IFERROR(VLOOKUP(CONCATENATE("P",ROUND(AC5,0),"lin5m"),_viitearvot!$A:$H,7,FALSE()),99),2,1)))),IF(H5<=IFERROR(VLOOKUP(CONCATENATE("T",ROUND(AC5,0),"lin5m"),_viitearvot!$A:$H,4,FALSE()),99),5,IF(H5<=IFERROR(VLOOKUP(CONCATENATE("T",ROUND(AC5,0),"lin5m"),_viitearvot!$A:$H,5,FALSE()),99),4,IF(H5<=IFERROR(VLOOKUP(CONCATENATE("T",ROUND(AC5,0),"lin5m"),_viitearvot!$A:$H,6,FALSE()),99),3,IF(H5<=IFERROR(VLOOKUP(CONCATENATE("T",ROUND(AC5,0),"lin5m"),_viitearvot!$A:$H,7,FALSE()),99),2,1)))))-S5))
S6: =IF(OR(H6="",D6=""),"",IF(H6<=IFERROR(VLOOKUP(CONCATENATE(D6,YEAR(TODAY())-YEAR(C6),"lin5m"),_viitearvot!$I$2:$M$205,2,FALSE()),99),5,IF(H6<=IFERROR(VLOOKUP(CONCATENATE(D6,YEAR(TODAY())-YEAR(C6),"lin5m"),_viitearvot!$I$2:$M$205,3,FALSE()),99),4,IF(H6<=IFERROR(VLOOKUP(CONCATENATE(D6,YEAR(TODAY())-YEAR(C6),"lin5m"),_viitearvot!$I$2:$M$205,4,FALSE()),99),3,IF(H6<=IFERROR(VLOOKUP(CONCATENATE(D6,YEAR(TODAY())-YEAR(C6),"lin5m"),_viitearvot!$I$2:$M$205,5,FALSE()),99),2,1))))) | T6: =IF(OR(I6="",D6=""),"",IF(I6<=IFERROR(VLOOKUP(CONCATENATE(D6,YEAR(TODAY())-YEAR(C6),"lin10m"),_viitearvot!$I$2:$M$205,2,FALSE()),99),5,IF(I6<=IFERROR(VLOOKUP(CONCATENATE(D6,YEAR(TODAY())-YEAR(C6),"lin10m"),_viitearvot!$I$2:$M$205,3,FALSE()),99),4,IF(I6<=IFERROR(VLOOKUP(CONCATENATE(D6,YEAR(TODAY())-YEAR(C6),"lin10m"),_viitearvot!$I$2:$M$205,4,FALSE()),99),3,IF(I6<=IFERROR(VLOOKUP(CONCATENATE(D6,YEAR(TODAY())-YEAR(C6),"lin10m"),_viitearvot!$I$2:$M$205,5,FALSE()),99),2,1))))) | U6: =IF(OR(J6="",D6=""),"",IF(J6<=IFERROR(VLOOKUP(CONCATENATE(D6,YEAR(TODAY())-YEAR(C6),"lin20m"),_viitearvot!$I$2:$M$205,2,FALSE()),99),5,IF(J6<=IFERROR(VLOOKUP(CONCATENATE(D6,YEAR(TODAY())-YEAR(C6),"lin20m"),_viitearvot!$I$2:$M$205,3,FALSE()),99),4,IF(J6<=IFERROR(VLOOKUP(CONCATENATE(D6,YEAR(TODAY())-YEAR(C6),"lin20m"),_viitearvot!$I$2:$M$205,4,FALSE()),99),3,IF(J6<=IFERROR(VLOOKUP(CONCATENATE(D6,YEAR(TODAY())-YEAR(C6),"lin20m"),_viitearvot!$I$2:$M$205,5,FALSE()),99),2,1))))) | V6: =IF(OR(K6="",D6=""),"",IF(K6<=IFERROR(VLOOKUP(CONCATENATE(D6,YEAR(TODAY())-YEAR(C6),"lin30m"),_viitearvot!$I$2:$M$205,2,FALSE()),99),5,IF(K6<=IFERROR(VLOOKUP(CONCATENATE(D6,YEAR(TODAY())-YEAR(C6),"lin30m"),_viitearvot!$I$2:$M$205,3,FALSE()),99),4,IF(K6<=IFERROR(VLOOKUP(CONCATENATE(D6,YEAR(TODAY())-YEAR(C6),"lin30m"),_viitearvot!$I$2:$M$205,4,FALSE()),99),3,IF(K6<=IFERROR(VLOOKUP(CONCATENATE(D6,YEAR(TODAY())-YEAR(C6),"lin30m"),_viitearvot!$I$2:$M$205,5,FALSE()),99),2,1))))) | W6: =IF(OR(L6="",D6=""),"",IF(L6<=IFERROR(VLOOKUP(CONCATENATE(D6,YEAR(TODAY())-YEAR(C6),"kasirata"),_viitearvot!$I$2:$M$205,2,FALSE()),99),5,IF(L6<=IFERROR(VLOOKUP(CONCATENATE(D6,YEAR(TODAY())-YEAR(C6),"kasirata"),_viitearvot!$I$2:$M$205,3,FALSE()),99),4,IF(L6<=IFERROR(VLOOKUP(CONCATENATE(D6,YEAR(TODAY())-YEAR(C6),"kasirata"),_viitearvot!$I$2:$M$205,4,FALSE()),99),3,IF(L6<=IFERROR(VLOOKUP(CONCATENATE(D6,YEAR(TODAY())-YEAR(C6),"kasirata"),_viitearvot!$I$2:$M$205,5,FALSE()),99),2,1))))) | X6: =IF(OR(M6="",D6=""),"",IF(M6<=IFERROR(VLOOKUP(CONCATENATE(D6,YEAR(TODAY())-YEAR(C6),"smjuoksu"),_viitearvot!$I$2:$M$205,2,FALSE()),99),5,IF(M6<=IFERROR(VLOOKUP(CONCATENATE(D6,YEAR(TODAY())-YEAR(C6),"smjuoksu"),_viitearvot!$I$2:$M$205,3,FALSE()),99),4,IF(M6<=IFERROR(VLOOKUP(CONCATENATE(D6,YEAR(TODAY())-YEAR(C6),"smjuoksu"),_viitearvot!$I$2:$M$205,4,FALSE()),99),3,IF(M6<=IFERROR(VLOOKUP(CONCATENATE(D6,YEAR(TODAY())-YEAR(C6),"smjuoksu"),_viitearvot!$I$2:$M$205,5,FALSE()),99),2,1))))) | Y6: =IF(OR(N6="",D6=""),"",IF(N6<=IFERROR(VLOOKUP(CONCATENATE(D6,YEAR(TODAY())-YEAR(C6),"smpallo"),_viitearvot!$I$2:$M$205,2,FALSE()),99),5,IF(N6<=IFERROR(VLOOKUP(CONCATENATE(D6,YEAR(TODAY())-YEAR(C6),"smpallo"),_viitearvot!$I$2:$M$205,3,FALSE()),99),4,IF(N6<=IFERROR(VLOOKUP(CONCATENATE(D6,YEAR(TODAY())-YEAR(C6),"smpallo"),_viitearvot!$I$2:$M$205,4,FALSE()),99),3,IF(N6<=IFERROR(VLOOKUP(CONCATENATE(D6,YEAR(TODAY())-YEAR(C6),"smpallo"),_viitearvot!$I$2:$M$205,5,FALSE()),99),2,1))))) | Z6: =IF(OR(O6="",D6=""),"",IF(O6>=IFERROR(VLOOKUP(CONCATENATE(D6,YEAR(TODAY())-YEAR(C6),"cmj"),_viitearvot!$I$2:$M$205,2,FALSE()),0),5,IF(O6>=IFERROR(VLOOKUP(CONCATENATE(D6,YEAR(TODAY())-YEAR(C6),"cmj"),_viitearvot!$I$2:$M$205,3,FALSE()),0),4,IF(O6>=IFERROR(VLOOKUP(CONCATENATE(D6,YEAR(TODAY())-YEAR(C6),"cmj"),_viitearvot!$I$2:$M$205,4,FALSE()),0),3,IF(O6>=IFERROR(VLOOKUP(CONCATENATE(D6,YEAR(TODAY())-YEAR(C6),"cmj"),_viitearvot!$I$2:$M$205,5,FALSE()),0),2,1))))) | AA6: =IF(OR(P6="",D6=""),"",IF(P6>=IFERROR(VLOOKUP(CONCATENATE(D6,YEAR(TODAY())-YEAR(C6),"bronco"),_viitearvot!$I$2:$M$205,2,FALSE()),0),5,IF(P6>=IFERROR(VLOOKUP(CONCATENATE(D6,YEAR(TODAY())-YEAR(C6),"bronco"),_viitearvot!$I$2:$M$205,3,FALSE()),0),4,IF(P6>=IFERROR(VLOOKUP(CONCATENATE(D6,YEAR(TODAY())-YEAR(C6),"bronco"),_viitearvot!$I$2:$M$205,4,FALSE()),0),3,IF(P6>=IFERROR(VLOOKUP(CONCATENATE(D6,YEAR(TODAY())-YEAR(C6),"bronco"),_viitearvot!$I$2:$M$205,5,FALSE()),0),2,1))))) | AD6: =IF(OR(AC6="",H6=""),"",(IF(D6="P",IF(H6<=IFERROR(VLOOKUP(CONCATENATE("P",ROUND(AC6,0),"lin5m"),_viitearvot!$A:$H,4,FALSE()),99),5,IF(H6<=IFERROR(VLOOKUP(CONCATENATE("P",ROUND(AC6,0),"lin5m"),_viitearvot!$A:$H,5,FALSE()),99),4,IF(H6<=IFERROR(VLOOKUP(CONCATENATE("P",ROUND(AC6,0),"lin5m"),_viitearvot!$A:$H,6,FALSE()),99),3,IF(H6<=IFERROR(VLOOKUP(CONCATENATE("P",ROUND(AC6,0),"lin5m"),_viitearvot!$A:$H,7,FALSE()),99),2,1)))),IF(H6<=IFERROR(VLOOKUP(CONCATENATE("T",ROUND(AC6,0),"lin5m"),_viitearvot!$A:$H,4,FALSE()),99),5,IF(H6<=IFERROR(VLOOKUP(CONCATENATE("T",ROUND(AC6,0),"lin5m"),_viitearvot!$A:$H,5,FALSE()),99),4,IF(H6<=IFERROR(VLOOKUP(CONCATENATE("T",ROUND(AC6,0),"lin5m"),_viitearvot!$A:$H,6,FALSE()),99),3,IF(H6<=IFERROR(VLOOKUP(CONCATENATE("T",ROUND(AC6,0),"lin5m"),_viitearvot!$A:$H,7,FALSE()),99),2,1)))))-S6))
S7: =IF(OR(H7="",D7=""),"",IF(H7<=IFERROR(VLOOKUP(CONCATENATE(D7,YEAR(TODAY())-YEAR(C7),"lin5m"),_viitearvot!$I$2:$M$205,2,FALSE()),99),5,IF(H7<=IFERROR(VLOOKUP(CONCATENATE(D7,YEAR(TODAY())-YEAR(C7),"lin5m"),_viitearvot!$I$2:$M$205,3,FALSE()),99),4,IF(H7<=IFERROR(VLOOKUP(CONCATENATE(D7,YEAR(TODAY())-YEAR(C7),"lin5m"),_viitearvot!$I$2:$M$205,4,FALSE()),99),3,IF(H7<=IFERROR(VLOOKUP(CONCATENATE(D7,YEAR(TODAY())-YEAR(C7),"lin5m"),_viitearvot!$I$2:$M$205,5,FALSE()),99),2,1))))) | T7: =IF(OR(I7="",D7=""),"",IF(I7<=IFERROR(VLOOKUP(CONCATENATE(D7,YEAR(TODAY())-YEAR(C7),"lin10m"),_viitearvot!$I$2:$M$205,2,FALSE()),99),5,IF(I7<=IFERROR(VLOOKUP(CONCATENATE(D7,YEAR(TODAY())-YEAR(C7),"lin10m"),_viitearvot!$I$2:$M$205,3,FALSE()),99),4,IF(I7<=IFERROR(VLOOKUP(CONCATENATE(D7,YEAR(TODAY())-YEAR(C7),"lin10m"),_viitearvot!$I$2:$M$205,4,FALSE()),99),3,IF(I7<=IFERROR(VLOOKUP(CONCATENATE(D7,YEAR(TODAY())-YEAR(C7),"lin10m"),_viitearvot!$I$2:$M$205,5,FALSE()),99),2,1))))) | U7: =IF(OR(J7="",D7=""),"",IF(J7<=IFERROR(VLOOKUP(CONCATENATE(D7,YEAR(TODAY())-YEAR(C7),"lin20m"),_viitearvot!$I$2:$M$205,2,FALSE()),99),5,IF(J7<=IFERROR(VLOOKUP(CONCATENATE(D7,YEAR(TODAY())-YEAR(C7),"lin20m"),_viitearvot!$I$2:$M$205,3,FALSE()),99),4,IF(J7<=IFERROR(VLOOKUP(CONCATENATE(D7,YEAR(TODAY())-YEAR(C7),"lin20m"),_viitearvot!$I$2:$M$205,4,FALSE()),99),3,IF(J7<=IFERROR(VLOOKUP(CONCATENATE(D7,YEAR(TODAY())-YEAR(C7),"lin20m"),_viitearvot!$I$2:$M$205,5,FALSE()),99),2,1))))) | V7: =IF(OR(K7="",D7=""),"",IF(K7<=IFERROR(VLOOKUP(CONCATENATE(D7,YEAR(TODAY())-YEAR(C7),"lin30m"),_viitearvot!$I$2:$M$205,2,FALSE()),99),5,IF(K7<=IFERROR(VLOOKUP(CONCATENATE(D7,YEAR(TODAY())-YEAR(C7),"lin30m"),_viitearvot!$I$2:$M$205,3,FALSE()),99),4,IF(K7<=IFERROR(VLOOKUP(CONCATENATE(D7,YEAR(TODAY())-YEAR(C7),"lin30m"),_viitearvot!$I$2:$M$205,4,FALSE()),99),3,IF(K7<=IFERROR(VLOOKUP(CONCATENATE(D7,YEAR(TODAY())-YEAR(C7),"lin30m"),_viitearvot!$I$2:$M$205,5,FALSE()),99),2,1))))) | W7: =IF(OR(L7="",D7=""),"",IF(L7<=IFERROR(VLOOKUP(CONCATENATE(D7,YEAR(TODAY())-YEAR(C7),"kasirata"),_viitearvot!$I$2:$M$205,2,FALSE()),99),5,IF(L7<=IFERROR(VLOOKUP(CONCATENATE(D7,YEAR(TODAY())-YEAR(C7),"kasirata"),_viitearvot!$I$2:$M$205,3,FALSE()),99),4,IF(L7<=IFERROR(VLOOKUP(CONCATENATE(D7,YEAR(TODAY())-YEAR(C7),"kasirata"),_viitearvot!$I$2:$M$205,4,FALSE()),99),3,IF(L7<=IFERROR(VLOOKUP(CONCATENATE(D7,YEAR(TODAY())-YEAR(C7),"kasirata"),_viitearvot!$I$2:$M$205,5,FALSE()),99),2,1))))) | X7: =IF(OR(M7="",D7=""),"",IF(M7<=IFERROR(VLOOKUP(CONCATENATE(D7,YEAR(TODAY())-YEAR(C7),"smjuoksu"),_viitearvot!$I$2:$M$205,2,FALSE()),99),5,IF(M7<=IFERROR(VLOOKUP(CONCATENATE(D7,YEAR(TODAY())-YEAR(C7),"smjuoksu"),_viitearvot!$I$2:$M$205,3,FALSE()),99),4,IF(M7<=IFERROR(VLOOKUP(CONCATENATE(D7,YEAR(TODAY())-YEAR(C7),"smjuoksu"),_viitearvot!$I$2:$M$205,4,FALSE()),99),3,IF(M7<=IFERROR(VLOOKUP(CONCATENATE(D7,YEAR(TODAY())-YEAR(C7),"smjuoksu"),_viitearvot!$I$2:$M$205,5,FALSE()),99),2,1))))) | Y7: =IF(OR(N7="",D7=""),"",IF(N7<=IFERROR(VLOOKUP(CONCATENATE(D7,YEAR(TODAY())-YEAR(C7),"smpallo"),_viitearvot!$I$2:$M$205,2,FALSE()),99),5,IF(N7<=IFERROR(VLOOKUP(CONCATENATE(D7,YEAR(TODAY())-YEAR(C7),"smpallo"),_viitearvot!$I$2:$M$205,3,FALSE()),99),4,IF(N7<=IFERROR(VLOOKUP(CONCATENATE(D7,YEAR(TODAY())-YEAR(C7),"smpallo"),_viitearvot!$I$2:$M$205,4,FALSE()),99),3,IF(N7<=IFERROR(VLOOKUP(CONCATENATE(D7,YEAR(TODAY())-YEAR(C7),"smpallo"),_viitearvot!$I$2:$M$205,5,FALSE()),99),2,1))))) | Z7: =IF(OR(O7="",D7=""),"",IF(O7>=IFERROR(VLOOKUP(CONCATENATE(D7,YEAR(TODAY())-YEAR(C7),"cmj"),_viitearvot!$I$2:$M$205,2,FALSE()),0),5,IF(O7>=IFERROR(VLOOKUP(CONCATENATE(D7,YEAR(TODAY())-YEAR(C7),"cmj"),_viitearvot!$I$2:$M$205,3,FALSE()),0),4,IF(O7>=IFERROR(VLOOKUP(CONCATENATE(D7,YEAR(TODAY())-YEAR(C7),"cmj"),_viitearvot!$I$2:$M$205,4,FALSE()),0),3,IF(O7>=IFERROR(VLOOKUP(CONCATENATE(D7,YEAR(TODAY())-YEAR(C7),"cmj"),_viitearvot!$I$2:$M$205,5,FALSE()),0),2,1))))) | AA7: =IF(OR(P7="",D7=""),"",IF(P7>=IFERROR(VLOOKUP(CONCATENATE(D7,YEAR(TODAY())-YEAR(C7),"bronco"),_viitearvot!$I$2:$M$205,2,FALSE()),0),5,IF(P7>=IFERROR(VLOOKUP(CONCATENATE(D7,YEAR(TODAY())-YEAR(C7),"bronco"),_viitearvot!$I$2:$M$205,3,FALSE()),0),4,IF(P7>=IFERROR(VLOOKUP(CONCATENATE(D7,YEAR(TODAY())-YEAR(C7),"bronco"),_viitearvot!$I$2:$M$205,4,FALSE()),0),3,IF(P7>=IFERROR(VLOOKUP(CONCATENATE(D7,YEAR(TODAY())-YEAR(C7),"bronco"),_viitearvot!$I$2:$M$205,5,FALSE()),0),2,1))))) | AD7: =IF(OR(AC7="",H7=""),"",(IF(D7="P",IF(H7<=IFERROR(VLOOKUP(CONCATENATE("P",ROUND(AC7,0),"lin5m"),_viitearvot!$A:$H,4,FALSE()),99),5,IF(H7<=IFERROR(VLOOKUP(CONCATENATE("P",ROUND(AC7,0),"lin5m"),_viitearvot!$A:$H,5,FALSE()),99),4,IF(H7<=IFERROR(VLOOKUP(CONCATENATE("P",ROUND(AC7,0),"lin5m"),_viitearvot!$A:$H,6,FALSE()),99),3,IF(H7<=IFERROR(VLOOKUP(CONCATENATE("P",ROUND(AC7,0),"lin5m"),_viitearvot!$A:$H,7,FALSE()),99),2,1)))),IF(H7<=IFERROR(VLOOKUP(CONCATENATE("T",ROUND(AC7,0),"lin5m"),_viitearvot!$A:$H,4,FALSE()),99),5,IF(H7<=IFERROR(VLOOKUP(CONCATENATE("T",ROUND(AC7,0),"lin5m"),_viitearvot!$A:$H,5,FALSE()),99),4,IF(H7<=IFERROR(VLOOKUP(CONCATENATE("T",ROUND(AC7,0),"lin5m"),_viitearvot!$A:$H,6,FALSE()),99),3,IF(H7<=IFERROR(VLOOKUP(CONCATENATE("T",ROUND(AC7,0),"lin5m"),_viitearvot!$A:$H,7,FALSE()),99),2,1)))))-S7))
S8: =IF(OR(H8="",D8=""),"",IF(H8<=IFERROR(VLOOKUP(CONCATENATE(D8,YEAR(TODAY())-YEAR(C8),"lin5m"),_viitearvot!$I$2:$M$205,2,FALSE()),99),5,IF(H8<=IFERROR(VLOOKUP(CONCATENATE(D8,YEAR(TODAY())-YEAR(C8),"lin5m"),_viitearvot!$I$2:$M$205,3,FALSE()),99),4,IF(H8<=IFERROR(VLOOKUP(CONCATENATE(D8,YEAR(TODAY())-YEAR(C8),"lin5m"),_viitearvot!$I$2:$M$205,4,FALSE()),99),3,IF(H8<=IFERROR(VLOOKUP(CONCATENATE(D8,YEAR(TODAY())-YEAR(C8),"lin5m"),_viitearvot!$I$2:$M$205,5,FALSE()),99),2,1))))) | T8: =IF(OR(I8="",D8=""),"",IF(I8<=IFERROR(VLOOKUP(CONCATENATE(D8,YEAR(TODAY())-YEAR(C8),"lin10m"),_viitearvot!$I$2:$M$205,2,FALSE()),99),5,IF(I8<=IFERROR(VLOOKUP(CONCATENATE(D8,YEAR(TODAY())-YEAR(C8),"lin10m"),_viitearvot!$I$2:$M$205,3,FALSE()),99),4,IF(I8<=IFERROR(VLOOKUP(CONCATENATE(D8,YEAR(TODAY())-YEAR(C8),"lin10m"),_viitearvot!$I$2:$M$205,4,FALSE()),99),3,IF(I8<=IFERROR(VLOOKUP(CONCATENATE(D8,YEAR(TODAY())-YEAR(C8),"lin10m"),_viitearvot!$I$2:$M$205,5,FALSE()),99),2,1))))) | U8: =IF(OR(J8="",D8=""),"",IF(J8<=IFERROR(VLOOKUP(CONCATENATE(D8,YEAR(TODAY())-YEAR(C8),"lin20m"),_viitearvot!$I$2:$M$205,2,FALSE()),99),5,IF(J8<=IFERROR(VLOOKUP(CONCATENATE(D8,YEAR(TODAY())-YEAR(C8),"lin20m"),_viitearvot!$I$2:$M$205,3,FALSE()),99),4,IF(J8<=IFERROR(VLOOKUP(CONCATENATE(D8,YEAR(TODAY())-YEAR(C8),"lin20m"),_viitearvot!$I$2:$M$205,4,FALSE()),99),3,IF(J8<=IFERROR(VLOOKUP(CONCATENATE(D8,YEAR(TODAY())-YEAR(C8),"lin20m"),_viitearvot!$I$2:$M$205,5,FALSE()),99),2,1))))) | V8: =IF(OR(K8="",D8=""),"",IF(K8<=IFERROR(VLOOKUP(CONCATENATE(D8,YEAR(TODAY())-YEAR(C8),"lin30m"),_viitearvot!$I$2:$M$205,2,FALSE()),99),5,IF(K8<=IFERROR(VLOOKUP(CONCATENATE(D8,YEAR(TODAY())-YEAR(C8),"lin30m"),_viitearvot!$I$2:$M$205,3,FALSE()),99),4,IF(K8<=IFERROR(VLOOKUP(CONCATENATE(D8,YEAR(TODAY())-YEAR(C8),"lin30m"),_viitearvot!$I$2:$M$205,4,FALSE()),99),3,IF(K8<=IFERROR(VLOOKUP(CONCATENATE(D8,YEAR(TODAY())-YEAR(C8),"lin30m"),_viitearvot!$I$2:$M$205,5,FALSE()),99),2,1))))) | W8: =IF(OR(L8="",D8=""),"",IF(L8<=IFERROR(VLOOKUP(CONCATENATE(D8,YEAR(TODAY())-YEAR(C8),"kasirata"),_viitearvot!$I$2:$M$205,2,FALSE()),99),5,IF(L8<=IFERROR(VLOOKUP(CONCATENATE(D8,YEAR(TODAY())-YEAR(C8),"kasirata"),_viitearvot!$I$2:$M$205,3,FALSE()),99),4,IF(L8<=IFERROR(VLOOKUP(CONCATENATE(D8,YEAR(TODAY())-YEAR(C8),"kasirata"),_viitearvot!$I$2:$M$205,4,FALSE()),99),3,IF(L8<=IFERROR(VLOOKUP(CONCATENATE(D8,YEAR(TODAY())-YEAR(C8),"kasirata"),_viitearvot!$I$2:$M$205,5,FALSE()),99),2,1))))) | X8: =IF(OR(M8="",D8=""),"",IF(M8<=IFERROR(VLOOKUP(CONCATENATE(D8,YEAR(TODAY())-YEAR(C8),"smjuoksu"),_viitearvot!$I$2:$M$205,2,FALSE()),99),5,IF(M8<=IFERROR(VLOOKUP(CONCATENATE(D8,YEAR(TODAY())-YEAR(C8),"smjuoksu"),_viitearvot!$I$2:$M$205,3,FALSE()),99),4,IF(M8<=IFERROR(VLOOKUP(CONCATENATE(D8,YEAR(TODAY())-YEAR(C8),"smjuoksu"),_viitearvot!$I$2:$M$205,4,FALSE()),99),3,IF(M8<=IFERROR(VLOOKUP(CONCATENATE(D8,YEAR(TODAY())-YEAR(C8),"smjuoksu"),_viitearvot!$I$2:$M$205,5,FALSE()),99),2,1))))) | Y8: =IF(OR(N8="",D8=""),"",IF(N8<=IFERROR(VLOOKUP(CONCATENATE(D8,YEAR(TODAY())-YEAR(C8),"smpallo"),_viitearvot!$I$2:$M$205,2,FALSE()),99),5,IF(N8<=IFERROR(VLOOKUP(CONCATENATE(D8,YEAR(TODAY())-YEAR(C8),"smpallo"),_viitearvot!$I$2:$M$205,3,FALSE()),99),4,IF(N8<=IFERROR(VLOOKUP(CONCATENATE(D8,YEAR(TODAY())-YEAR(C8),"smpallo"),_viitearvot!$I$2:$M$205,4,FALSE()),99),3,IF(N8<=IFERROR(VLOOKUP(CONCATENATE(D8,YEAR(TODAY())-YEAR(C8),"smpallo"),_viitearvot!$I$2:$M$205,5,FALSE()),99),2,1))))) | Z8: =IF(OR(O8="",D8=""),"",IF(O8>=IFERROR(VLOOKUP(CONCATENATE(D8,YEAR(TODAY())-YEAR(C8),"cmj"),_viitearvot!$I$2:$M$205,2,FALSE()),0),5,IF(O8>=IFERROR(VLOOKUP(CONCATENATE(D8,YEAR(TODAY())-YEAR(C8),"cmj"),_viitearvot!$I$2:$M$205,3,FALSE()),0),4,IF(O8>=IFERROR(VLOOKUP(CONCATENATE(D8,YEAR(TODAY())-YEAR(C8),"cmj"),_viitearvot!$I$2:$M$205,4,FALSE()),0),3,IF(O8>=IFERROR(VLOOKUP(CONCATENATE(D8,YEAR(TODAY())-YEAR(C8),"cmj"),_viitearvot!$I$2:$M$205,5,FALSE()),0),2,1))))) | AA8: =IF(OR(P8="",D8=""),"",IF(P8>=IFERROR(VLOOKUP(CONCATENATE(D8,YEAR(TODAY())-YEAR(C8),"bronco"),_viitearvot!$I$2:$M$205,2,FALSE()),0),5,IF(P8>=IFERROR(VLOOKUP(CONCATENATE(D8,YEAR(TODAY())-YEAR(C8),"bronco"),_viitearvot!$I$2:$M$205,3,FALSE()),0),4,IF(P8>=IFERROR(VLOOKUP(CONCATENATE(D8,YEAR(TODAY())-YEAR(C8),"bronco"),_viitearvot!$I$2:$M$205,4,FALSE()),0),3,IF(P8>=IFERROR(VLOOKUP(CONCATENATE(D8,YEAR(TODAY())-YEAR(C8),"bronco"),_viitearvot!$I$2:$M$205,5,FALSE()),0),2,1))))) | AD8: =IF(OR(AC8="",H8=""),"",(IF(D8="P",IF(H8<=IFERROR(VLOOKUP(CONCATENATE("P",ROUND(AC8,0),"lin5m"),_viitearvot!$A:$H,4,FALSE()),99),5,IF(H8<=IFERROR(VLOOKUP(CONCATENATE("P",ROUND(AC8,0),"lin5m"),_viitearvot!$A:$H,5,FALSE()),99),4,IF(H8<=IFERROR(VLOOKUP(CONCATENATE("P",ROUND(AC8,0),"lin5m"),_viitearvot!$A:$H,6,FALSE()),99),3,IF(H8<=IFERROR(VLOOKUP(CONCATENATE("P",ROUND(AC8,0),"lin5m"),_viitearvot!$A:$H,7,FALSE()),99),2,1)))),IF(H8<=IFERROR(VLOOKUP(CONCATENATE("T",ROUND(AC8,0),"lin5m"),_viitearvot!$A:$H,4,FALSE()),99),5,IF(H8<=IFERROR(VLOOKUP(CONCATENATE("T",ROUND(AC8,0),"lin5m"),_viitearvot!$A:$H,5,FALSE()),99),4,IF(H8<=IFERROR(VLOOKUP(CONCATENATE("T",ROUND(AC8,0),"lin5m"),_viitearvot!$A:$H,6,FALSE()),99),3,IF(H8<=IFERROR(VLOOKUP(CONCATENATE("T",ROUND(AC8,0),"lin5m"),_viitearvot!$A:$H,7,FALSE()),99),2,1)))))-S8))
S9: =IF(OR(H9="",D9=""),"",IF(H9<=IFERROR(VLOOKUP(CONCATENATE(D9,YEAR(TODAY())-YEAR(C9),"lin5m"),_viitearvot!$I$2:$M$205,2,FALSE()),99),5,IF(H9<=IFERROR(VLOOKUP(CONCATENATE(D9,YEAR(TODAY())-YEAR(C9),"lin5m"),_viitearvot!$I$2:$M$205,3,FALSE()),99),4,IF(H9<=IFERROR(VLOOKUP(CONCATENATE(D9,YEAR(TODAY())-YEAR(C9),"lin5m"),_viitearvot!$I$2:$M$205,4,FALSE()),99),3,IF(H9<=IFERROR(VLOOKUP(CONCATENATE(D9,YEAR(TODAY())-YEAR(C9),"lin5m"),_viitearvot!$I$2:$M$205,5,FALSE()),99),2,1))))) | T9: =IF(OR(I9="",D9=""),"",IF(I9<=IFERROR(VLOOKUP(CONCATENATE(D9,YEAR(TODAY())-YEAR(C9),"lin10m"),_viitearvot!$I$2:$M$205,2,FALSE()),99),5,IF(I9<=IFERROR(VLOOKUP(CONCATENATE(D9,YEAR(TODAY())-YEAR(C9),"lin10m"),_viitearvot!$I$2:$M$205,3,FALSE()),99),4,IF(I9<=IFERROR(VLOOKUP(CONCATENATE(D9,YEAR(TODAY())-YEAR(C9),"lin10m"),_viitearvot!$I$2:$M$205,4,FALSE()),99),3,IF(I9<=IFERROR(VLOOKUP(CONCATENATE(D9,YEAR(TODAY())-YEAR(C9),"lin10m"),_viitearvot!$I$2:$M$205,5,FALSE()),99),2,1))))) | U9: =IF(OR(J9="",D9=""),"",IF(J9<=IFERROR(VLOOKUP(CONCATENATE(D9,YEAR(TODAY())-YEAR(C9),"lin20m"),_viitearvot!$I$2:$M$205,2,FALSE()),99),5,IF(J9<=IFERROR(VLOOKUP(CONCATENATE(D9,YEAR(TODAY())-YEAR(C9),"lin20m"),_viitearvot!$I$2:$M$205,3,FALSE()),99),4,IF(J9<=IFERROR(VLOOKUP(CONCATENATE(D9,YEAR(TODAY())-YEAR(C9),"lin20m"),_viitearvot!$I$2:$M$205,4,FALSE()),99),3,IF(J9<=IFERROR(VLOOKUP(CONCATENATE(D9,YEAR(TODAY())-YEAR(C9),"lin20m"),_viitearvot!$I$2:$M$205,5,FALSE()),99),2,1))))) | V9: =IF(OR(K9="",D9=""),"",IF(K9<=IFERROR(VLOOKUP(CONCATENATE(D9,YEAR(TODAY())-YEAR(C9),"lin30m"),_viitearvot!$I$2:$M$205,2,FALSE()),99),5,IF(K9<=IFERROR(VLOOKUP(CONCATENATE(D9,YEAR(TODAY())-YEAR(C9),"lin30m"),_viitearvot!$I$2:$M$205,3,FALSE()),99),4,IF(K9<=IFERROR(VLOOKUP(CONCATENATE(D9,YEAR(TODAY())-YEAR(C9),"lin30m"),_viitearvot!$I$2:$M$205,4,FALSE()),99),3,IF(K9<=IFERROR(VLOOKUP(CONCATENATE(D9,YEAR(TODAY())-YEAR(C9),"lin30m"),_viitearvot!$I$2:$M$205,5,FALSE()),99),2,1))))) | W9: =IF(OR(L9="",D9=""),"",IF(L9<=IFERROR(VLOOKUP(CONCATENATE(D9,YEAR(TODAY())-YEAR(C9),"kasirata"),_viitearvot!$I$2:$M$205,2,FALSE()),99),5,IF(L9<=IFERROR(VLOOKUP(CONCATENATE(D9,YEAR(TODAY())-YEAR(C9),"kasirata"),_viitearvot!$I$2:$M$205,3,FALSE()),99),4,IF(L9<=IFERROR(VLOOKUP(CONCATENATE(D9,YEAR(TODAY())-YEAR(C9),"kasirata"),_viitearvot!$I$2:$M$205,4,FALSE()),99),3,IF(L9<=IFERROR(VLOOKUP(CONCATENATE(D9,YEAR(TODAY())-YEAR(C9),"kasirata"),_viitearvot!$I$2:$M$205,5,FALSE()),99),2,1))))) | X9: =IF(OR(M9="",D9=""),"",IF(M9<=IFERROR(VLOOKUP(CONCATENATE(D9,YEAR(TODAY())-YEAR(C9),"smjuoksu"),_viitearvot!$I$2:$M$205,2,FALSE()),99),5,IF(M9<=IFERROR(VLOOKUP(CONCATENATE(D9,YEAR(TODAY())-YEAR(C9),"smjuoksu"),_viitearvot!$I$2:$M$205,3,FALSE()),99),4,IF(M9<=IFERROR(VLOOKUP(CONCATENATE(D9,YEAR(TODAY())-YEAR(C9),"smjuoksu"),_viitearvot!$I$2:$M$205,4,FALSE()),99),3,IF(M9<=IFERROR(VLOOKUP(CONCATENATE(D9,YEAR(TODAY())-YEAR(C9),"smjuoksu"),_viitearvot!$I$2:$M$205,5,FALSE()),99),2,1))))) | Y9: =IF(OR(N9="",D9=""),"",IF(N9<=IFERROR(VLOOKUP(CONCATENATE(D9,YEAR(TODAY())-YEAR(C9),"smpallo"),_viitearvot!$I$2:$M$205,2,FALSE()),99),5,IF(N9<=IFERROR(VLOOKUP(CONCATENATE(D9,YEAR(TODAY())-YEAR(C9),"smpallo"),_viitearvot!$I$2:$M$205,3,FALSE()),99),4,IF(N9<=IFERROR(VLOOKUP(CONCATENATE(D9,YEAR(TODAY())-YEAR(C9),"smpallo"),_viitearvot!$I$2:$M$205,4,FALSE()),99),3,IF(N9<=IFERROR(VLOOKUP(CONCATENATE(D9,YEAR(TODAY())-YEAR(C9),"smpallo"),_viitearvot!$I$2:$M$205,5,FALSE()),99),2,1))))) | Z9: =IF(OR(O9="",D9=""),"",IF(O9>=IFERROR(VLOOKUP(CONCATENATE(D9,YEAR(TODAY())-YEAR(C9),"cmj"),_viitearvot!$I$2:$M$205,2,FALSE()),0),5,IF(O9>=IFERROR(VLOOKUP(CONCATENATE(D9,YEAR(TODAY())-YEAR(C9),"cmj"),_viitearvot!$I$2:$M$205,3,FALSE()),0),4,IF(O9>=IFERROR(VLOOKUP(CONCATENATE(D9,YEAR(TODAY())-YEAR(C9),"cmj"),_viitearvot!$I$2:$M$205,4,FALSE()),0),3,IF(O9>=IFERROR(VLOOKUP(CONCATENATE(D9,YEAR(TODAY())-YEAR(C9),"cmj"),_viitearvot!$I$2:$M$205,5,FALSE()),0),2,1))))) | AA9: =IF(OR(P9="",D9=""),"",IF(P9>=IFERROR(VLOOKUP(CONCATENATE(D9,YEAR(TODAY())-YEAR(C9),"bronco"),_viitearvot!$I$2:$M$205,2,FALSE()),0),5,IF(P9>=IFERROR(VLOOKUP(CONCATENATE(D9,YEAR(TODAY())-YEAR(C9),"bronco"),_viitearvot!$I$2:$M$205,3,FALSE()),0),4,IF(P9>=IFERROR(VLOOKUP(CONCATENATE(D9,YEAR(TODAY())-YEAR(C9),"bronco"),_viitearvot!$I$2:$M$205,4,FALSE()),0),3,IF(P9>=IFERROR(VLOOKUP(CONCATENATE(D9,YEAR(TODAY())-YEAR(C9),"bronco"),_viitearvot!$I$2:$M$205,5,FALSE()),0),2,1))))) | AD9: =IF(OR(AC9="",H9=""),"",(IF(D9="P",IF(H9<=IFERROR(VLOOKUP(CONCATENATE("P",ROUND(AC9,0),"lin5m"),_viitearvot!$A:$H,4,FALSE()),99),5,IF(H9<=IFERROR(VLOOKUP(CONCATENATE("P",ROUND(AC9,0),"lin5m"),_viitearvot!$A:$H,5,FALSE()),99),4,IF(H9<=IFERROR(VLOOKUP(CONCATENATE("P",ROUND(AC9,0),"lin5m"),_viitearvot!$A:$H,6,FALSE()),99),3,IF(H9<=IFERROR(VLOOKUP(CONCATENATE("P",ROUND(AC9,0),"lin5m"),_viitearvot!$A:$H,7,FALSE()),99),2,1)))),IF(H9<=IFERROR(VLOOKUP(CONCATENATE("T",ROUND(AC9,0),"lin5m"),_viitearvot!$A:$H,4,FALSE()),99),5,IF(H9<=IFERROR(VLOOKUP(CONCATENATE("T",ROUND(AC9,0),"lin5m"),_viitearvot!$A:$H,5,FALSE()),99),4,IF(H9<=IFERROR(VLOOKUP(CONCATENATE("T",ROUND(AC9,0),"lin5m"),_viitearvot!$A:$H,6,FALSE()),99),3,IF(H9<=IFERROR(VLOOKUP(CONCATENATE("T",ROUND(AC9,0),"lin5m"),_viitearvot!$A:$H,7,FALSE()),99),2,1)))))-S9))
S10: =IF(OR(H10="",D10=""),"",IF(H10<=IFERROR(VLOOKUP(CONCATENATE(D10,YEAR(TODAY())-YEAR(C10),"lin5m"),_viitearvot!$I$2:$M$205,2,FALSE()),99),5,IF(H10<=IFERROR(VLOOKUP(CONCATENATE(D10,YEAR(TODAY())-YEAR(C10),"lin5m"),_viitearvot!$I$2:$M$205,3,FALSE()),99),4,IF(H10<=IFERROR(VLOOKUP(CONCATENATE(D10,YEAR(TODAY())-YEAR(C10),"lin5m"),_viitearvot!$I$2:$M$205,4,FALSE()),99),3,IF(H10<=IFERROR(VLOOKUP(CONCATENATE(D10,YEAR(TODAY())-YEAR(C10),"lin5m"),_viitearvot!$I$2:$M$205,5,FALSE()),99),2,1))))) | T10: =IF(OR(I10="",D10=""),"",IF(I10<=IFERROR(VLOOKUP(CONCATENATE(D10,YEAR(TODAY())-YEAR(C10),"lin10m"),_viitearvot!$I$2:$M$205,2,FALSE()),99),5,IF(I10<=IFERROR(VLOOKUP(CONCATENATE(D10,YEAR(TODAY())-YEAR(C10),"lin10m"),_viitearvot!$I$2:$M$205,3,FALSE()),99),4,IF(I10<=IFERROR(VLOOKUP(CONCATENATE(D10,YEAR(TODAY())-YEAR(C10),"lin10m"),_viitearvot!$I$2:$M$205,4,FALSE()),99),3,IF(I10<=IFERROR(VLOOKUP(CONCATENATE(D10,YEAR(TODAY())-YEAR(C10),"lin10m"),_viitearvot!$I$2:$M$205,5,FALSE()),99),2,1))))) | U10: =IF(OR(J10="",D10=""),"",IF(J10<=IFERROR(VLOOKUP(CONCATENATE(D10,YEAR(TODAY())-YEAR(C10),"lin20m"),_viitearvot!$I$2:$M$205,2,FALSE()),99),5,IF(J10<=IFERROR(VLOOKUP(CONCATENATE(D10,YEAR(TODAY())-YEAR(C10),"lin20m"),_viitearvot!$I$2:$M$205,3,FALSE()),99),4,IF(J10<=IFERROR(VLOOKUP(CONCATENATE(D10,YEAR(TODAY())-YEAR(C10),"lin20m"),_viitearvot!$I$2:$M$205,4,FALSE()),99),3,IF(J10<=IFERROR(VLOOKUP(CONCATENATE(D10,YEAR(TODAY())-YEAR(C10),"lin20m"),_viitearvot!$I$2:$M$205,5,FALSE()),99),2,1))))) | V10: =IF(OR(K10="",D10=""),"",IF(K10<=IFERROR(VLOOKUP(CONCATENATE(D10,YEAR(TODAY())-YEAR(C10),"lin30m"),_viitearvot!$I$2:$M$205,2,FALSE()),99),5,IF(K10<=IFERROR(VLOOKUP(CONCATENATE(D10,YEAR(TODAY())-YEAR(C10),"lin30m"),_viitearvot!$I$2:$M$205,3,FALSE()),99),4,IF(K10<=IFERROR(VLOOKUP(CONCATENATE(D10,YEAR(TODAY())-YEAR(C10),"lin30m"),_viitearvot!$I$2:$M$205,4,FALSE()),99),3,IF(K10<=IFERROR(VLOOKUP(CONCATENATE(D10,YEAR(TODAY())-YEAR(C10),"lin30m"),_viitearvot!$I$2:$M$205,5,FALSE()),99),2,1))))) | W10: =IF(OR(L10="",D10=""),"",IF(L10<=IFERROR(VLOOKUP(CONCATENATE(D10,YEAR(TODAY())-YEAR(C10),"kasirata"),_viitearvot!$I$2:$M$205,2,FALSE()),99),5,IF(L10<=IFERROR(VLOOKUP(CONCATENATE(D10,YEAR(TODAY())-YEAR(C10),"kasirata"),_viitearvot!$I$2:$M$205,3,FALSE()),99),4,IF(L10<=IFERROR(VLOOKUP(CONCATENATE(D10,YEAR(TODAY())-YEAR(C10),"kasirata"),_viitearvot!$I$2:$M$205,4,FALSE()),99),3,IF(L10<=IFERROR(VLOOKUP(CONCATENATE(D10,YEAR(TODAY())-YEAR(C10),"kasirata"),_viitearvot!$I$2:$M$205,5,FALSE()),99),2,1))))) | X10: =IF(OR(M10="",D10=""),"",IF(M10<=IFERROR(VLOOKUP(CONCATENATE(D10,YEAR(TODAY())-YEAR(C10),"smjuoksu"),_viitearvot!$I$2:$M$205,2,FALSE()),99),5,IF(M10<=IFERROR(VLOOKUP(CONCATENATE(D10,YEAR(TODAY())-YEAR(C10),"smjuoksu"),_viitearvot!$I$2:$M$205,3,FALSE()),99),4,IF(M10<=IFERROR(VLOOKUP(CONCATENATE(D10,YEAR(TODAY())-YEAR(C10),"smjuoksu"),_viitearvot!$I$2:$M$205,4,FALSE()),99),3,IF(M10<=IFERROR(VLOOKUP(CONCATENATE(D10,YEAR(TODAY())-YEAR(C10),"smjuoksu"),_viitearvot!$I$2:$M$205,5,FALSE()),99),2,1))))) | Y10: =IF(OR(N10="",D10=""),"",IF(N10<=IFERROR(VLOOKUP(CONCATENATE(D10,YEAR(TODAY())-YEAR(C10),"smpallo"),_viitearvot!$I$2:$M$205,2,FALSE()),99),5,IF(N10<=IFERROR(VLOOKUP(CONCATENATE(D10,YEAR(TODAY())-YEAR(C10),"smpallo"),_viitearvot!$I$2:$M$205,3,FALSE()),99),4,IF(N10<=IFERROR(VLOOKUP(CONCATENATE(D10,YEAR(TODAY())-YEAR(C10),"smpallo"),_viitearvot!$I$2:$M$205,4,FALSE()),99),3,IF(N10<=IFERROR(VLOOKUP(CONCATENATE(D10,YEAR(TODAY())-YEAR(C10),"smpallo"),_viitearvot!$I$2:$M$205,5,FALSE()),99),2,1))))) | Z10: =IF(OR(O10="",D10=""),"",IF(O10>=IFERROR(VLOOKUP(CONCATENATE(D10,YEAR(TODAY())-YEAR(C10),"cmj"),_viitearvot!$I$2:$M$205,2,FALSE()),0),5,IF(O10>=IFERROR(VLOOKUP(CONCATENATE(D10,YEAR(TODAY())-YEAR(C10),"cmj"),_viitearvot!$I$2:$M$205,3,FALSE()),0),4,IF(O10>=IFERROR(VLOOKUP(CONCATENATE(D10,YEAR(TODAY())-YEAR(C10),"cmj"),_viitearvot!$I$2:$M$205,4,FALSE()),0),3,IF(O10>=IFERROR(VLOOKUP(CONCATENATE(D10,YEAR(TODAY())-YEAR(C10),"cmj"),_viitearvot!$I$2:$M$205,5,FALSE()),0),2,1))))) | AA10: =IF(OR(P10="",D10=""),"",IF(P10>=IFERROR(VLOOKUP(CONCATENATE(D10,YEAR(TODAY())-YEAR(C10),"bronco"),_viitearvot!$I$2:$M$205,2,FALSE()),0),5,IF(P10>=IFERROR(VLOOKUP(CONCATENATE(D10,YEAR(TODAY())-YEAR(C10),"bronco"),_viitearvot!$I$2:$M$205,3,FALSE()),0),4,IF(P10>=IFERROR(VLOOKUP(CONCATENATE(D10,YEAR(TODAY())-YEAR(C10),"bronco"),_viitearvot!$I$2:$M$205,4,FALSE()),0),3,IF(P10>=IFERROR(VLOOKUP(CONCATENATE(D10,YEAR(TODAY())-YEAR(C10),"bronco"),_viitearvot!$I$2:$M$205,5,FALSE()),0),2,1))))) | AD10: =IF(OR(AC10="",H10=""),"",(IF(D10="P",IF(H10<=IFERROR(VLOOKUP(CONCATENATE("P",ROUND(AC10,0),"lin5m"),_viitearvot!$A:$H,4,FALSE()),99),5,IF(H10<=IFERROR(VLOOKUP(CONCATENATE("P",ROUND(AC10,0),"lin5m"),_viitearvot!$A:$H,5,FALSE()),99),4,IF(H10<=IFERROR(VLOOKUP(CONCATENATE("P",ROUND(AC10,0),"lin5m"),_viitearvot!$A:$H,6,FALSE()),99),3,IF(H10<=IFERROR(VLOOKUP(CONCATENATE("P",ROUND(AC10,0),"lin5m"),_viitearvot!$A:$H,7,FALSE()),99),2,1)))),IF(H10<=IFERROR(VLOOKUP(CONCATENATE("T",ROUND(AC10,0),"lin5m"),_viitearvot!$A:$H,4,FALSE()),99),5,IF(H10<=IFERROR(VLOOKUP(CONCATENATE("T",ROUND(AC10,0),"lin5m"),_viitearvot!$A:$H,5,FALSE()),99),4,IF(H10<=IFERROR(VLOOKUP(CONCATENATE("T",ROUND(AC10,0),"lin5m"),_viitearvot!$A:$H,6,FALSE()),99),3,IF(H10<=IFERROR(VLOOKUP(CONCATENATE("T",ROUND(AC10,0),"lin5m"),_viitearvot!$A:$H,7,FALSE()),99),2,1)))))-S10))
S11: =IF(OR(H11="",D11=""),"",IF(H11<=IFERROR(VLOOKUP(CONCATENATE(D11,YEAR(TODAY())-YEAR(C11),"lin5m"),_viitearvot!$I$2:$M$205,2,FALSE()),99),5,IF(H11<=IFERROR(VLOOKUP(CONCATENATE(D11,YEAR(TODAY())-YEAR(C11),"lin5m"),_viitearvot!$I$2:$M$205,3,FALSE()),99),4,IF(H11<=IFERROR(VLOOKUP(CONCATENATE(D11,YEAR(TODAY())-YEAR(C11),"lin5m"),_viitearvot!$I$2:$M$205,4,FALSE()),99),3,IF(H11<=IFERROR(VLOOKUP(CONCATENATE(D11,YEAR(TODAY())-YEAR(C11),"lin5m"),_viitearvot!$I$2:$M$205,5,FALSE()),99),2,1))))) | T11: =IF(OR(I11="",D11=""),"",IF(I11<=IFERROR(VLOOKUP(CONCATENATE(D11,YEAR(TODAY())-YEAR(C11),"lin10m"),_viitearvot!$I$2:$M$205,2,FALSE()),99),5,IF(I11<=IFERROR(VLOOKUP(CONCATENATE(D11,YEAR(TODAY())-YEAR(C11),"lin10m"),_viitearvot!$I$2:$M$205,3,FALSE()),99),4,IF(I11<=IFERROR(VLOOKUP(CONCATENATE(D11,YEAR(TODAY())-YEAR(C11),"lin10m"),_viitearvot!$I$2:$M$205,4,FALSE()),99),3,IF(I11<=IFERROR(VLOOKUP(CONCATENATE(D11,YEAR(TODAY())-YEAR(C11),"lin10m"),_viitearvot!$I$2:$M$205,5,FALSE()),99),2,1))))) | U11: =IF(OR(J11="",D11=""),"",IF(J11<=IFERROR(VLOOKUP(CONCATENATE(D11,YEAR(TODAY())-YEAR(C11),"lin20m"),_viitearvot!$I$2:$M$205,2,FALSE()),99),5,IF(J11<=IFERROR(VLOOKUP(CONCATENATE(D11,YEAR(TODAY())-YEAR(C11),"lin20m"),_viitearvot!$I$2:$M$205,3,FALSE()),99),4,IF(J11<=IFERROR(VLOOKUP(CONCATENATE(D11,YEAR(TODAY())-YEAR(C11),"lin20m"),_viitearvot!$I$2:$M$205,4,FALSE()),99),3,IF(J11<=IFERROR(VLOOKUP(CONCATENATE(D11,YEAR(TODAY())-YEAR(C11),"lin20m"),_viitearvot!$I$2:$M$205,5,FALSE()),99),2,1))))) | V11: =IF(OR(K11="",D11=""),"",IF(K11<=IFERROR(VLOOKUP(CONCATENATE(D11,YEAR(TODAY())-YEAR(C11),"lin30m"),_viitearvot!$I$2:$M$205,2,FALSE()),99),5,IF(K11<=IFERROR(VLOOKUP(CONCATENATE(D11,YEAR(TODAY())-YEAR(C11),"lin30m"),_viitearvot!$I$2:$M$205,3,FALSE()),99),4,IF(K11<=IFERROR(VLOOKUP(CONCATENATE(D11,YEAR(TODAY())-YEAR(C11),"lin30m"),_viitearvot!$I$2:$M$205,4,FALSE()),99),3,IF(K11<=IFERROR(VLOOKUP(CONCATENATE(D11,YEAR(TODAY())-YEAR(C11),"lin30m"),_viitearvot!$I$2:$M$205,5,FALSE()),99),2,1))))) | W11: =IF(OR(L11="",D11=""),"",IF(L11<=IFERROR(VLOOKUP(CONCATENATE(D11,YEAR(TODAY())-YEAR(C11),"kasirata"),_viitearvot!$I$2:$M$205,2,FALSE()),99),5,IF(L11<=IFERROR(VLOOKUP(CONCATENATE(D11,YEAR(TODAY())-YEAR(C11),"kasirata"),_viitearvot!$I$2:$M$205,3,FALSE()),99),4,IF(L11<=IFERROR(VLOOKUP(CONCATENATE(D11,YEAR(TODAY())-YEAR(C11),"kasirata"),_viitearvot!$I$2:$M$205,4,FALSE()),99),3,IF(L11<=IFERROR(VLOOKUP(CONCATENATE(D11,YEAR(TODAY())-YEAR(C11),"kasirata"),_viitearvot!$I$2:$M$205,5,FALSE()),99),2,1))))) | X11: =IF(OR(M11="",D11=""),"",IF(M11<=IFERROR(VLOOKUP(CONCATENATE(D11,YEAR(TODAY())-YEAR(C11),"smjuoksu"),_viitearvot!$I$2:$M$205,2,FALSE()),99),5,IF(M11<=IFERROR(VLOOKUP(CONCATENATE(D11,YEAR(TODAY())-YEAR(C11),"smjuoksu"),_viitearvot!$I$2:$M$205,3,FALSE()),99),4,IF(M11<=IFERROR(VLOOKUP(CONCATENATE(D11,YEAR(TODAY())-YEAR(C11),"smjuoksu"),_viitearvot!$I$2:$M$205,4,FALSE()),99),3,IF(M11<=IFERROR(VLOOKUP(CONCATENATE(D11,YEAR(TODAY())-YEAR(C11),"smjuoksu"),_viitearvot!$I$2:$M$205,5,FALSE()),99),2,1))))) | Y11: =IF(OR(N11="",D11=""),"",IF(N11<=IFERROR(VLOOKUP(CONCATENATE(D11,YEAR(TODAY())-YEAR(C11),"smpallo"),_viitearvot!$I$2:$M$205,2,FALSE()),99),5,IF(N11<=IFERROR(VLOOKUP(CONCATENATE(D11,YEAR(TODAY())-YEAR(C11),"smpallo"),_viitearvot!$I$2:$M$205,3,FALSE()),99),4,IF(N11<=IFERROR(VLOOKUP(CONCATENATE(D11,YEAR(TODAY())-YEAR(C11),"smpallo"),_viitearvot!$I$2:$M$205,4,FALSE()),99),3,IF(N11<=IFERROR(VLOOKUP(CONCATENATE(D11,YEAR(TODAY())-YEAR(C11),"smpallo"),_viitearvot!$I$2:$M$205,5,FALSE()),99),2,1))))) | Z11: =IF(OR(O11="",D11=""),"",IF(O11>=IFERROR(VLOOKUP(CONCATENATE(D11,YEAR(TODAY())-YEAR(C11),"cmj"),_viitearvot!$I$2:$M$205,2,FALSE()),0),5,IF(O11>=IFERROR(VLOOKUP(CONCATENATE(D11,YEAR(TODAY())-YEAR(C11),"cmj"),_viitearvot!$I$2:$M$205,3,FALSE()),0),4,IF(O11>=IFERROR(VLOOKUP(CONCATENATE(D11,YEAR(TODAY())-YEAR(C11),"cmj"),_viitearvot!$I$2:$M$205,4,FALSE()),0),3,IF(O11>=IFERROR(VLOOKUP(CONCATENATE(D11,YEAR(TODAY())-YEAR(C11),"cmj"),_viitearvot!$I$2:$M$205,5,FALSE()),0),2,1))))) | AA11: =IF(OR(P11="",D11=""),"",IF(P11>=IFERROR(VLOOKUP(CONCATENATE(D11,YEAR(TODAY())-YEAR(C11),"bronco"),_viitearvot!$I$2:$M$205,2,FALSE()),0),5,IF(P11>=IFERROR(VLOOKUP(CONCATENATE(D11,YEAR(TODAY())-YEAR(C11),"bronco"),_viitearvot!$I$2:$M$205,3,FALSE()),0),4,IF(P11>=IFERROR(VLOOKUP(CONCATENATE(D11,YEAR(TODAY())-YEAR(C11),"bronco"),_viitearvot!$I$2:$M$205,4,FALSE()),0),3,IF(P11>=IFERROR(VLOOKUP(CONCATENATE(D11,YEAR(TODAY())-YEAR(C11),"bronco"),_viitearvot!$I$2:$M$205,5,FALSE()),0),2,1))))) | AD11: =IF(OR(AC11="",H11=""),"",(IF(D11="P",IF(H11<=IFERROR(VLOOKUP(CONCATENATE("P",ROUND(AC11,0),"lin5m"),_viitearvot!$A:$H,4,FALSE()),99),5,IF(H11<=IFERROR(VLOOKUP(CONCATENATE("P",ROUND(AC11,0),"lin5m"),_viitearvot!$A:$H,5,FALSE()),99),4,IF(H11<=IFERROR(VLOOKUP(CONCATENATE("P",ROUND(AC11,0),"lin5m"),_viitearvot!$A:$H,6,FALSE()),99),3,IF(H11<=IFERROR(VLOOKUP(CONCATENATE("P",ROUND(AC11,0),"lin5m"),_viitearvot!$A:$H,7,FALSE()),99),2,1)))),IF(H11<=IFERROR(VLOOKUP(CONCATENATE("T",ROUND(AC11,0),"lin5m"),_viitearvot!$A:$H,4,FALSE()),99),5,IF(H11<=IFERROR(VLOOKUP(CONCATENATE("T",ROUND(AC11,0),"lin5m"),_viitearvot!$A:$H,5,FALSE()),99),4,IF(H11<=IFERROR(VLOOKUP(CONCATENATE("T",ROUND(AC11,0),"lin5m"),_viitearvot!$A:$H,6,FALSE()),99),3,IF(H11<=IFERROR(VLOOKUP(CONCATENATE("T",ROUND(AC11,0),"lin5m"),_viitearvot!$A:$H,7,FALSE()),99),2,1)))))-S11))
S12: =IF(OR(H12="",D12=""),"",IF(H12<=IFERROR(VLOOKUP(CONCATENATE(D12,YEAR(TODAY())-YEAR(C12),"lin5m"),_viitearvot!$I$2:$M$205,2,FALSE()),99),5,IF(H12<=IFERROR(VLOOKUP(CONCATENATE(D12,YEAR(TODAY())-YEAR(C12),"lin5m"),_viitearvot!$I$2:$M$205,3,FALSE()),99),4,IF(H12<=IFERROR(VLOOKUP(CONCATENATE(D12,YEAR(TODAY())-YEAR(C12),"lin5m"),_viitearvot!$I$2:$M$205,4,FALSE()),99),3,IF(H12<=IFERROR(VLOOKUP(CONCATENATE(D12,YEAR(TODAY())-YEAR(C12),"lin5m"),_viitearvot!$I$2:$M$205,5,FALSE()),99),2,1))))) | T12: =IF(OR(I12="",D12=""),"",IF(I12<=IFERROR(VLOOKUP(CONCATENATE(D12,YEAR(TODAY())-YEAR(C12),"lin10m"),_viitearvot!$I$2:$M$205,2,FALSE()),99),5,IF(I12<=IFERROR(VLOOKUP(CONCATENATE(D12,YEAR(TODAY())-YEAR(C12),"lin10m"),_viitearvot!$I$2:$M$205,3,FALSE()),99),4,IF(I12<=IFERROR(VLOOKUP(CONCATENATE(D12,YEAR(TODAY())-YEAR(C12),"lin10m"),_viitearvot!$I$2:$M$205,4,FALSE()),99),3,IF(I12<=IFERROR(VLOOKUP(CONCATENATE(D12,YEAR(TODAY())-YEAR(C12),"lin10m"),_viitearvot!$I$2:$M$205,5,FALSE()),99),2,1))))) | U12: =IF(OR(J12="",D12=""),"",IF(J12<=IFERROR(VLOOKUP(CONCATENATE(D12,YEAR(TODAY())-YEAR(C12),"lin20m"),_viitearvot!$I$2:$M$205,2,FALSE()),99),5,IF(J12<=IFERROR(VLOOKUP(CONCATENATE(D12,YEAR(TODAY())-YEAR(C12),"lin20m"),_viitearvot!$I$2:$M$205,3,FALSE()),99),4,IF(J12<=IFERROR(VLOOKUP(CONCATENATE(D12,YEAR(TODAY())-YEAR(C12),"lin20m"),_viitearvot!$I$2:$M$205,4,FALSE()),99),3,IF(J12<=IFERROR(VLOOKUP(CONCATENATE(D12,YEAR(TODAY())-YEAR(C12),"lin20m"),_viitearvot!$I$2:$M$205,5,FALSE()),99),2,1))))) | V12: =IF(OR(K12="",D12=""),"",IF(K12<=IFERROR(VLOOKUP(CONCATENATE(D12,YEAR(TODAY())-YEAR(C12),"lin30m"),_viitearvot!$I$2:$M$205,2,FALSE()),99),5,IF(K12<=IFERROR(VLOOKUP(CONCATENATE(D12,YEAR(TODAY())-YEAR(C12),"lin30m"),_viitearvot!$I$2:$M$205,3,FALSE()),99),4,IF(K12<=IFERROR(VLOOKUP(CONCATENATE(D12,YEAR(TODAY())-YEAR(C12),"lin30m"),_viitearvot!$I$2:$M$205,4,FALSE()),99),3,IF(K12<=IFERROR(VLOOKUP(CONCATENATE(D12,YEAR(TODAY())-YEAR(C12),"lin30m"),_viitearvot!$I$2:$M$205,5,FALSE()),99),2,1))))) | W12: =IF(OR(L12="",D12=""),"",IF(L12<=IFERROR(VLOOKUP(CONCATENATE(D12,YEAR(TODAY())-YEAR(C12),"kasirata"),_viitearvot!$I$2:$M$205,2,FALSE()),99),5,IF(L12<=IFERROR(VLOOKUP(CONCATENATE(D12,YEAR(TODAY())-YEAR(C12),"kasirata"),_viitearvot!$I$2:$M$205,3,FALSE()),99),4,IF(L12<=IFERROR(VLOOKUP(CONCATENATE(D12,YEAR(TODAY())-YEAR(C12),"kasirata"),_viitearvot!$I$2:$M$205,4,FALSE()),99),3,IF(L12<=IFERROR(VLOOKUP(CONCATENATE(D12,YEAR(TODAY())-YEAR(C12),"kasirata"),_viitearvot!$I$2:$M$205,5,FALSE()),99),2,1))))) | X12: =IF(OR(M12="",D12=""),"",IF(M12<=IFERROR(VLOOKUP(CONCATENATE(D12,YEAR(TODAY())-YEAR(C12),"smjuoksu"),_viitearvot!$I$2:$M$205,2,FALSE()),99),5,IF(M12<=IFERROR(VLOOKUP(CONCATENATE(D12,YEAR(TODAY())-YEAR(C12),"smjuoksu"),_viitearvot!$I$2:$M$205,3,FALSE()),99),4,IF(M12<=IFERROR(VLOOKUP(CONCATENATE(D12,YEAR(TODAY())-YEAR(C12),"smjuoksu"),_viitearvot!$I$2:$M$205,4,FALSE()),99),3,IF(M12<=IFERROR(VLOOKUP(CONCATENATE(D12,YEAR(TODAY())-YEAR(C12),"smjuoksu"),_viitearvot!$I$2:$M$205,5,FALSE()),99),2,1))))) | Y12: =IF(OR(N12="",D12=""),"",IF(N12<=IFERROR(VLOOKUP(CONCATENATE(D12,YEAR(TODAY())-YEAR(C12),"smpallo"),_viitearvot!$I$2:$M$205,2,FALSE()),99),5,IF(N12<=IFERROR(VLOOKUP(CONCATENATE(D12,YEAR(TODAY())-YEAR(C12),"smpallo"),_viitearvot!$I$2:$M$205,3,FALSE()),99),4,IF(N12<=IFERROR(VLOOKUP(CONCATENATE(D12,YEAR(TODAY())-YEAR(C12),"smpallo"),_viitearvot!$I$2:$M$205,4,FALSE()),99),3,IF(N12<=IFERROR(VLOOKUP(CONCATENATE(D12,YEAR(TODAY())-YEAR(C12),"smpallo"),_viitearvot!$I$2:$M$205,5,FALSE()),99),2,1))))) | Z12: =IF(OR(O12="",D12=""),"",IF(O12>=IFERROR(VLOOKUP(CONCATENATE(D12,YEAR(TODAY())-YEAR(C12),"cmj"),_viitearvot!$I$2:$M$205,2,FALSE()),0),5,IF(O12>=IFERROR(VLOOKUP(CONCATENATE(D12,YEAR(TODAY())-YEAR(C12),"cmj"),_viitearvot!$I$2:$M$205,3,FALSE()),0),4,IF(O12>=IFERROR(VLOOKUP(CONCATENATE(D12,YEAR(TODAY())-YEAR(C12),"cmj"),_viitearvot!$I$2:$M$205,4,FALSE()),0),3,IF(O12>=IFERROR(VLOOKUP(CONCATENATE(D12,YEAR(TODAY())-YEAR(C12),"cmj"),_viitearvot!$I$2:$M$205,5,FALSE()),0),2,1))))) | AA12: =IF(OR(P12="",D12=""),"",IF(P12>=IFERROR(VLOOKUP(CONCATENATE(D12,YEAR(TODAY())-YEAR(C12),"bronco"),_viitearvot!$I$2:$M$205,2,FALSE()),0),5,IF(P12>=IFERROR(VLOOKUP(CONCATENATE(D12,YEAR(TODAY())-YEAR(C12),"bronco"),_viitearvot!$I$2:$M$205,3,FALSE()),0),4,IF(P12>=IFERROR(VLOOKUP(CONCATENATE(D12,YEAR(TODAY())-YEAR(C12),"bronco"),_viitearvot!$I$2:$M$205,4,FALSE()),0),3,IF(P12>=IFERROR(VLOOKUP(CONCATENATE(D12,YEAR(TODAY())-YEAR(C12),"bronco"),_viitearvot!$I$2:$M$205,5,FALSE()),0),2,1))))) | AD12: =IF(OR(AC12="",H12=""),"",(IF(D12="P",IF(H12<=IFERROR(VLOOKUP(CONCATENATE("P",ROUND(AC12,0),"lin5m"),_viitearvot!$A:$H,4,FALSE()),99),5,IF(H12<=IFERROR(VLOOKUP(CONCATENATE("P",ROUND(AC12,0),"lin5m"),_viitearvot!$A:$H,5,FALSE()),99),4,IF(H12<=IFERROR(VLOOKUP(CONCATENATE("P",ROUND(AC12,0),"lin5m"),_viitearvot!$A:$H,6,FALSE()),99),3,IF(H12<=IFERROR(VLOOKUP(CONCATENATE("P",ROUND(AC12,0),"lin5m"),_viitearvot!$A:$H,7,FALSE()),99),2,1)))),IF(H12<=IFERROR(VLOOKUP(CONCATENATE("T",ROUND(AC12,0),"lin5m"),_viitearvot!$A:$H,4,FALSE()),99),5,IF(H12<=IFERROR(VLOOKUP(CONCATENATE("T",ROUND(AC12,0),"lin5m"),_viitearvot!$A:$H,5,FALSE()),99),4,IF(H12<=IFERROR(VLOOKUP(CONCATENATE("T",ROUND(AC12,0),"lin5m"),_viitearvot!$A:$H,6,FALSE()),99),3,IF(H12<=IFERROR(VLOOKUP(CONCATENATE("T",ROUND(AC12,0),"lin5m"),_viitearvot!$A:$H,7,FALSE()),99),2,1)))))-S12))
S13: =IF(OR(H13="",D13=""),"",IF(H13<=IFERROR(VLOOKUP(CONCATENATE(D13,YEAR(TODAY())-YEAR(C13),"lin5m"),_viitearvot!$I$2:$M$205,2,FALSE()),99),5,IF(H13<=IFERROR(VLOOKUP(CONCATENATE(D13,YEAR(TODAY())-YEAR(C13),"lin5m"),_viitearvot!$I$2:$M$205,3,FALSE()),99),4,IF(H13<=IFERROR(VLOOKUP(CONCATENATE(D13,YEAR(TODAY())-YEAR(C13),"lin5m"),_viitearvot!$I$2:$M$205,4,FALSE()),99),3,IF(H13<=IFERROR(VLOOKUP(CONCATENATE(D13,YEAR(TODAY())-YEAR(C13),"lin5m"),_viitearvot!$I$2:$M$205,5,FALSE()),99),2,1))))) | T13: =IF(OR(I13="",D13=""),"",IF(I13<=IFERROR(VLOOKUP(CONCATENATE(D13,YEAR(TODAY())-YEAR(C13),"lin10m"),_viitearvot!$I$2:$M$205,2,FALSE()),99),5,IF(I13<=IFERROR(VLOOKUP(CONCATENATE(D13,YEAR(TODAY())-YEAR(C13),"lin10m"),_viitearvot!$I$2:$M$205,3,FALSE()),99),4,IF(I13<=IFERROR(VLOOKUP(CONCATENATE(D13,YEAR(TODAY())-YEAR(C13),"lin10m"),_viitearvot!$I$2:$M$205,4,FALSE()),99),3,IF(I13<=IFERROR(VLOOKUP(CONCATENATE(D13,YEAR(TODAY())-YEAR(C13),"lin10m"),_viitearvot!$I$2:$M$205,5,FALSE()),99),2,1))))) | U13: =IF(OR(J13="",D13=""),"",IF(J13<=IFERROR(VLOOKUP(CONCATENATE(D13,YEAR(TODAY())-YEAR(C13),"lin20m"),_viitearvot!$I$2:$M$205,2,FALSE()),99),5,IF(J13<=IFERROR(VLOOKUP(CONCATENATE(D13,YEAR(TODAY())-YEAR(C13),"lin20m"),_viitearvot!$I$2:$M$205,3,FALSE()),99),4,IF(J13<=IFERROR(VLOOKUP(CONCATENATE(D13,YEAR(TODAY())-YEAR(C13),"lin20m"),_viitearvot!$I$2:$M$205,4,FALSE()),99),3,IF(J13<=IFERROR(VLOOKUP(CONCATENATE(D13,YEAR(TODAY())-YEAR(C13),"lin20m"),_viitearvot!$I$2:$M$205,5,FALSE()),99),2,1))))) | V13: =IF(OR(K13="",D13=""),"",IF(K13<=IFERROR(VLOOKUP(CONCATENATE(D13,YEAR(TODAY())-YEAR(C13),"lin30m"),_viitearvot!$I$2:$M$205,2,FALSE()),99),5,IF(K13<=IFERROR(VLOOKUP(CONCATENATE(D13,YEAR(TODAY())-YEAR(C13),"lin30m"),_viitearvot!$I$2:$M$205,3,FALSE()),99),4,IF(K13<=IFERROR(VLOOKUP(CONCATENATE(D13,YEAR(TODAY())-YEAR(C13),"lin30m"),_viitearvot!$I$2:$M$205,4,FALSE()),99),3,IF(K13<=IFERROR(VLOOKUP(CONCATENATE(D13,YEAR(TODAY())-YEAR(C13),"lin30m"),_viitearvot!$I$2:$M$205,5,FALSE()),99),2,1))))) | W13: =IF(OR(L13="",D13=""),"",IF(L13<=IFERROR(VLOOKUP(CONCATENATE(D13,YEAR(TODAY())-YEAR(C13),"kasirata"),_viitearvot!$I$2:$M$205,2,FALSE()),99),5,IF(L13<=IFERROR(VLOOKUP(CONCATENATE(D13,YEAR(TODAY())-YEAR(C13),"kasirata"),_viitearvot!$I$2:$M$205,3,FALSE()),99),4,IF(L13<=IFERROR(VLOOKUP(CONCATENATE(D13,YEAR(TODAY())-YEAR(C13),"kasirata"),_viitearvot!$I$2:$M$205,4,FALSE()),99),3,IF(L13<=IFERROR(VLOOKUP(CONCATENATE(D13,YEAR(TODAY())-YEAR(C13),"kasirata"),_viitearvot!$I$2:$M$205,5,FALSE()),99),2,1))))) | X13: =IF(OR(M13="",D13=""),"",IF(M13<=IFERROR(VLOOKUP(CONCATENATE(D13,YEAR(TODAY())-YEAR(C13),"smjuoksu"),_viitearvot!$I$2:$M$205,2,FALSE()),99),5,IF(M13<=IFERROR(VLOOKUP(CONCATENATE(D13,YEAR(TODAY())-YEAR(C13),"smjuoksu"),_viitearvot!$I$2:$M$205,3,FALSE()),99),4,IF(M13<=IFERROR(VLOOKUP(CONCATENATE(D13,YEAR(TODAY())-YEAR(C13),"smjuoksu"),_viitearvot!$I$2:$M$205,4,FALSE()),99),3,IF(M13<=IFERROR(VLOOKUP(CONCATENATE(D13,YEAR(TODAY())-YEAR(C13),"smjuoksu"),_viitearvot!$I$2:$M$205,5,FALSE()),99),2,1))))) | Y13: =IF(OR(N13="",D13=""),"",IF(N13<=IFERROR(VLOOKUP(CONCATENATE(D13,YEAR(TODAY())-YEAR(C13),"smpallo"),_viitearvot!$I$2:$M$205,2,FALSE()),99),5,IF(N13<=IFERROR(VLOOKUP(CONCATENATE(D13,YEAR(TODAY())-YEAR(C13),"smpallo"),_viitearvot!$I$2:$M$205,3,FALSE()),99),4,IF(N13<=IFERROR(VLOOKUP(CONCATENATE(D13,YEAR(TODAY())-YEAR(C13),"smpallo"),_viitearvot!$I$2:$M$205,4,FALSE()),99),3,IF(N13<=IFERROR(VLOOKUP(CONCATENATE(D13,YEAR(TODAY())-YEAR(C13),"smpallo"),_viitearvot!$I$2:$M$205,5,FALSE()),99),2,1))))) | Z13: =IF(OR(O13="",D13=""),"",IF(O13>=IFERROR(VLOOKUP(CONCATENATE(D13,YEAR(TODAY())-YEAR(C13),"cmj"),_viitearvot!$I$2:$M$205,2,FALSE()),0),5,IF(O13>=IFERROR(VLOOKUP(CONCATENATE(D13,YEAR(TODAY())-YEAR(C13),"cmj"),_viitearvot!$I$2:$M$205,3,FALSE()),0),4,IF(O13>=IFERROR(VLOOKUP(CONCATENATE(D13,YEAR(TODAY())-YEAR(C13),"cmj"),_viitearvot!$I$2:$M$205,4,FALSE()),0),3,IF(O13>=IFERROR(VLOOKUP(CONCATENATE(D13,YEAR(TODAY())-YEAR(C13),"cmj"),_viitearvot!$I$2:$M$205,5,FALSE()),0),2,1))))) | AA13: =IF(OR(P13="",D13=""),"",IF(P13>=IFERROR(VLOOKUP(CONCATENATE(D13,YEAR(TODAY())-YEAR(C13),"bronco"),_viitearvot!$I$2:$M$205,2,FALSE()),0),5,IF(P13>=IFERROR(VLOOKUP(CONCATENATE(D13,YEAR(TODAY())-YEAR(C13),"bronco"),_viitearvot!$I$2:$M$205,3,FALSE()),0),4,IF(P13>=IFERROR(VLOOKUP(CONCATENATE(D13,YEAR(TODAY())-YEAR(C13),"bronco"),_viitearvot!$I$2:$M$205,4,FALSE()),0),3,IF(P13>=IFERROR(VLOOKUP(CONCATENATE(D13,YEAR(TODAY())-YEAR(C13),"bronco"),_viitearvot!$I$2:$M$205,5,FALSE()),0),2,1))))) | AD13: =IF(OR(AC13="",H13=""),"",(IF(D13="P",IF(H13<=IFERROR(VLOOKUP(CONCATENATE("P",ROUND(AC13,0),"lin5m"),_viitearvot!$A:$H,4,FALSE()),99),5,IF(H13<=IFERROR(VLOOKUP(CONCATENATE("P",ROUND(AC13,0),"lin5m"),_viitearvot!$A:$H,5,FALSE()),99),4,IF(H13<=IFERROR(VLOOKUP(CONCATENATE("P",ROUND(AC13,0),"lin5m"),_viitearvot!$A:$H,6,FALSE()),99),3,IF(H13<=IFERROR(VLOOKUP(CONCATENATE("P",ROUND(AC13,0),"lin5m"),_viitearvot!$A:$H,7,FALSE()),99),2,1)))),IF(H13<=IFERROR(VLOOKUP(CONCATENATE("T",ROUND(AC13,0),"lin5m"),_viitearvot!$A:$H,4,FALSE()),99),5,IF(H13<=IFERROR(VLOOKUP(CONCATENATE("T",ROUND(AC13,0),"lin5m"),_viitearvot!$A:$H,5,FALSE()),99),4,IF(H13<=IFERROR(VLOOKUP(CONCATENATE("T",ROUND(AC13,0),"lin5m"),_viitearvot!$A:$H,6,FALSE()),99),3,IF(H13<=IFERROR(VLOOKUP(CONCATENATE("T",ROUND(AC13,0),"lin5m"),_viitearvot!$A:$H,7,FALSE()),99),2,1)))))-S13))
S14: =IF(OR(H14="",D14=""),"",IF(H14<=IFERROR(VLOOKUP(CONCATENATE(D14,YEAR(TODAY())-YEAR(C14),"lin5m"),_viitearvot!$I$2:$M$205,2,FALSE()),99),5,IF(H14<=IFERROR(VLOOKUP(CONCATENATE(D14,YEAR(TODAY())-YEAR(C14),"lin5m"),_viitearvot!$I$2:$M$205,3,FALSE()),99),4,IF(H14<=IFERROR(VLOOKUP(CONCATENATE(D14,YEAR(TODAY())-YEAR(C14),"lin5m"),_viitearvot!$I$2:$M$205,4,FALSE()),99),3,IF(H14<=IFERROR(VLOOKUP(CONCATENATE(D14,YEAR(TODAY())-YEAR(C14),"lin5m"),_viitearvot!$I$2:$M$205,5,FALSE()),99),2,1))))) | T14: =IF(OR(I14="",D14=""),"",IF(I14<=IFERROR(VLOOKUP(CONCATENATE(D14,YEAR(TODAY())-YEAR(C14),"lin10m"),_viitearvot!$I$2:$M$205,2,FALSE()),99),5,IF(I14<=IFERROR(VLOOKUP(CONCATENATE(D14,YEAR(TODAY())-YEAR(C14),"lin10m"),_viitearvot!$I$2:$M$205,3,FALSE()),99),4,IF(I14<=IFERROR(VLOOKUP(CONCATENATE(D14,YEAR(TODAY())-YEAR(C14),"lin10m"),_viitearvot!$I$2:$M$205,4,FALSE()),99),3,IF(I14<=IFERROR(VLOOKUP(CONCATENATE(D14,YEAR(TODAY())-YEAR(C14),"lin10m"),_viitearvot!$I$2:$M$205,5,FALSE()),99),2,1))))) | U14: =IF(OR(J14="",D14=""),"",IF(J14<=IFERROR(VLOOKUP(CONCATENATE(D14,YEAR(TODAY())-YEAR(C14),"lin20m"),_viitearvot!$I$2:$M$205,2,FALSE()),99),5,IF(J14<=IFERROR(VLOOKUP(CONCATENATE(D14,YEAR(TODAY())-YEAR(C14),"lin20m"),_viitearvot!$I$2:$M$205,3,FALSE()),99),4,IF(J14<=IFERROR(VLOOKUP(CONCATENATE(D14,YEAR(TODAY())-YEAR(C14),"lin20m"),_viitearvot!$I$2:$M$205,4,FALSE()),99),3,IF(J14<=IFERROR(VLOOKUP(CONCATENATE(D14,YEAR(TODAY())-YEAR(C14),"lin20m"),_viitearvot!$I$2:$M$205,5,FALSE()),99),2,1))))) | V14: =IF(OR(K14="",D14=""),"",IF(K14<=IFERROR(VLOOKUP(CONCATENATE(D14,YEAR(TODAY())-YEAR(C14),"lin30m"),_viitearvot!$I$2:$M$205,2,FALSE()),99),5,IF(K14<=IFERROR(VLOOKUP(CONCATENATE(D14,YEAR(TODAY())-YEAR(C14),"lin30m"),_viitearvot!$I$2:$M$205,3,FALSE()),99),4,IF(K14<=IFERROR(VLOOKUP(CONCATENATE(D14,YEAR(TODAY())-YEAR(C14),"lin30m"),_viitearvot!$I$2:$M$205,4,FALSE()),99),3,IF(K14<=IFERROR(VLOOKUP(CONCATENATE(D14,YEAR(TODAY())-YEAR(C14),"lin30m"),_viitearvot!$I$2:$M$205,5,FALSE()),99),2,1))))) | W14: =IF(OR(L14="",D14=""),"",IF(L14<=IFERROR(VLOOKUP(CONCATENATE(D14,YEAR(TODAY())-YEAR(C14),"kasirata"),_viitearvot!$I$2:$M$205,2,FALSE()),99),5,IF(L14<=IFERROR(VLOOKUP(CONCATENATE(D14,YEAR(TODAY())-YEAR(C14),"kasirata"),_viitearvot!$I$2:$M$205,3,FALSE()),99),4,IF(L14<=IFERROR(VLOOKUP(CONCATENATE(D14,YEAR(TODAY())-YEAR(C14),"kasirata"),_viitearvot!$I$2:$M$205,4,FALSE()),99),3,IF(L14<=IFERROR(VLOOKUP(CONCATENATE(D14,YEAR(TODAY())-YEAR(C14),"kasirata"),_viitearvot!$I$2:$M$205,5,FALSE()),99),2,1))))) | X14: =IF(OR(M14="",D14=""),"",IF(M14<=IFERROR(VLOOKUP(CONCATENATE(D14,YEAR(TODAY())-YEAR(C14),"smjuoksu"),_viitearvot!$I$2:$M$205,2,FALSE()),99),5,IF(M14<=IFERROR(VLOOKUP(CONCATENATE(D14,YEAR(TODAY())-YEAR(C14),"smjuoksu"),_viitearvot!$I$2:$M$205,3,FALSE()),99),4,IF(M14<=IFERROR(VLOOKUP(CONCATENATE(D14,YEAR(TODAY())-YEAR(C14),"smjuoksu"),_viitearvot!$I$2:$M$205,4,FALSE()),99),3,IF(M14<=IFERROR(VLOOKUP(CONCATENATE(D14,YEAR(TODAY())-YEAR(C14),"smjuoksu"),_viitearvot!$I$2:$M$205,5,FALSE()),99),2,1))))) | Y14: =IF(OR(N14="",D14=""),"",IF(N14<=IFERROR(VLOOKUP(CONCATENATE(D14,YEAR(TODAY())-YEAR(C14),"smpallo"),_viitearvot!$I$2:$M$205,2,FALSE()),99),5,IF(N14<=IFERROR(VLOOKUP(CONCATENATE(D14,YEAR(TODAY())-YEAR(C14),"smpallo"),_viitearvot!$I$2:$M$205,3,FALSE()),99),4,IF(N14<=IFERROR(VLOOKUP(CONCATENATE(D14,YEAR(TODAY())-YEAR(C14),"smpallo"),_viitearvot!$I$2:$M$205,4,FALSE()),99),3,IF(N14<=IFERROR(VLOOKUP(CONCATENATE(D14,YEAR(TODAY())-YEAR(C14),"smpallo"),_viitearvot!$I$2:$M$205,5,FALSE()),99),2,1))))) | Z14: =IF(OR(O14="",D14=""),"",IF(O14>=IFERROR(VLOOKUP(CONCATENATE(D14,YEAR(TODAY())-YEAR(C14),"cmj"),_viitearvot!$I$2:$M$205,2,FALSE()),0),5,IF(O14>=IFERROR(VLOOKUP(CONCATENATE(D14,YEAR(TODAY())-YEAR(C14),"cmj"),_viitearvot!$I$2:$M$205,3,FALSE()),0),4,IF(O14>=IFERROR(VLOOKUP(CONCATENATE(D14,YEAR(TODAY())-YEAR(C14),"cmj"),_viitearvot!$I$2:$M$205,4,FALSE()),0),3,IF(O14>=IFERROR(VLOOKUP(CONCATENATE(D14,YEAR(TODAY())-YEAR(C14),"cmj"),_viitearvot!$I$2:$M$205,5,FALSE()),0),2,1))))) | AA14: =IF(OR(P14="",D14=""),"",IF(P14>=IFERROR(VLOOKUP(CONCATENATE(D14,YEAR(TODAY())-YEAR(C14),"bronco"),_viitearvot!$I$2:$M$205,2,FALSE()),0),5,IF(P14>=IFERROR(VLOOKUP(CONCATENATE(D14,YEAR(TODAY())-YEAR(C14),"bronco"),_viitearvot!$I$2:$M$205,3,FALSE()),0),4,IF(P14>=IFERROR(VLOOKUP(CONCATENATE(D14,YEAR(TODAY())-YEAR(C14),"bronco"),_viitearvot!$I$2:$M$205,4,FALSE()),0),3,IF(P14>=IFERROR(VLOOKUP(CONCATENATE(D14,YEAR(TODAY())-YEAR(C14),"bronco"),_viitearvot!$I$2:$M$205,5,FALSE()),0),2,1))))) | AD14: =IF(OR(AC14="",H14=""),"",(IF(D14="P",IF(H14<=IFERROR(VLOOKUP(CONCATENATE("P",ROUND(AC14,0),"lin5m"),_viitearvot!$A:$H,4,FALSE()),99),5,IF(H14<=IFERROR(VLOOKUP(CONCATENATE("P",ROUND(AC14,0),"lin5m"),_viitearvot!$A:$H,5,FALSE()),99),4,IF(H14<=IFERROR(VLOOKUP(CONCATENATE("P",ROUND(AC14,0),"lin5m"),_viitearvot!$A:$H,6,FALSE()),99),3,IF(H14<=IFERROR(VLOOKUP(CONCATENATE("P",ROUND(AC14,0),"lin5m"),_viitearvot!$A:$H,7,FALSE()),99),2,1)))),IF(H14<=IFERROR(VLOOKUP(CONCATENATE("T",ROUND(AC14,0),"lin5m"),_viitearvot!$A:$H,4,FALSE()),99),5,IF(H14<=IFERROR(VLOOKUP(CONCATENATE("T",ROUND(AC14,0),"lin5m"),_viitearvot!$A:$H,5,FALSE()),99),4,IF(H14<=IFERROR(VLOOKUP(CONCATENATE("T",ROUND(AC14,0),"lin5m"),_viitearvot!$A:$H,6,FALSE()),99),3,IF(H14<=IFERROR(VLOOKUP(CONCATENATE("T",ROUND(AC14,0),"lin5m"),_viitearvot!$A:$H,7,FALSE()),99),2,1)))))-S14))
