Workbook

Sheet _viitearvot
A1: ikäluokka | B1: sukupuoli | C1: testi | D1: taso5 | E1: taso4 | F1: taso3 | G1: taso2 | H1: taso1 | I1: avain | J1: t5_lookup | K1: t4_lookup | L1: t3_lookup | M1: t2_lookup
A2: P10 | B2: P | C2: lin5m | D2: 1.08 | E2: 1.11 | F2: 1.14 | G2: 1.18 | H2: 99 | I2: P10lin5m | J2: 1.08 | K2: 1.11 | L2: 1.14 | M2: 1.18
A3: P11 | B3: P | C3: lin5m | D3: 1.05 | E3: 1.09 | F3: 1.11 | G3: 1.15 | H3: 99 | I3: P11lin5m | J3: 1.05 | K3: 1.09 | L3: 1.11 | M3: 1.15
A4: P12 | B4: P | C4: lin5m | D4: 1.02 | E4: 1.05 | F4: 1.08 | G4: 1.12 | H4: 99 | I4: P12lin5m | J4: 1.02 | K4: 1.05 | L4: 1.08 | M4: 1.12
A5: P13 | B5: P | C5: lin5m | D5: 0.99 | E5: 1.02 | F5: 1.05 | G5: 1.09 | H5: 99 | I5: P13lin5m | J5: 0.99 | K5: 1.02 | L5: 1.05 | M5: 1.09
A6: P14 | B6: P | C6: lin5m | D6: 0.96 | E6: 0.99 | F6: 1.01 | G6: 1.05 | H6: 99 | I6: P14lin5m | J6: 0.96 | K6: 0.99 | L6: 1.01 | M6: 1.05
A7: P15 | B7: P | C7: lin5m | D7: 0.94 | E7: 0.97 | F7: 0.99 | G7: 1.03 | H7: 99 | I7: P15lin5m | J7: 0.94 | K7: 0.97 | L7: 0.99 | M7: 1.03
A8: P16 | B8: P | C8: lin5m | D8: 0.92 | E8: 0.95 | F8: 0.97 | G8: 1.01 | H8: 99 | I8: P16lin5m | J8: 0.92 | K8: 0.95 | L8: 0.97 | M8: 1.01
A9: P17 | B9: P | C9: lin5m | D9: 0.9 | E9: 0.93 | F9: 0.95 | G9: 0.99 | H9: 99 | I9: P17lin5m | J9: 0.9 | K9: 0.93 | L9: 0.95 | M9: 0.99
A10: P18 | B10: P | C10: lin5m | D10: 0.88 | E10: 0.91 | F10: 0.93 | G10: 0.97 | H10: 99 | I10: P18lin5m | J10: 0.88 | K10: 0.91 | L10: 0.93 | M10: 0.97
A11: P19 | B11: P | C11: lin5m | D11: 0.87 | E11: 0.89 | F11: 0.91 | G11: 0.95 | H11: 99 | I11: P19lin5m | J11: 0.87 | K11: 0.89 | L11: 0.91 | M11: 0.95
A12: P10 | B12: P | C12: lin10m | D12: 1.92 | E12: 1.97 | F12: 2.02 | G12: 2.08 | H12: 99 | I12: P10lin10m | J12: 1.92 | K12: 1.97 | L12: 2.02 | M12: 2.08
A13: P11 | B13: P | C13: lin10m | D13: 1.88 | E13: 1.93 | F13: 1.97 | G13: 2.02 | H13: 99 | I13: P11lin10m | J13: 1.88 | K13: 1.93 | L13: 1.97 | M13: 2.02
... A205: T15 | B205: T | C205: syotto | D205: 32.8 | E205: 38.5 | F205: 99 | G205: 99 | H205: 99 | I205: T15syotto | J205: 32.8 | K205: 38.5 | L205: 99 | M205: 99

Sheet H-H Testit
A1: TalentMaster™ — H-H-polun fyysistekniset testit (Eerikkilä/Palloliitto 2024)
A2: 🔵 Pakollinen kenttä 🟢 Syötä RAW-tulos (joka yritys) ⭐ Paras = automaattinen 🟡 Taso = automaattinen Bio-ikä = syötä Mirwald-pohjasta
A3: YRITYKSET: Lin/Kasi/SM-j/CMJ = 3 yritystä | SM-pallo/Pujottelu/Syöttö = 2 yritystä | Bronco = 1 yritys | Paras tulos lasketaan automaattisesti
A4: PalloID * | B4: Nimi * | C4: Syntymäaika * | D4: Sukupuoli * | E4: Joukkue * | F4: Testauspvm * | G4: Arvioija | H4: 5m (s) [1] | I4: 5m (s) [2] | J4: 5m (s) [3] | K4: ★ Paras 5m | L4: Taso 5m | M4: 10m (s) [1] | N4: 10m (s) [2] | O4: 10m (s) [3] | P4: ★ Paras 10m | Q4: Taso 10m | R4: 20m (s) [1] | S4: 20m (s) [2] | T4: 20m (s) [3] | U4: ★ Paras 20m | V4: Taso 20m | W4: 30m (s) [1] | X4: 30m (s) [2] | Y4: 30m (s) [3] | Z4: ★ Paras 30m | AA4: Taso 30m | AB4: Kasirata (s) [1] | AC4: Kasirata (s) [2] | AD4: Kasirata (s) [3] | AE4: ★ Paras Kasirata | AF4: Taso Kasirata | AG4: SM-juoksu (s) [1] | AH4: SM-juoksu (s) [2] | AI4: SM-juoksu (s) [3] | AJ4: ★ Paras SM-juoksu | AK4: Taso SM-juoksu | AL4: SM-pallo (s) [1] | AM4: SM-pallo (s) [2] | AN4: ★ Paras SM-pallo | AO4: Taso SM-pallo | AP4: CMJ (cm) [1] | AQ4: CMJ (cm) [2] | AR4: CMJ (cm) [3] | AS4: ★ Paras CMJ | AT4: Taso CMJ | AU4: Bronco (m/s) [1] | AV4: ★ Paras Bronco | AW4: Taso Bronco | AX4: Pujottelu (s) [1] | AY4: Pujottelu (s) [2] | AZ4: ★ Paras Pujottelu | BA4: Taso Pujottelu | BB4: Syöttö (s) [1] | BC4: Syöttö (s) [2] | BD4: ★ Paras Syöttö | BE4: Taso Syöttö | BF4: Bio-ikä (Mirwald) | BG4: Taso-ero bio-krono | BH4: Huomio
K5: =IFERROR(MIN(H5,I5,J5),"") | L5: =IF(OR(K5="",D5=""),"",IF(K5<=IFERROR(VLOOKUP(CONCATENATE(D5,YEAR(TODAY())-YEAR(C5),"lin5m"),_viitearvot!$I$2:$M$205,2,FALSE()),99),5,IF(K5<=IFERROR(VLOOKUP(CONCATENATE(D5,YEAR(TODAY())-YEAR(C5),"lin5m"),_viitearvot!$I$2:$M$205,3,FALSE()),99),4,IF(K5<=IFERROR(VLOOKUP(CONCATENATE(D5,YEAR(TODAY())-YEAR(C5),"lin5m"),_viitearvot!$I$2:$M$205,4,FALSE()),99),3,IF(K5<=IFERROR(VLOOKUP(CONCATENATE(D5,YEAR(TODAY())-YEAR(C5),"lin5m"),_viitearvot!$I$2:$M$205,5,FALSE()),99),2,1))))) | P5: =IFERROR(MIN(M5,N5,O5),"") | Q5: =IF(OR(P5="",D5=""),"",IF(P5<=IFERROR(VLOOKUP(CONCATENATE(D5,YEAR(TODAY())-YEAR(C5),"lin10m"),_viitearvot!$I$2:$M$205,2,FALSE()),99),5,IF(P5<=IFERROR(VLOOKUP(CONCATENATE(D5,YEAR(TODAY())-YEAR(C5),"lin10m"),_viitearvot!$I$2:$M$205,3,FALSE()),99),4,IF(P5<=IFERROR(VLOOKUP(CONCATENATE(D5,YEAR(TODAY())-YEAR(C5),"lin10m"),_viitearvot!$I$2:$M$205,4,FALSE()),99),3,IF(P5<=IFERROR(VLOOKUP(CONCATENATE(D5,YEAR(TODAY())-YEAR(C5),"lin10m"),_viitearvot!$I$2:$M$205,5,FALSE()),99),2,1))))) | U5: =IFERROR(MIN(R5,S5,T5),"") | V5: =IF(OR(U5="",D5=""),"",IF(U5<=IFERROR(VLOOKUP(CONCATENATE(D5,YEAR(TODAY())-YEAR(C5),"lin20m"),_viitearvot!$I$2:$M$205,2,FALSE()),99),5,IF(U5<=IFERROR(VLOOKUP(CONCATENATE(D5,YEAR(TODAY())-YEAR(C5),"lin20m"),_viitearvot!$I$2:$M$205,3,FALSE()),99),4,IF(U5<=IFERROR(VLOOKUP(CONCATENATE(D5,YEAR(TODAY())-YEAR(C5),"lin20m"),_viitearvot!$I$2:$M$205,4,FALSE()),99),3,IF(U5<=IFERROR(VLOOKUP(CONCATENATE(D5,YEAR(TODAY())-YEAR(C5),"lin20m"),_viitearvot!$I$2:$M$205,5,FALSE()),99),2,1))))) | Z5: =IFERROR(MIN(W5,X5,Y5),"") | AA5: =IF(OR(Z5="",D5=""),"",IF(Z5<=IFERROR(VLOOKUP(CONCATENATE(D5,YEAR(TODAY())-YEAR(C5),"lin30m"),_viitearvot!$I$2:$M$205,2,FALSE()),99),5,IF(Z5<=IFERROR(VLOOKUP(CONCATENATE(D5,YEAR(TODAY())-YEAR(C5),"lin30m"),_viitearvot!$I$2:$M$205,3,FALSE()),99),4,IF(Z5<=IFERROR(VLOOKUP(CONCATENATE(D5,YEAR(TODAY())-YEAR(C5),"lin30m"),_viitearvot!$I$2:$M$205,4,FALSE()),99),3,IF(Z5<=IFERROR(VLOOKUP(CONCATENATE(D5,YEAR(TODAY())-YEAR(C5),"lin30m"),_viitearvot!$I$2:$M$205,5,FALSE()),99),2,1))))) | AE5: =IFERROR(MIN(AB5,AC5,AD5),"") | AF5: =IF(OR(AE5="",D5=""),"",IF(AE5<=IFERROR(VLOOKUP(CONCATENATE(D5,YEAR(TODAY())-YEAR(C5),"kasirata"),_viitearvot!$I$2:$M$205,2,FALSE()),99),5,IF(AE5<=IFERROR(VLOOKUP(CONCATENATE(D5,YEAR(TODAY())-YEAR(C5),"kasirata"),_viitearvot!$I$2:$M$205,3,FALSE()),99),4,IF(AE5<=IFERROR(VLOOKUP(CONCATENATE(D5,YEAR(TODAY())-YEAR(C5),"kasirata"),_viitearvot!$I$2:$M$205,4,FALSE()),99),3,IF(AE5<=IFERROR(VLOOKUP(CONCATENATE(D5,YEAR(TODAY())-YEAR(C5),"kasirata"),_viitearvot!$I$2:$M$205,5,FALSE()),99),2,1))))) | AJ5: =IFERROR(MIN(AG5,AH5,AI5),"") | AK5: =IF(OR(AJ5="",D5=""),"",IF(AJ5<=IFERROR(VLOOKUP(CONCATENATE(D5,YEAR(TODAY())-YEAR(C5),"smjuoksu"),_viitearvot!$I$2:$M$205,2,FALSE()),99),5,IF(AJ5<=IFERROR(VLOOKUP(CONCATENATE(D5,YEAR(TODAY())-YEAR(C5),"smjuoksu"),_viitearvot!$I$2:$M$205,3,FALSE()),99),4,IF(AJ5<=IFERROR(VLOOKUP(CONCATENATE(D5,YEAR(TODAY())-YEAR(C5),"smjuoksu"),_viitearvot!$I$2:$M$205,4,FALSE()),99),3,IF(AJ5<=IFERROR(VLOOKUP(CONCATENATE(D5,YEAR(TODAY())-YEAR(C5),"smjuoksu"),_viitearvot!$I$2:$M$205,5,FALSE()),99),2,1))))) | AN5: =IFERROR(MIN(AL5,AM5),"") | AO5: =IF(OR(AN5="",D5=""),"",IF(AN5<=IFERROR(VLOOKUP(CONCATENATE(D5,YEAR(TODAY())-YEAR(C5),"smpallo"),_viitearvot!$I$2:$M$205,2,FALSE()),99),5,IF(AN5<=IFERROR(VLOOKUP(CONCATENATE(D5,YEAR(TODAY())-YEAR(C5),"smpallo"),_viitearvot!$I$2:$M$205,3,FALSE()),99),4,IF(AN5<=IFERROR(VLOOKUP(CONCATENATE(D5,YEAR(TODAY())-YEAR(C5),"smpallo"),_viitearvot!$I$2:$M$205,4,FALSE()),99),3,IF(AN5<=IFERROR(VLOOKUP(CONCATENATE(D5,YEAR(TODAY())-YEAR(C5),"smpallo"),_viitearvot!$I$2:$M$205,5,FALSE()),99),2,1))))) | AS5: =IFERROR(MAX(AP5,AQ5,AR5),"") | AT5: =IF(OR(AS5="",D5=""),"",IF(AS5>=IFERROR(VLOOKUP(CONCATENATE(D5,YEAR(TODAY())-YEAR(C5),"cmj"),_viitearvot!$I$2:$M$205,2,FALSE()),0),5,IF(AS5>=IFERROR(VLOOKUP(CONCATENATE(D5,YEAR(TODAY())-YEAR(C5),"cmj"),_viitearvot!$I$2:$M$205,3,FALSE()),0),4,IF(AS5>=IFERROR(VLOOKUP(CONCATENATE(D5,YEAR(TODAY())-YEAR(C5),"cmj"),_viitearvot!$I$2:$M$205,4,FALSE()),0),3,IF(AS5>=IFERROR(VLOOKUP(CONCATENATE(D5,YEAR(TODAY())-YEAR(C5),"cmj"),_viitearvot!$I$2:$M$205,5,FALSE()),0),2,1))))) | AV5: =IFERROR(MAX(AU5),"") | AW5: =IF(OR(AV5="",D5=""),"",IF(AV5>=IFERROR(VLOOKUP(CONCATENATE(D5,YEAR(TODAY())-YEAR(C5),"bronco"),_viitearvot!$I$2:$M$205,2,FALSE()),0),5,IF(AV5>=IFERROR(VLOOKUP(CONCATENATE(D5,YEAR(TODAY())-YEAR(C5),"bronco"),_viitearvot!$I$2:$M$205,3,FALSE()),0),4,IF(AV5>=IFERROR(VLOOKUP(CONCATENATE(D5,YEAR(TODAY())-YEAR(C5),"bronco"),_viitearvot!$I$2:$M$205,4,FALSE()),0),3,IF(AV5>=IFERROR(VLOOKUP(CONCATENATE(D5,YEAR(TODAY())-YEAR(C5),"bronco"),_viitearvot!$I$2:$M$205,5,FALSE()),0),2,1))))) | AZ5: =IFERROR(MIN(AX5,AY5),"") | BA5: =IF(OR(AZ5="",D5=""),"",IF(AZ5<=IFERROR(VLOOKUP(CONCATENATE(D5,YEAR(TODAY())-YEAR(C5),"pujottelu"),_viitearvot!$I$2:$M$205,2,FALSE()),99),5,IF(AZ5<=IFERROR(VLOOKUP(CONCATENATE(D5,YEAR(TODAY())-YEAR(C5),"pujottelu"),_viitearvot!$I$2:$M$205,3,FALSE()),99),4,IF(AZ5<=IFERROR(VLOOKUP(CONCATENATE(D5,YEAR(TODAY())-YEAR(C5),"pujottelu"),_viitearvot!$I$2:$M$205,4,FALSE()),99),3,IF(AZ5<=IFERROR(VLOOKUP(CONCATENATE(D5,YEAR(TODAY())-YEAR(C5),"pujottelu"),_viitearvot!$I$2:$M$205,5,FALSE()),99),2,1))))) | BD5: =IFERROR(MIN(BB5,BC5),"") | BE5: =IF(OR(BD5="",D5=""),"",IF(BD5<=IFERROR(VLOOKUP(CONCATENATE(D5,YEAR(TODAY())-YEAR(C5),"syotto"),_viitearvot!$I$2:$M$205,2,FALSE()),99),5,IF(BD5<=IFERROR(VLOOKUP(CONCATENATE(D5,YEAR(TODAY())-YEAR(C5),"syotto"),_viitearvot!$I$2:$M$205,3,FALSE()),99),4,IF(BD5<=IFERROR(VLOOKUP(CONCATENATE(D5,YEAR(TODAY())-YEAR(C5),"syotto"),_viitearvot!$I$2:$M$205,4,FALSE()),99),3,IF(BD5<=IFERROR(VLOOKUP(CONCATENATE(D5,YEAR(TODAY())-YEAR(C5),"syotto"),_viitearvot!$I$2:$M$205,5,FALSE()),99),2,1))))) | BG5: =IF(OR(BF5="",K5=""),"",(IF(D5="P",IF(K5<=IFERROR(VLOOKUP(CONCATENATE("P",ROUND(BF5,0),"lin5m"),_viitearvot!$A:$H,4,FALSE()),99),5,IF(K5<=IFERROR(VLOOKUP(CONCATENATE("P",ROUND(BF5,0),"lin5m"),_viitearvot!$A:$H,5,FALSE()),99),4,IF(K5<=IFERROR(VLOOKUP(CONCATENATE("P",ROUND(BF5,0),"lin5m"),_viitearvot!$A:$H,6,FALSE()),99),3,IF(K5<=IFERROR(VLOOKUP(CONCATENATE("P",ROUND(BF5,0),"lin5m"),_viitearvot!$A:$H,7,FALSE()),99),2,1)))),IF(K5<=IFERROR(VLOOKUP(CONCATENATE("T",ROUND(BF5,0),"lin5m"),_viitearvot!$A:$H,4,FALSE()),99),5,IF(K5<=IFERROR(VLOOKUP(CONCATENATE("T",ROUND(BF5,0),"lin5m"),_viitearvot!$A:$H,5,FALSE()),99),4,IF(K5<=IFERROR(VLOOKUP(CONCATENATE("T",ROUND(BF5,0),"lin5m"),_viitearvot!$A:$H,6,FALSE()),99),3,IF(K5<=IFERROR(VLOOKUP(CONCATENATE("T",ROUND(BF5,0),"lin5m"),_viitearvot!$A:$H,7,FALSE()),99),2,1))))))-L5)
K6: =IFERROR(MIN(H6,I6,J6),"") | L6: =IF(OR(K6="",D6=""),"",IF(K6<=IFERROR(VLOOKUP(CONCATENATE(D6,YEAR(TODAY())-YEAR(C6),"lin5m"),_viitearvot!$I$2:$M$205,2,FALSE()),99),5,IF(K6<=IFERROR(VLOOKUP(CONCATENATE(D6,YEAR(TODAY())-YEAR(C6),"lin5m"),_viitearvot!$I$2:$M$205,3,FALSE()),99),4,IF(K6<=IFERROR(VLOOKUP(CONCATENATE(D6,YEAR(TODAY())-YEAR(C6),"lin5m"),_viitearvot!$I$2:$M$205,4,FALSE()),99),3,IF(K6<=IFERROR(VLOOKUP(CONCATENATE(D6,YEAR(TODAY())-YEAR(C6),"lin5m"),_viitearvot!$I$2:$M$205,5,FALSE()),99),2,1))))) | P6: =IFERROR(MIN(M6,N6,O6),"") | Q6: =IF(OR(P6="",D6=""),"",IF(P6<=IFERROR(VLOOKUP(CONCATENATE(D6,YEAR(TODAY())-YEAR(C6),"lin10m"),_viitearvot!$I$2:$M$205,2,FALSE()),99),5,IF(P6<=IFERROR(VLOOKUP(CONCATENATE(D6,YEAR(TODAY())-YEAR(C6),"lin10m"),_viitearvot!$I$2:$M$205,3,FALSE()),99),4,IF(P6<=IFERROR(VLOOKUP(CONCATENATE(D6,YEAR(TODAY())-YEAR(C6),"lin10m"),_viitearvot!$I$2:$M$205,4,FALSE()),99),3,IF(P6<=IFERROR(VLOOKUP(CONCATENATE(D6,YEAR(TODAY())-YEAR(C6),"lin10m"),_viitearvot!$I$2:$M$205,5,FALSE()),99),2,1))))) | U6: =IFERROR(MIN(R6,S6,T6),"") | V6: =IF(OR(U6="",D6=""),"",IF(U6<=IFERROR(VLOOKUP(CONCATENATE(D6,YEAR(TODAY())-YEAR(C6),"lin20m"),_viitearvot!$I$2:$M$205,2,FALSE()),99),5,IF(U6<=IFERROR(VLOOKUP(CONCATENATE(D6,YEAR(TODAY())-YEAR(C6),"lin20m"),_viitearvot!$I$2:$M$205,3,FALSE()),99),4,IF(U6<=IFERROR(VLOOKUP(CONCATENATE(D6,YEAR(TODAY())-YEAR(C6),"lin20m"),_viitearvot!$I$2:$M$205,4,FALSE()),99),3,IF(U6<=IFERROR(VLOOKUP(CONCATENATE(D6,YEAR(TODAY())-YEAR(C6),"lin20m"),_viitearvot!$I$2:$M$205,5,FALSE()),99),2,1))))) | Z6: =IFERROR(MIN(W6,X6,Y6),"") | AA6: =IF(OR(Z6="",D6=""),"",IF(Z6<=IFERROR(VLOOKUP(CONCATENATE(D6,YEAR(TODAY())-YEAR(C6),"lin30m"),_viitearvot!$I$2:$M$205,2,FALSE()),99),5,IF(Z6<=IFERROR(VLOOKUP(CONCATENATE(D6,YEAR(TODAY())-YEAR(C6),"lin30m"),_viitearvot!$I$2:$M$205,3,FALSE()),99),4,IF(Z6<=IFERROR(VLOOKUP(CONCATENATE(D6,YEAR(TODAY())-YEAR(C6),"lin30m"),_viitearvot!$I$2:$M$205,4,FALSE()),99),3,IF(Z6<=IFERROR(VLOOKUP(CONCATENATE(D6,YEAR(TODAY())-YEAR(C6),"lin30m"),_viitearvot!$I$2:$M$205,5,FALSE()),99),2,1))))) | AE6: =IFERROR(MIN(AB6,AC6,AD6),"") | AF6: =IF(OR(AE6="",D6=""),"",IF(AE6<=IFERROR(VLOOKUP(CONCATENATE(D6,YEAR(TODAY())-YEAR(C6),"kasirata"),_viitearvot!$I$2:$M$205,2,FALSE()),99),5,IF(AE6<=IFERROR(VLOOKUP(CONCATENATE(D6,YEAR(TODAY())-YEAR(C6),"kasirata"),_viitearvot!$I$2:$M$205,3,FALSE()),99),4,IF(AE6<=IFERROR(VLOOKUP(CONCATENATE(D6,YEAR(TODAY())-YEAR(C6),"kasirata"),_viitearvot!$I$2:$M$205,4,FALSE()),99),3,IF(AE6<=IFERROR(VLOOKUP(CONCATENATE(D6,YEAR(TODAY())-YEAR(C6),"kasirata"),_viitearvot!$I$2:$M$205,5,FALSE()),99),2,1))))) | AJ6: =IFERROR(MIN(AG6,AH6,AI6),"") | AK6: =IF(OR(AJ6="",D6=""),"",IF(AJ6<=IFERROR(VLOOKUP(CONCATENATE(D6,YEAR(TODAY())-YEAR(C6),"smjuoksu"),_viitearvot!$I$2:$M$205,2,FALSE()),99),5,IF(AJ6<=IFERROR(VLOOKUP(CONCATENATE(D6,YEAR(TODAY())-YEAR(C6),"smjuoksu"),_viitearvot!$I$2:$M$205,3,FALSE()),99),4,IF(AJ6<=IFERROR(VLOOKUP(CONCATENATE(D6,YEAR(TODAY())-YEAR(C6),"smjuoksu"),_viitearvot!$I$2:$M$205,4,FALSE()),99),3,IF(AJ6<=IFERROR(VLOOKUP(CONCATENATE(D6,YEAR(TODAY())-YEAR(C6),"smjuoksu"),_viitearvot!$I$2:$M$205,5,FALSE()),99),2,1))))) | AN6: =IFERROR(MIN(AL6,AM6),"") | AO6: =IF(OR(AN6="",D6=""),"",IF(AN6<=IFERROR(VLOOKUP(CONCATENATE(D6,YEAR(TODAY())-YEAR(C6),"smpallo"),_viitearvot!$I$2:$M$205,2,FALSE()),99),5,IF(AN6<=IFERROR(VLOOKUP(CONCATENATE(D6,YEAR(TODAY())-YEAR(C6),"smpallo"),_viitearvot!$I$2:$M$205,3,FALSE()),99),4,IF(AN6<=IFERROR(VLOOKUP(CONCATENATE(D6,YEAR(TODAY())-YEAR(C6),"smpallo"),_viitearvot!$I$2:$M$205,4,FALSE()),99),3,IF(AN6<=IFERROR(VLOOKUP(CONCATENATE(D6,YEAR(TODAY())-YEAR(C6),"smpallo"),_viitearvot!$I$2:$M$205,5,FALSE()),99),2,1))))) | AS6: =IFERROR(MAX(AP6,AQ6,AR6),"") | AT6: =IF(OR(AS6="",D6=""),"",IF(AS6>=IFERROR(VLOOKUP(CONCATENATE(D6,YEAR(TODAY())-YEAR(C6),"cmj"),_viitearvot!$I$2:$M$205,2,FALSE()),0),5,IF(AS6>=IFERROR(VLOOKUP(CONCATENATE(D6,YEAR(TODAY())-YEAR(C6),"cmj"),_viitearvot!$I$2:$M$205,3,FALSE()),0),4,IF(AS6>=IFERROR(VLOOKUP(CONCATENATE(D6,YEAR(TODAY())-YEAR(C6),"cmj"),_viitearvot!$I$2:$M$205,4,FALSE()),0),3,IF(AS6>=IFERROR(VLOOKUP(CONCATENATE(D6,YEAR(TODAY())-YEAR(C6),"cmj"),_viitearvot!$I$2:$M$205,5,FALSE()),0),2,1))))) | AV6: =IFERROR(MAX(AU6),"") | AW6: =IF(OR(AV6="",D6=""),"",IF(AV6>=IFERROR(VLOOKUP(CONCATENATE(D6,YEAR(TODAY())-YEAR(C6),"bronco"),_viitearvot!$I$2:$M$205,2,FALSE()),0),5,IF(AV6>=IFERROR(VLOOKUP(CONCATENATE(D6,YEAR(TODAY())-YEAR(C6),"bronco"),_viitearvot!$I$2:$M$205,3,FALSE()),0),4,IF(AV6>=IFERROR(VLOOKUP(CONCATENATE(D6,YEAR(TODAY())-YEAR(C6),"bronco"),_viitearvot!$I$2:$M$205,4,FALSE()),0),3,IF(AV6>=IFERROR(VLOOKUP(CONCATENATE(D6,YEAR(TODAY())-YEAR(C6),"bronco"),_viitearvot!$I$2:$M$205,5,FALSE()),0),2,1))))) | AZ6: =IFERROR(MIN(AX6,AY6),"") | BA6: =IF(OR(AZ6="",D6=""),"",IF(AZ6<=IFERROR(VLOOKUP(CONCATENATE(D6,YEAR(TODAY())-YEAR(C6),"pujottelu"),_viitearvot!$I$2:$M$205,2,FALSE()),99),5,IF(AZ6<=IFERROR(VLOOKUP(CONCATENATE(D6,YEAR(TODAY())-YEAR(C6),"pujottelu"),_viitearvot!$I$2:$M$205,3,FALSE()),99),4,IF(AZ6<=IFERROR(VLOOKUP(CONCATENATE(D6,YEAR(TODAY())-YEAR(C6),"pujottelu"),_viitearvot!$I$2:$M$205,4,FALSE()),99),3,IF(AZ6<=IFERROR(VLOOKUP(CONCATENATE(D6,YEAR(TODAY())-YEAR(C6),"pujottelu"),_viitearvot!$I$2:$M$205,5,FALSE()),99),2,1))))) | BD6: =IFERROR(MIN(BB6,BC6),"") | BE6: =IF(OR(BD6="",D6=""),"",IF(BD6<=IFERROR(VLOOKUP(CONCATENATE(D6,YEAR(TODAY())-YEAR(C6),"syotto"),_viitearvot!$I$2:$M$205,2,FALSE()),99),5,IF(BD6<=IFERROR(VLOOKUP(CONCATENATE(D6,YEAR(TODAY())-YEAR(C6),"syotto"),_viitearvot!$I$2:$M$205,3,FALSE()),99),4,IF(BD6<=IFERROR(VLOOKUP(CONCATENATE(D6,YEAR(TODAY())-YEAR(C6),"syotto"),_viitearvot!$I$2:$M$205,4,FALSE()),99),3,IF(BD6<=IFERROR(VLOOKUP(CONCATENATE(D6,YEAR(TODAY())-YEAR(C6),"syotto"),_viitearvot!$I$2:$M$205,5,FALSE()),99),2,1))))) | BG6: =IF(OR(BF6="",K6=""),"",(IF(D6="P",IF(K6<=IFERROR(VLOOKUP(CONCATENATE("P",ROUND(BF6,0),"lin5m"),_viitearvot!$A:$H,4,FALSE()),99),5,IF(K6<=IFERROR(VLOOKUP(CONCATENATE("P",ROUND(BF6,0),"lin5m"),_viitearvot!$A:$H,5,FALSE()),99),4,IF(K6<=IFERROR(VLOOKUP(CONCATENATE("P",ROUND(BF6,0),"lin5m"),_viitearvot!$A:$H,6,FALSE()),99),3,IF(K6<=IFERROR(VLOOKUP(CONCATENATE("P",ROUND(BF6,0),"lin5m"),_viitearvot!$A:$H,7,FALSE()),99),2,1)))),IF(K6<=IFERROR(VLOOKUP(CONCATENATE("T",ROUND(BF6,0),"lin5m"),_viitearvot!$A:$H,4,FALSE()),99),5,IF(K6<=IFERROR(VLOOKUP(CONCATENATE("T",ROUND(BF6,0),"lin5m"),_viitearvot!$A:$H,5,FALSE()),99),4,IF(K6<=IFERROR(VLOOKUP(CONCATENATE("T",ROUND(BF6,0),"lin5m"),_viitearvot!$A:$H,6,FALSE()),99),3,IF(K6<=IFERROR(VLOOKUP(CONCATENATE("T",ROUND(BF6,0),"lin5m"),_viitearvot!$A:$H,7,FALSE()),99),2,1))))))-L6)
K7: =IFERROR(MIN(H7,I7,J7),"") | L7: =IF(OR(K7="",D7=""),"",IF(K7<=IFERROR(VLOOKUP(CONCATENATE(D7,YEAR(TODAY())-YEAR(C7),"lin5m"),_viitearvot!$I$2:$M$205,2,FALSE()),99),5,IF(K7<=IFERROR(VLOOKUP(CONCATENATE(D7,YEAR(TODAY())-YEAR(C7),"lin5m"),_viitearvot!$I$2:$M$205,3,FALSE()),99),4,IF(K7<=IFERROR(VLOOKUP(CONCATENATE(D7,YEAR(TODAY())-YEAR(C7),"lin5m"),_viitearvot!$I$2:$M$205,4,FALSE()),99),3,IF(K7<=IFERROR(VLOOKUP(CONCATENATE(D7,YEAR(TODAY())-YEAR(C7),"lin5m"),_viitearvot!$I$2:$M$205,5,FALSE()),99),2,1))))) | P7: =IFERROR(MIN(M7,N7,O7),"") | Q7: =IF(OR(P7="",D7=""),"",IF(P7<=IFERROR(VLOOKUP(CONCATENATE(D7,YEAR(TODAY())-YEAR(C7),"lin10m"),_viitearvot!$I$2:$M$205,2,FALSE()),99),5,IF(P7<=IFERROR(VLOOKUP(CONCATENATE(D7,YEAR(TODAY())-YEAR(C7),"lin10m"),_viitearvot!$I$2:$M$205,3,FALSE()),99),4,IF(P7<=IFERROR(VLOOKUP(CONCATENATE(D7,YEAR(TODAY())-YEAR(C7),"lin10m"),_viitearvot!$I$2:$M$205,4,FALSE()),99),3,IF(P7<=IFERROR(VLOOKUP(CONCATENATE(D7,YEAR(TODAY())-YEAR(C7),"lin10m"),_viitearvot!$I$2:$M$205,5,FALSE()),99),2,1))))) | U7: =IFERROR(MIN(R7,S7,T7),"") | V7: =IF(OR(U7="",D7=""),"",IF(U7<=IFERROR(VLOOKUP(CONCATENATE(D7,YEAR(TODAY())-YEAR(C7),"lin20m"),_viitearvot!$I$2:$M$205,2,FALSE()),99),5,IF(U7<=IFERROR(VLOOKUP(CONCATENATE(D7,YEAR(TODAY())-YEAR(C7),"lin20m"),_viitearvot!$I$2:$M$205,3,FALSE()),99),4,IF(U7<=IFERROR(VLOOKUP(CONCATENATE(D7,YEAR(TODAY())-YEAR(C7),"lin20m"),_viitearvot!$I$2:$M$205,4,FALSE()),99),3,IF(U7<=IFERROR(VLOOKUP(CONCATENATE(D7,YEAR(TODAY())-YEAR(C7),"lin20m"),_viitearvot!$I$2:$M$205,5,FALSE()),99),2,1))))) | Z7: =IFERROR(MIN(W7,X7,Y7),"") | AA7: =IF(OR(Z7="",D7=""),"",IF(Z7<=IFERROR(VLOOKUP(CONCATENATE(D7,YEAR(TODAY())-YEAR(C7),"lin30m"),_viitearvot!$I$2:$M$205,2,FALSE()),99),5,IF(Z7<=IFERROR(VLOOKUP(CONCATENATE(D7,YEAR(TODAY())-YEAR(C7),"lin30m"),_viitearvot!$I$2:$M$205,3,FALSE()),99),4,IF(Z7<=IFERROR(VLOOKUP(CONCATENATE(D7,YEAR(TODAY())-YEAR(C7),"lin30m"),_viitearvot!$I$2:$M$205,4,FALSE()),99),3,IF(Z7<=IFERROR(VLOOKUP(CONCATENATE(D7,YEAR(TODAY())-YEAR(C7),"lin30m"),_viitearvot!$I$2:$M$205,5,FALSE()),99),2,1))))) | AE7: =IFERROR(MIN(AB7,AC7,AD7),"") | AF7: =IF(OR(AE7="",D7=""),"",IF(AE7<=IFERROR(VLOOKUP(CONCATENATE(D7,YEAR(TODAY())-YEAR(C7),"kasirata"),_viitearvot!$I$2:$M$205,2,FALSE()),99),5,IF(AE7<=IFERROR(VLOOKUP(CONCATENATE(D7,YEAR(TODAY())-YEAR(C7),"kasirata"),_viitearvot!$I$2:$M$205,3,FALSE()),99),4,IF(AE7<=IFERROR(VLOOKUP(CONCATENATE(D7,YEAR(TODAY())-YEAR(C7),"kasirata"),_viitearvot!$I$2:$M$205,4,FALSE()),99),3,IF(AE7<=IFERROR(VLOOKUP(CONCATENATE(D7,YEAR(TODAY())-YEAR(C7),"kasirata"),_viitearvot!$I$2:$M$205,5,FALSE()),99),2,1))))) | AJ7: =IFERROR(MIN(AG7,AH7,AI7),"") | AK7: =IF(OR(AJ7="",D7=""),"",IF(AJ7<=IFERROR(VLOOKUP(CONCATENATE(D7,YEAR(TODAY())-YEAR(C7),"smjuoksu"),_viitearvot!$I$2:$M$205,2,FALSE()),99),5,IF(AJ7<=IFERROR(VLOOKUP(CONCATENATE(D7,YEAR(TODAY())-YEAR(C7),"smjuoksu"),_viitearvot!$I$2:$M$205,3,FALSE()),99),4,IF(AJ7<=IFERROR(VLOOKUP(CONCATENATE(D7,YEAR(TODAY())-YEAR(C7),"smjuoksu"),_viitearvot!$I$2:$M$205,4,FALSE()),99),3,IF(AJ7<=IFERROR(VLOOKUP(CONCATENATE(D7,YEAR(TODAY())-YEAR(C7),"smjuoksu"),_viitearvot!$I$2:$M$205,5,FALSE()),99),2,1))))) | AN7: =IFERROR(MIN(AL7,AM7),"") | AO7: =IF(OR(AN7="",D7=""),"",IF(AN7<=IFERROR(VLOOKUP(CONCATENATE(D7,YEAR(TODAY())-YEAR(C7),"smpallo"),_viitearvot!$I$2:$M$205,2,FALSE()),99),5,IF(AN7<=IFERROR(VLOOKUP(CONCATENATE(D7,YEAR(TODAY())-YEAR(C7),"smpallo"),_viitearvot!$I$2:$M$205,3,FALSE()),99),4,IF(AN7<=IFERROR(VLOOKUP(CONCATENATE(D7,YEAR(TODAY())-YEAR(C7),"smpallo"),_viitearvot!$I$2:$M$205,4,FALSE()),99),3,IF(AN7<=IFERROR(VLOOKUP(CONCATENATE(D7,YEAR(TODAY())-YEAR(C7),"smpallo"),_viitearvot!$I$2:$M$205,5,FALSE()),99),2,1))))) | AS7: =IFERROR(MAX(AP7,AQ7,AR7),"") | AT7: =IF(OR(AS7="",D7=""),"",IF(AS7>=IFERROR(VLOOKUP(CONCATENATE(D7,YEAR(TODAY())-YEAR(C7),"cmj"),_viitearvot!$I$2:$M$205,2,FALSE()),0),5,IF(AS7>=IFERROR(VLOOKUP(CONCATENATE(D7,YEAR(TODAY())-YEAR(C7),"cmj"),_viitearvot!$I$2:$M$205,3,FALSE()),0),4,IF(AS7>=IFERROR(VLOOKUP(CONCATENATE(D7,YEAR(TODAY())-YEAR(C7),"cmj"),_viitearvot!$I$2:$M$205,4,FALSE()),0),3,IF(AS7>=IFERROR(VLOOKUP(CONCATENATE(D7,YEAR(TODAY())-YEAR(C7),"cmj"),_viitearvot!$I$2:$M$205,5,FALSE()),0),2,1))))) | AV7: =IFERROR(MAX(AU7),"") | AW7: =IF(OR(AV7="",D7=""),"",IF(AV7>=IFERROR(VLOOKUP(CONCATENATE(D7,YEAR(TODAY())-YEAR(C7),"bronco"),_viitearvot!$I$2:$M$205,2,FALSE()),0),5,IF(AV7>=IFERROR(VLOOKUP(CONCATENATE(D7,YEAR(TODAY())-YEAR(C7),"bronco"),_viitearvot!$I$2:$M$205,3,FALSE()),0),4,IF(AV7>=IFERROR(VLOOKUP(CONCATENATE(D7,YEAR(TODAY())-YEAR(C7),"bronco"),_viitearvot!$I$2:$M$205,4,FALSE()),0),3,IF(AV7>=IFERROR(VLOOKUP(CONCATENATE(D7,YEAR(TODAY())-YEAR(C7),"bronco"),_viitearvot!$I$2:$M$205,5,FALSE()),0),2,1))))) | AZ7: =IFERROR(MIN(AX7,AY7),"") | BA7: =IF(OR(AZ7="",D7=""),"",IF(AZ7<=IFERROR(VLOOKUP(CONCATENATE(D7,YEAR(TODAY())-YEAR(C7),"pujottelu"),_viitearvot!$I$2:$M$205,2,FALSE()),99),5,IF(AZ7<=IFERROR(VLOOKUP(CONCATENATE(D7,YEAR(TODAY())-YEAR(C7),"pujottelu"),_viitearvot!$I$2:$M$205,3,FALSE()),99),4,IF(AZ7<=IFERROR(VLOOKUP(CONCATENATE(D7,YEAR(TODAY())-YEAR(C7),"pujottelu"),_viitearvot!$I$2:$M$205,4,FALSE()),99),3,IF(AZ7<=IFERROR(VLOOKUP(CONCATENATE(D7,YEAR(TODAY())-YEAR(C7),"pujottelu"),_viitearvot!$I$2:$M$205,5,FALSE()),99),2,1))))) | BD7: =IFERROR(MIN(BB7,BC7),"") | BE7: =IF(OR(BD7="",D7=""),"",IF(BD7<=IFERROR(VLOOKUP(CONCATENATE(D7,YEAR(TODAY())-YEAR(C7),"syotto"),_viitearvot!$I$2:$M$205,2,FALSE()),99),5,IF(BD7<=IFERROR(VLOOKUP(CONCATENATE(D7,YEAR(TODAY())-YEAR(C7),"syotto"),_viitearvot!$I$2:$M$205,3,FALSE()),99),4,IF(BD7<=IFERROR(VLOOKUP(CONCATENATE(D7,YEAR(TODAY())-YEAR(C7),"syotto"),_viitearvot!$I$2:$M$205,4,FALSE()),99),3,IF(BD7<=IFERROR(VLOOKUP(CONCATENATE(D7,YEAR(TODAY())-YEAR(C7),"syotto"),_viitearvot!$I$2:$M$205,5,FALSE()),99),2,1))))) | BG7: =IF(OR(BF7="",K7=""),"",(IF(D7="P",IF(K7<=IFERROR(VLOOKUP(CONCATENATE("P",ROUND(BF7,0),"lin5m"),_viitearvot!$A:$H,4,FALSE()),99),5,IF(K7<=IFERROR(VLOOKUP(CONCATENATE("P",ROUND(BF7,0),"lin5m"),_viitearvot!$A:$H,5,FALSE()),99),4,IF(K7<=IFERROR(VLOOKUP(CONCATENATE("P",ROUND(BF7,0),"lin5m"),_viitearvot!$A:$H,6,FALSE()),99),3,IF(K7<=IFERROR(VLOOKUP(CONCATENATE("P",ROUND(BF7,0),"lin5m"),_viitearvot!$A:$H,7,FALSE()),99),2,1)))),IF(K7<=IFERROR(VLOOKUP(CONCATENATE("T",ROUND(BF7,0),"lin5m"),_viitearvot!$A:$H,4,FALSE()),99),5,IF(K7<=IFERROR(VLOOKUP(CONCATENATE("T",ROUND(BF7,0),"lin5m"),_viitearvot!$A:$H,5,FALSE()),99),4,IF(K7<=IFERROR(VLOOKUP(CONCATENATE("T",ROUND(BF7,0),"lin5m"),_viitearvot!$A:$H,6,FALSE()),99),3,IF(K7<=IFERROR(VLOOKUP(CONCATENATE("T",ROUND(BF7,0),"lin5m"),_viitearvot!$A:$H,7,FALSE()),99),2,1))))))-L7)
K8: =IFERROR(MIN(H8,I8,J8),"") | L8: =IF(OR(K8="",D8=""),"",IF(K8<=IFERROR(VLOOKUP(CONCATENATE(D8,YEAR(TODAY())-YEAR(C8),"lin5m"),_viitearvot!$I$2:$M$205,2,FALSE()),99),5,IF(K8<=IFERROR(VLOOKUP(CONCATENATE(D8,YEAR(TODAY())-YEAR(C8),"lin5m"),_viitearvot!$I$2:$M$205,3,FALSE()),99),4,IF(K8<=IFERROR(VLOOKUP(CONCATENATE(D8,YEAR(TODAY())-YEAR(C8),"lin5m"),_viitearvot!$I$2:$M$205,4,FALSE()),99),3,IF(K8<=IFERROR(VLOOKUP(CONCATENATE(D8,YEAR(TODAY())-YEAR(C8),"lin5m"),_viitearvot!$I$2:$M$205,5,FALSE()),99),2,1))))) | P8: =IFERROR(MIN(M8,N8,O8),"") | Q8: =IF(OR(P8="",D8=""),"",IF(P8<=IFERROR(VLOOKUP(CONCATENATE(D8,YEAR(TODAY())-YEAR(C8),"lin10m"),_viitearvot!$I$2:$M$205,2,FALSE()),99),5,IF(P8<=IFERROR(VLOOKUP(CONCATENATE(D8,YEAR(TODAY())-YEAR(C8),"lin10m"),_viitearvot!$I$2:$M$205,3,FALSE()),99),4,IF(P8<=IFERROR(VLOOKUP(CONCATENATE(D8,YEAR(TODAY())-YEAR(C8),"lin10m"),_viitearvot!$I$2:$M$205,4,FALSE()),99),3,IF(P8<=IFERROR(VLOOKUP(CONCATENATE(D8,YEAR(TODAY())-YEAR(C8),"lin10m"),_viitearvot!$I$2:$M$205,5,FALSE()),99),2,1))))) | U8: =IFERROR(MIN(R8,S8,T8),"") | V8: =IF(OR(U8="",D8=""),"",IF(U8<=IFERROR(VLOOKUP(CONCATENATE(D8,YEAR(TODAY())-YEAR(C8),"lin20m"),_viitearvot!$I$2:$M$205,2,FALSE()),99),5,IF(U8<=IFERROR(VLOOKUP(CONCATENATE(D8,YEAR(TODAY())-YEAR(C8),"lin20m"),_viitearvot!$I$2:$M$205,3,FALSE()),99),4,IF(U8<=IFERROR(VLOOKUP(CONCATENATE(D8,YEAR(TODAY())-YEAR(C8),"lin20m"),_viitearvot!$I$2:$M$205,4,FALSE()),99),3,IF(U8<=IFERROR(VLOOKUP(CONCATENATE(D8,YEAR(TODAY())-YEAR(C8),"lin20m"),_viitearvot!$I$2:$M$205,5,FALSE()),99),2,1))))) | Z8: =IFERROR(MIN(W8,X8,Y8),"") | AA8: =IF(OR(Z8="",D8=""),"",IF(Z8<=IFERROR(VLOOKUP(CONCATENATE(D8,YEAR(TODAY())-YEAR(C8),"lin30m"),_viitearvot!$I$2:$M$205,2,FALSE()),99),5,IF(Z8<=IFERROR(VLOOKUP(CONCATENATE(D8,YEAR(TODAY())-YEAR(C8),"lin30m"),_viitearvot!$I$2:$M$205,3,FALSE()),99),4,IF(Z8<=IFERROR(VLOOKUP(CONCATENATE(D8,YEAR(TODAY())-YEAR(C8),"lin30m"),_viitearvot!$I$2:$M$205,4,FALSE()),99),3,IF(Z8<=IFERROR(VLOOKUP(CONCATENATE(D8,YEAR(TODAY())-YEAR(C8),"lin30m"),_viitearvot!$I$2:$M$205,5,FALSE()),99),2,1))))) | AE8: =IFERROR(MIN(AB8,AC8,AD8),"") | AF8: =IF(OR(AE8="",D8=""),"",IF(AE8<=IFERROR(VLOOKUP(CONCATENATE(D8,YEAR(TODAY())-YEAR(C8),"kasirata"),_viitearvot!$I$2:$M$205,2,FALSE()),99),5,IF(AE8<=IFERROR(VLOOKUP(CONCATENATE(D8,YEAR(TODAY())-YEAR(C8),"kasirata"),_viitearvot!$I$2:$M$205,3,FALSE()),99),4,IF(AE8<=IFERROR(VLOOKUP(CONCATENATE(D8,YEAR(TODAY())-YEAR(C8),"kasirata"),_viitearvot!$I$2:$M$205,4,FALSE()),99),3,IF(AE8<=IFERROR(VLOOKUP(CONCATENATE(D8,YEAR(TODAY())-YEAR(C8),"kasirata"),_viitearvot!$I$2:$M$205,5,FALSE()),99),2,1))))) | AJ8: =IFERROR(MIN(AG8,AH8,AI8),"") | AK8: =IF(OR(AJ8="",D8=""),"",IF(AJ8<=IFERROR(VLOOKUP(CONCATENATE(D8,YEAR(TODAY())-YEAR(C8),"smjuoksu"),_viitearvot!$I$2:$M$205,2,FALSE()),99),5,IF(AJ8<=IFERROR(VLOOKUP(CONCATENATE(D8,YEAR(TODAY())-YEAR(C8),"smjuoksu"),_viitearvot!$I$2:$M$205,3,FALSE()),99),4,IF(AJ8<=IFERROR(VLOOKUP(CONCATENATE(D8,YEAR(TODAY())-YEAR(C8),"smjuoksu"),_viitearvot!$I$2:$M$205,4,FALSE()),99),3,IF(AJ8<=IFERROR(VLOOKUP(CONCATENATE(D8,YEAR(TODAY())-YEAR(C8),"smjuoksu"),_viitearvot!$I$2:$M$205,5,FALSE()),99),2,1))))) | AN8: =IFERROR(MIN(AL8,AM8),"") | AO8: =IF(OR(AN8="",D8=""),"",IF(AN8<=IFERROR(VLOOKUP(CONCATENATE(D8,YEAR(TODAY())-YEAR(C8),"smpallo"),_viitearvot!$I$2:$M$205,2,FALSE()),99),5,IF(AN8<=IFERROR(VLOOKUP(CONCATENATE(D8,YEAR(TODAY())-YEAR(C8),"smpallo"),_viitearvot!$I$2:$M$205,3,FALSE()),99),4,IF(AN8<=IFERROR(VLOOKUP(CONCATENATE(D8,YEAR(TODAY())-YEAR(C8),"smpallo"),_viitearvot!$I$2:$M$205,4,FALSE()),99),3,IF(AN8<=IFERROR(VLOOKUP(CONCATENATE(D8,YEAR(TODAY())-YEAR(C8),"smpallo"),_viitearvot!$I$2:$M$205,5,FALSE()),99),2,1))))) | AS8: =IFERROR(MAX(AP8,AQ8,AR8),"") | AT8: =IF(OR(AS8="",D8=""),"",IF(AS8>=IFERROR(VLOOKUP(CONCATENATE(D8,YEAR(TODAY())-YEAR(C8),"cmj"),_viitearvot!$I$2:$M$205,2,FALSE()),0),5,IF(AS8>=IFERROR(VLOOKUP(CONCATENATE(D8,YEAR(TODAY())-YEAR(C8),"cmj"),_viitearvot!$I$2:$M$205,3,FALSE()),0),4,IF(AS8>=IFERROR(VLOOKUP(CONCATENATE(D8,YEAR(TODAY())-YEAR(C8),"cmj"),_viitearvot!$I$2:$M$205,4,FALSE()),0),3,IF(AS8>=IFERROR(VLOOKUP(CONCATENATE(D8,YEAR(TODAY())-YEAR(C8),"cmj"),_viitearvot!$I$2:$M$205,5,FALSE()),0),2,1))))) | AV8: =IFERROR(MAX(AU8),"") | AW8: =IF(OR(AV8="",D8=""),"",IF(AV8>=IFERROR(VLOOKUP(CONCATENATE(D8,YEAR(TODAY())-YEAR(C8),"bronco"),_viitearvot!$I$2:$M$205,2,FALSE()),0),5,IF(AV8>=IFERROR(VLOOKUP(CONCATENATE(D8,YEAR(TODAY())-YEAR(C8),"bronco"),_viitearvot!$I$2:$M$205,3,FALSE()),0),4,IF(AV8>=IFERROR(VLOOKUP(CONCATENATE(D8,YEAR(TODAY())-YEAR(C8),"bronco"),_viitearvot!$I$2:$M$205,4,FALSE()),0),3,IF(AV8>=IFERROR(VLOOKUP(CONCATENATE(D8,YEAR(TODAY())-YEAR(C8),"bronco"),_viitearvot!$I$2:$M$205,5,FALSE()),0),2,1))))) | AZ8: =IFERROR(MIN(AX8,AY8),"") | BA8: =IF(OR(AZ8="",D8=""),"",IF(AZ8<=IFERROR(VLOOKUP(CONCATENATE(D8,YEAR(TODAY())-YEAR(C8),"pujottelu"),_viitearvot!$I$2:$M$205,2,FALSE()),99),5,IF(AZ8<=IFERROR(VLOOKUP(CONCATENATE(D8,YEAR(TODAY())-YEAR(C8),"pujottelu"),_viitearvot!$I$2:$M$205,3,FALSE()),99),4,IF(AZ8<=IFERROR(VLOOKUP(CONCATENATE(D8,YEAR(TODAY())-YEAR(C8),"pujottelu"),_viitearvot!$I$2:$M$205,4,FALSE()),99),3,IF(AZ8<=IFERROR(VLOOKUP(CONCATENATE(D8,YEAR(TODAY())-YEAR(C8),"pujottelu"),_viitearvot!$I$2:$M$205,5,FALSE()),99),2,1))))) | BD8: =IFERROR(MIN(BB8,BC8),"") | BE8: =IF(OR(BD8="",D8=""),"",IF(BD8<=IFERROR(VLOOKUP(CONCATENATE(D8,YEAR(TODAY())-YEAR(C8),"syotto"),_viitearvot!$I$2:$M$205,2,FALSE()),99),5,IF(BD8<=IFERROR(VLOOKUP(CONCATENATE(D8,YEAR(TODAY())-YEAR(C8),"syotto"),_viitearvot!$I$2:$M$205,3,FALSE()),99),4,IF(BD8<=IFERROR(VLOOKUP(CONCATENATE(D8,YEAR(TODAY())-YEAR(C8),"syotto"),_viitearvot!$I$2:$M$205,4,FALSE()),99),3,IF(BD8<=IFERROR(VLOOKUP(CONCATENATE(D8,YEAR(TODAY())-YEAR(C8),"syotto"),_viitearvot!$I$2:$M$205,5,FALSE()),99),2,1))))) | BG8: =IF(OR(BF8="",K8=""),"",(IF(D8="P",IF(K8<=IFERROR(VLOOKUP(CONCATENATE("P",ROUND(BF8,0),"lin5m"),_viitearvot!$A:$H,4,FALSE()),99),5,IF(K8<=IFERROR(VLOOKUP(CONCATENATE("P",ROUND(BF8,0),"lin5m"),_viitearvot!$A:$H,5,FALSE()),99),4,IF(K8<=IFERROR(VLOOKUP(CONCATENATE("P",ROUND(BF8,0),"lin5m"),_viitearvot!$A:$H,6,FALSE()),99),3,IF(K8<=IFERROR(VLOOKUP(CONCATENATE("P",ROUND(BF8,0),"lin5m"),_viitearvot!$A:$H,7,FALSE()),99),2,1)))),IF(K8<=IFERROR(VLOOKUP(CONCATENATE("T",ROUND(BF8,0),"lin5m"),_viitearvot!$A:$H,4,FALSE()),99),5,IF(K8<=IFERROR(VLOOKUP(CONCATENATE("T",ROUND(BF8,0),"lin5m"),_viitearvot!$A:$H,5,FALSE()),99),4,IF(K8<=IFERROR(VLOOKUP(CONCATENATE("T",ROUND(BF8,0),"lin5m"),_viitearvot!$A:$H,6,FALSE()),99),3,IF(K8<=IFERROR(VLOOKUP(CONCATENATE("T",ROUND(BF8,0),"lin5m"),_viitearvot!$A:$H,7,FALSE()),99),2,1))))))-L8)
K9: =IFERROR(MIN(H9,I9,J9),"") | L9: =IF(OR(K9="",D9=""),"",IF(K9<=IFERROR(VLOOKUP(CONCATENATE(D9,YEAR(TODAY())-YEAR(C9),"lin5m"),_viitearvot!$I$2:$M$205,2,FALSE()),99),5,IF(K9<=IFERROR(VLOOKUP(CONCATENATE(D9,YEAR(TODAY())-YEAR(C9),"lin5m"),_viitearvot!$I$2:$M$205,3,FALSE()),99),4,IF(K9<=IFERROR(VLOOKUP(CONCATENATE(D9,YEAR(TODAY())-YEAR(C9),"lin5m"),_viitearvot!$I$2:$M$205,4,FALSE()),99),3,IF(K9<=IFERROR(VLOOKUP(CONCATENATE(D9,YEAR(TODAY())-YEAR(C9),"lin5m"),_viitearvot!$I$2:$M$205,5,FALSE()),99),2,1))))) | P9: =IFERROR(MIN(M9,N9,O9),"") | Q9: =IF(OR(P9="",D9=""),"",IF(P9<=IFERROR(VLOOKUP(CONCATENATE(D9,YEAR(TODAY())-YEAR(C9),"lin10m"),_viitearvot!$I$2:$M$205,2,FALSE()),99),5,IF(P9<=IFERROR(VLOOKUP(CONCATENATE(D9,YEAR(TODAY())-YEAR(C9),"lin10m"),_viitearvot!$I$2:$M$205,3,FALSE()),99),4,IF(P9<=IFERROR(VLOOKUP(CONCATENATE(D9,YEAR(TODAY())-YEAR(C9),"lin10m"),_viitearvot!$I$2:$M$205,4,FALSE()),99),3,IF(P9<=IFERROR(VLOOKUP(CONCATENATE(D9,YEAR(TODAY())-YEAR(C9),"lin10m"),_viitearvot!$I$2:$M$205,5,FALSE()),99),2,1))))) | U9: =IFERROR(MIN(R9,S9,T9),"") | V9: =IF(OR(U9="",D9=""),"",IF(U9<=IFERROR(VLOOKUP(CONCATENATE(D9,YEAR(TODAY())-YEAR(C9),"lin20m"),_viitearvot!$I$2:$M$205,2,FALSE()),99),5,IF(U9<=IFERROR(VLOOKUP(CONCATENATE(D9,YEAR(TODAY())-YEAR(C9),"lin20m"),_viitearvot!$I$2:$M$205,3,FALSE()),99),4,IF(U9<=IFERROR(VLOOKUP(CONCATENATE(D9,YEAR(TODAY())-YEAR(C9),"lin20m"),_viitearvot!$I$2:$M$205,4,FALSE()),99),3,IF(U9<=IFERROR(VLOOKUP(CONCATENATE(D9,YEAR(TODAY())-YEAR(C9),"lin20m"),_viitearvot!$I$2:$M$205,5,FALSE()),99),2,1))))) | Z9: =IFERROR(MIN(W9,X9,Y9),"") | AA9: =IF(OR(Z9="",D9=""),"",IF(Z9<=IFERROR(VLOOKUP(CONCATENATE(D9,YEAR(TODAY())-YEAR(C9),"lin30m"),_viitearvot!$I$2:$M$205,2,FALSE()),99),5,IF(Z9<=IFERROR(VLOOKUP(CONCATENATE(D9,YEAR(TODAY())-YEAR(C9),"lin30m"),_viitearvot!$I$2:$M$205,3,FALSE()),99),4,IF(Z9<=IFERROR(VLOOKUP(CONCATENATE(D9,YEAR(TODAY())-YEAR(C9),"lin30m"),_viitearvot!$I$2:$M$205,4,FALSE()),99),3,IF(Z9<=IFERROR(VLOOKUP(CONCATENATE(D9,YEAR(TODAY())-YEAR(C9),"lin30m"),_viitearvot!$I$2:$M$205,5,FALSE()),99),2,1))))) | AE9: =IFERROR(MIN(AB9,AC9,AD9),"") | AF9: =IF(OR(AE9="",D9=""),"",IF(AE9<=IFERROR(VLOOKUP(CONCATENATE(D9,YEAR(TODAY())-YEAR(C9),"kasirata"),_viitearvot!$I$2:$M$205,2,FALSE()),99),5,IF(AE9<=IFERROR(VLOOKUP(CONCATENATE(D9,YEAR(TODAY())-YEAR(C9),"kasirata"),_viitearvot!$I$2:$M$205,3,FALSE()),99),4,IF(AE9<=IFERROR(VLOOKUP(CONCATENATE(D9,YEAR(TODAY())-YEAR(C9),"kasirata"),_viitearvot!$I$2:$M$205,4,FALSE()),99),3,IF(AE9<=IFERROR(VLOOKUP(CONCATENATE(D9,YEAR(TODAY())-YEAR(C9),"kasirata"),_viitearvot!$I$2:$M$205,5,FALSE()),99),2,1))))) | AJ9: =IFERROR(MIN(AG9,AH9,AI9),"") | AK9: =IF(OR(AJ9="",D9=""),"",IF(AJ9<=IFERROR(VLOOKUP(CONCATENATE(D9,YEAR(TODAY())-YEAR(C9),"smjuoksu"),_viitearvot!$I$2:$M$205,2,FALSE()),99),5,IF(AJ9<=IFERROR(VLOOKUP(CONCATENATE(D9,YEAR(TODAY())-YEAR(C9),"smjuoksu"),_viitearvot!$I$2:$M$205,3,FALSE()),99),4,IF(AJ9<=IFERROR(VLOOKUP(CONCATENATE(D9,YEAR(TODAY())-YEAR(C9),"smjuoksu"),_viitearvot!$I$2:$M$205,4,FALSE()),99),3,IF(AJ9<=IFERROR(VLOOKUP(CONCATENATE(D9,YEAR(TODAY())-YEAR(C9),"smjuoksu"),_viitearvot!$I$2:$M$205,5,FALSE()),99),2,1))))) | AN9: =IFERROR(MIN(AL9,AM9),"") | AO9: =IF(OR(AN9="",D9=""),"",IF(AN9<=IFERROR(VLOOKUP(CONCATENATE(D9,YEAR(TODAY())-YEAR(C9),"smpallo"),_viitearvot!$I$2:$M$205,2,FALSE()),99),5,IF(AN9<=IFERROR(VLOOKUP(CONCATENATE(D9,YEAR(TODAY())-YEAR(C9),"smpallo"),_viitearvot!$I$2:$M$205,3,FALSE()),99),4,IF(AN9<=IFERROR(VLOOKUP(CONCATENATE(D9,YEAR(TODAY())-YEAR(C9),"smpallo"),_viitearvot!$I$2:$M$205,4,FALSE()),99),3,IF(AN9<=IFERROR(VLOOKUP(CONCATENATE(D9,YEAR(TODAY())-YEAR(C9),"smpallo"),_viitearvot!$I$2:$M$205,5,FALSE()),99),2,1))))) | AS9: =IFERROR(MAX(AP9,AQ9,AR9),"") | AT9: =IF(OR(AS9="",D9=""),"",IF(AS9>=IFERROR(VLOOKUP(CONCATENATE(D9,YEAR(TODAY())-YEAR(C9),"cmj"),_viitearvot!$I$2:$M$205,2,FALSE()),0),5,IF(AS9>=IFERROR(VLOOKUP(CONCATENATE(D9,YEAR(TODAY())-YEAR(C9),"cmj"),_viitearvot!$I$2:$M$205,3,FALSE()),0),4,IF(AS9>=IFERROR(VLOOKUP(CONCATENATE(D9,YEAR(TODAY())-YEAR(C9),"cmj"),_viitearvot!$I$2:$M$205,4,FALSE()),0),3,IF(AS9>=IFERROR(VLOOKUP(CONCATENATE(D9,YEAR(TODAY())-YEAR(C9),"cmj"),_viitearvot!$I$2:$M$205,5,FALSE()),0),2,1))))) | AV9: =IFERROR(MAX(AU9),"") | AW9: =IF(OR(AV9="",D9=""),"",IF(AV9>=IFERROR(VLOOKUP(CONCATENATE(D9,YEAR(TODAY())-YEAR(C9),"bronco"),_viitearvot!$I$2:$M$205,2,FALSE()),0),5,IF(AV9>=IFERROR(VLOOKUP(CONCATENATE(D9,YEAR(TODAY())-YEAR(C9),"bronco"),_viitearvot!$I$2:$M$205,3,FALSE()),0),4,IF(AV9>=IFERROR(VLOOKUP(CONCATENATE(D9,YEAR(TODAY())-YEAR(C9),"bronco"),_viitearvot!$I$2:$M$205,4,FALSE()),0),3,IF(AV9>=IFERROR(VLOOKUP(CONCATENATE(D9,YEAR(TODAY())-YEAR(C9),"bronco"),_viitearvot!$I$2:$M$205,5,FALSE()),0),2,1))))) | AZ9: =IFERROR(MIN(AX9,AY9),"") | BA9: =IF(OR(AZ9="",D9=""),"",IF(AZ9<=IFERROR(VLOOKUP(CONCATENATE(D9,YEAR(TODAY())-YEAR(C9),"pujottelu"),_viitearvot!$I$2:$M$205,2,FALSE()),99),5,IF(AZ9<=IFERROR(VLOOKUP(CONCATENATE(D9,YEAR(TODAY())-YEAR(C9),"pujottelu"),_viitearvot!$I$2:$M$205,3,FALSE()),99),4,IF(AZ9<=IFERROR(VLOOKUP(CONCATENATE(D9,YEAR(TODAY())-YEAR(C9),"pujottelu"),_viitearvot!$I$2:$M$205,4,FALSE()),99),3,IF(AZ9<=IFERROR(VLOOKUP(CONCATENATE(D9,YEAR(TODAY())-YEAR(C9),"pujottelu"),_viitearvot!$I$2:$M$205,5,FALSE()),99),2,1))))) | BD9: =IFERROR(MIN(BB9,BC9),"") | BE9: =IF(OR(BD9="",D9=""),"",IF(BD9<=IFERROR(VLOOKUP(CONCATENATE(D9,YEAR(TODAY())-YEAR(C9),"syotto"),_viitearvot!$I$2:$M$205,2,FALSE()),99),5,IF(BD9<=IFERROR(VLOOKUP(CONCATENATE(D9,YEAR(TODAY())-YEAR(C9),"syotto"),_viitearvot!$I$2:$M$205,3,FALSE()),99),4,IF(BD9<=IFERROR(VLOOKUP(CONCATENATE(D9,YEAR(TODAY())-YEAR(C9),"syotto"),_viitearvot!$I$2:$M$205,4,FALSE()),99),3,IF(BD9<=IFERROR(VLOOKUP(CONCATENATE(D9,YEAR(TODAY())-YEAR(C9),"syotto"),_viitearvot!$I$2:$M$205,5,FALSE()),99),2,1))))) | BG9: =IF(OR(BF9="",K9=""),"",(IF(D9="P",IF(K9<=IFERROR(VLOOKUP(CONCATENATE("P",ROUND(BF9,0),"lin5m"),_viitearvot!$A:$H,4,FALSE()),99),5,IF(K9<=IFERROR(VLOOKUP(CONCATENATE("P",ROUND(BF9,0),"lin5m"),_viitearvot!$A:$H,5,FALSE()),99),4,IF(K9<=IFERROR(VLOOKUP(CONCATENATE("P",ROUND(BF9,0),"lin5m"),_viitearvot!$A:$H,6,FALSE()),99),3,IF(K9<=IFERROR(VLOOKUP(CONCATENATE("P",ROUND(BF9,0),"lin5m"),_viitearvot!$A:$H,7,FALSE()),99),2,1)))),IF(K9<=IFERROR(VLOOKUP(CONCATENATE("T",ROUND(BF9,0),"lin5m"),_viitearvot!$A:$H,4,FALSE()),99),5,IF(K9<=IFERROR(VLOOKUP(CONCATENATE("T",ROUND(BF9,0),"lin5m"),_viitearvot!$A:$H,5,FALSE()),99),4,IF(K9<=IFERROR(VLOOKUP(CONCATENATE("T",ROUND(BF9,0),"lin5m"),_viitearvot!$A:$H,6,FALSE()),99),3,IF(K9<=IFERROR(VLOOKUP(CONCATENATE("T",ROUND(BF9,0),"lin5m"),_viitearvot!$A:$H,7,FALSE()),99),2,1))))))-L9)
K10: =IFERROR(MIN(H10,I10,J10),"") | L10: =IF(OR(K10="",D10=""),"",IF(K10<=IFERROR(VLOOKUP(CONCATENATE(D10,YEAR(TODAY())-YEAR(C10),"lin5m"),_viitearvot!$I$2:$M$205,2,FALSE()),99),5,IF(K10<=IFERROR(VLOOKUP(CONCATENATE(D10,YEAR(TODAY())-YEAR(C10),"lin5m"),_viitearvot!$I$2:$M$205,3,FALSE()),99),4,IF(K10<=IFERROR(VLOOKUP(CONCATENATE(D10,YEAR(TODAY())-YEAR(C10),"lin5m"),_viitearvot!$I$2:$M$205,4,FALSE()),99),3,IF(K10<=IFERROR(VLOOKUP(CONCATENATE(D10,YEAR(TODAY())-YEAR(C10),"lin5m"),_viitearvot!$I$2:$M$205,5,FALSE()),99),2,1))))) | P10: =IFERROR(MIN(M10,N10,O10),"") | Q10: =IF(OR(P10="",D10=""),"",IF(P10<=IFERROR(VLOOKUP(CONCATENATE(D10,YEAR(TODAY())-YEAR(C10),"lin10m"),_viitearvot!$I$2:$M$205,2,FALSE()),99),5,IF(P10<=IFERROR(VLOOKUP(CONCATENATE(D10,YEAR(TODAY())-YEAR(C10),"lin10m"),_viitearvot!$I$2:$M$205,3,FALSE()),99),4,IF(P10<=IFERROR(VLOOKUP(CONCATENATE(D10,YEAR(TODAY())-YEAR(C10),"lin10m"),_viitearvot!$I$2:$M$205,4,FALSE()),99),3,IF(P10<=IFERROR(VLOOKUP(CONCATENATE(D10,YEAR(TODAY())-YEAR(C10),"lin10m"),_viitearvot!$I$2:$M$205,5,FALSE()),99),2,1))))) | U10: =IFERROR(MIN(R10,S10,T10),"") | V10: =IF(OR(U10="",D10=""),"",IF(U10<=IFERROR(VLOOKUP(CONCATENATE(D10,YEAR(TODAY())-YEAR(C10),"lin20m"),_viitearvot!$I$2:$M$205,2,FALSE()),99),5,IF(U10<=IFERROR(VLOOKUP(CONCATENATE(D10,YEAR(TODAY())-YEAR(C10),"lin20m"),_viitearvot!$I$2:$M$205,3,FALSE()),99),4,IF(U10<=IFERROR(VLOOKUP(CONCATENATE(D10,YEAR(TODAY())-YEAR(C10),"lin20m"),_viitearvot!$I$2:$M$205,4,FALSE()),99),3,IF(U10<=IFERROR(VLOOKUP(CONCATENATE(D10,YEAR(TODAY())-YEAR(C10),"lin20m"),_viitearvot!$I$2:$M$205,5,FALSE()),99),2,1))))) | Z10: =IFERROR(MIN(W10,X10,Y10),"") | AA10: =IF(OR(Z10="",D10=""),"",IF(Z10<=IFERROR(VLOOKUP(CONCATENATE(D10,YEAR(TODAY())-YEAR(C10),"lin30m"),_viitearvot!$I$2:$M$205,2,FALSE()),99),5,IF(Z10<=IFERROR(VLOOKUP(CONCATENATE(D10,YEAR(TODAY())-YEAR(C10),"lin30m"),_viitearvot!$I$2:$M$205,3,FALSE()),99),4,IF(Z10<=IFERROR(VLOOKUP(CONCATENATE(D10,YEAR(TODAY())-YEAR(C10),"lin30m"),_viitearvot!$I$2:$M$205,4,FALSE()),99),3,IF(Z10<=IFERROR(VLOOKUP(CONCATENATE(D10,YEAR(TODAY())-YEAR(C10),"lin30m"),_viitearvot!$I$2:$M$205,5,FALSE()),99),2,1))))) | AE10: =IFERROR(MIN(AB10,AC10,AD10),"") | AF10: =IF(OR(AE10="",D10=""),"",IF(AE10<=IFERROR(VLOOKUP(CONCATENATE(D10,YEAR(TODAY())-YEAR(C10),"kasirata"),_viitearvot!$I$2:$M$205,2,FALSE()),99),5,IF(AE10<=IFERROR(VLOOKUP(CONCATENATE(D10,YEAR(TODAY())-YEAR(C10),"kasirata"),_viitearvot!$I$2:$M$205,3,FALSE()),99),4,IF(AE10<=IFERROR(VLOOKUP(CONCATENATE(D10,YEAR(TODAY())-YEAR(C10),"kasirata"),_viitearvot!$I$2:$M$205,4,FALSE()),99),3,IF(AE10<=IFERROR(VLOOKUP(CONCATENATE(D10,YEAR(TODAY())-YEAR(C10),"kasirata"),_viitearvot!$I$2:$M$205,5,FALSE()),99),2,1))))) | AJ10: =IFERROR(MIN(AG10,AH10,AI10),"") | AK10: =IF(OR(AJ10="",D10=""),"",IF(AJ10<=IFERROR(VLOOKUP(CONCATENATE(D10,YEAR(TODAY())-YEAR(C10),"smjuoksu"),_viitearvot!$I$2:$M$205,2,FALSE()),99),5,IF(AJ10<=IFERROR(VLOOKUP(CONCATENATE(D10,YEAR(TODAY())-YEAR(C10),"smjuoksu"),_viitearvot!$I$2:$M$205,3,FALSE()),99),4,IF(AJ10<=IFERROR(VLOOKUP(CONCATENATE(D10,YEAR(TODAY())-YEAR(C10),"smjuoksu"),_viitearvot!$I$2:$M$205,4,FALSE()),99),3,IF(AJ10<=IFERROR(VLOOKUP(CONCATENATE(D10,YEAR(TODAY())-YEAR(C10),"smjuoksu"),_viitearvot!$I$2:$M$205,5,FALSE()),99),2,1))))) | AN10: =IFERROR(MIN(AL10,AM10),"") | AO10: =IF(OR(AN10="",D10=""),"",IF(AN10<=IFERROR(VLOOKUP(CONCATENATE(D10,YEAR(TODAY())-YEAR(C10),"smpallo"),_viitearvot!$I$2:$M$205,2,FALSE()),99),5,IF(AN10<=IFERROR(VLOOKUP(CONCATENATE(D10,YEAR(TODAY())-YEAR(C10),"smpallo"),_viitearvot!$I$2:$M$205,3,FALSE()),99),4,IF(AN10<=IFERROR(VLOOKUP(CONCATENATE(D10,YEAR(TODAY())-YEAR(C10),"smpallo"),_viitearvot!$I$2:$M$205,4,FALSE()),99),3,IF(AN10<=IFERROR(VLOOKUP(CONCATENATE(D10,YEAR(TODAY())-YEAR(C10),"smpallo"),_viitearvot!$I$2:$M$205,5,FALSE()),99),2,1))))) | AS10: =IFERROR(MAX(AP10,AQ10,AR10),"") | AT10: =IF(OR(AS10="",D10=""),"",IF(AS10>=IFERROR(VLOOKUP(CONCATENATE(D10,YEAR(TODAY())-YEAR(C10),"cmj"),_viitearvot!$I$2:$M$205,2,FALSE()),0),5,IF(AS10>=IFERROR(VLOOKUP(CONCATENATE(D10,YEAR(TODAY())-YEAR(C10),"cmj"),_viitearvot!$I$2:$M$205,3,FALSE()),0),4,IF(AS10>=IFERROR(VLOOKUP(CONCATENATE(D10,YEAR(TODAY())-YEAR(C10),"cmj"),_viitearvot!$I$2:$M$205,4,FALSE()),0),3,IF(AS10>=IFERROR(VLOOKUP(CONCATENATE(D10,YEAR(TODAY())-YEAR(C10),"cmj"),_viitearvot!$I$2:$M$205,5,FALSE()),0),2,1))))) | AV10: =IFERROR(MAX(AU10),"") | AW10: =IF(OR(AV10="",D10=""),"",IF(AV10>=IFERROR(VLOOKUP(CONCATENATE(D10,YEAR(TODAY())-YEAR(C10),"bronco"),_viitearvot!$I$2:$M$205,2,FALSE()),0),5,IF(AV10>=IFERROR(VLOOKUP(CONCATENATE(D10,YEAR(TODAY())-YEAR(C10),"bronco"),_viitearvot!$I$2:$M$205,3,FALSE()),0),4,IF(AV10>=IFERROR(VLOOKUP(CONCATENATE(D10,YEAR(TODAY())-YEAR(C10),"bronco"),_viitearvot!$I$2:$M$205,4,FALSE()),0),3,IF(AV10>=IFERROR(VLOOKUP(CONCATENATE(D10,YEAR(TODAY())-YEAR(C10),"bronco"),_viitearvot!$I$2:$M$205,5,FALSE()),0),2,1))))) | AZ10: =IFERROR(MIN(AX10,AY10),"") | BA10: =IF(OR(AZ10="",D10=""),"",IF(AZ10<=IFERROR(VLOOKUP(CONCATENATE(D10,YEAR(TODAY())-YEAR(C10),"pujottelu"),_viitearvot!$I$2:$M$205,2,FALSE()),99),5,IF(AZ10<=IFERROR(VLOOKUP(CONCATENATE(D10,YEAR(TODAY())-YEAR(C10),"pujottelu"),_viitearvot!$I$2:$M$205,3,FALSE()),99),4,IF(AZ10<=IFERROR(VLOOKUP(CONCATENATE(D10,YEAR(TODAY())-YEAR(C10),"pujottelu"),_viitearvot!$I$2:$M$205,4,FALSE()),99),3,IF(AZ10<=IFERROR(VLOOKUP(CONCATENATE(D10,YEAR(TODAY())-YEAR(C10),"pujottelu"),_viitearvot!$I$2:$M$205,5,FALSE()),99),2,1))))) | BD10: =IFERROR(MIN(BB10,BC10),"") | BE10: =IF(OR(BD10="",D10=""),"",IF(BD10<=IFERROR(VLOOKUP(CONCATENATE(D10,YEAR(TODAY())-YEAR(C10),"syotto"),_viitearvot!$I$2:$M$205,2,FALSE()),99),5,IF(BD10<=IFERROR(VLOOKUP(CONCATENATE(D10,YEAR(TODAY())-YEAR(C10),"syotto"),_viitearvot!$I$2:$M$205,3,FALSE()),99),4,IF(BD10<=IFERROR(VLOOKUP(CONCATENATE(D10,YEAR(TODAY())-YEAR(C10),"syotto"),_viitearvot!$I$2:$M$205,4,FALSE()),99),3,IF(BD10<=IFERROR(VLOOKUP(CONCATENATE(D10,YEAR(TODAY())-YEAR(C10),"syotto"),_viitearvot!$I$2:$M$205,5,FALSE()),99),2,1))))) | BG10: =IF(OR(BF10="",K10=""),"",(IF(D10="P",IF(K10<=IFERROR(VLOOKUP(CONCATENATE("P",ROUND(BF10,0),"lin5m"),_viitearvot!$A:$H,4,FALSE()),99),5,IF(K10<=IFERROR(VLOOKUP(CONCATENATE("P",ROUND(BF10,0),"lin5m"),_viitearvot!$A:$H,5,FALSE()),99),4,IF(K10<=IFERROR(VLOOKUP(CONCATENATE("P",ROUND(BF10,0),"lin5m"),_viitearvot!$A:$H,6,FALSE()),99),3,IF(K10<=IFERROR(VLOOKUP(CONCATENATE("P",ROUND(BF10,0),"lin5m"),_viitearvot!$A:$H,7,FALSE()),99),2,1)))),IF(K10<=IFERROR(VLOOKUP(CONCATENATE("T",ROUND(BF10,0),"lin5m"),_viitearvot!$A:$H,4,FALSE()),99),5,IF(K10<=IFERROR(VLOOKUP(CONCATENATE("T",ROUND(BF10,0),"lin5m"),_viitearvot!$A:$H,5,FALSE()),99),4,IF(K10<=IFERROR(VLOOKUP(CONCATENATE("T",ROUND(BF10,0),"lin5m"),_viitearvot!$A:$H,6,FALSE()),99),3,IF(K10<=IFERROR(VLOOKUP(CONCATENATE("T",ROUND(BF10,0),"lin5m"),_viitearvot!$A:$H,7,FALSE()),99),2,1))))))-L10)
K11: =IFERROR(MIN(H11,I11,J11),"") | L11: =IF(OR(K11="",D11=""),"",IF(K11<=IFERROR(VLOOKUP(CONCATENATE(D11,YEAR(TODAY())-YEAR(C11),"lin5m"),_viitearvot!$I$2:$M$205,2,FALSE()),99),5,IF(K11<=IFERROR(VLOOKUP(CONCATENATE(D11,YEAR(TODAY())-YEAR(C11),"lin5m"),_viitearvot!$I$2:$M$205,3,FALSE()),99),4,IF(K11<=IFERROR(VLOOKUP(CONCATENATE(D11,YEAR(TODAY())-YEAR(C11),"lin5m"),_viitearvot!$I$2:$M$205,4,FALSE()),99),3,IF(K11<=IFERROR(VLOOKUP(CONCATENATE(D11,YEAR(TODAY())-YEAR(C11),"lin5m"),_viitearvot!$I$2:$M$205,5,FALSE()),99),2,1))))) | P11: =IFERROR(MIN(M11,N11,O11),"") | Q11: =IF(OR(P11="",D11=""),"",IF(P11<=IFERROR(VLOOKUP(CONCATENATE(D11,YEAR(TODAY())-YEAR(C11),"lin10m"),_viitearvot!$I$2:$M$205,2,FALSE()),99),5,IF(P11<=IFERROR(VLOOKUP(CONCATENATE(D11,YEAR(TODAY())-YEAR(C11),"lin10m"),_viitearvot!$I$2:$M$205,3,FALSE()),99),4,IF(P11<=IFERROR(VLOOKUP(CONCATENATE(D11,YEAR(TODAY())-YEAR(C11),"lin10m"),_viitearvot!$I$2:$M$205,4,FALSE()),99),3,IF(P11<=IFERROR(VLOOKUP(CONCATENATE(D11,YEAR(TODAY())-YEAR(C11),"lin10m"),_viitearvot!$I$2:$M$205,5,FALSE()),99),2,1))))) | U11: =IFERROR(MIN(R11,S11,T11),"") | V11: =IF(OR(U11="",D11=""),"",IF(U11<=IFERROR(VLOOKUP(CONCATENATE(D11,YEAR(TODAY())-YEAR(C11),"lin20m"),_viitearvot!$I$2:$M$205,2,FALSE()),99),5,IF(U11<=IFERROR(VLOOKUP(CONCATENATE(D11,YEAR(TODAY())-YEAR(C11),"lin20m"),_viitearvot!$I$2:$M$205,3,FALSE()),99),4,IF(U11<=IFERROR(VLOOKUP(CONCATENATE(D11,YEAR(TODAY())-YEAR(C11),"lin20m"),_viitearvot!$I$2:$M$205,4,FALSE()),99),3,IF(U11<=IFERROR(VLOOKUP(CONCATENATE(D11,YEAR(TODAY())-YEAR(C11),"lin20m"),_viitearvot!$I$2:$M$205,5,FALSE()),99),2,1))))) | Z11: =IFERROR(MIN(W11,X11,Y11),"") | AA11: =IF(OR(Z11="",D11=""),"",IF(Z11<=IFERROR(VLOOKUP(CONCATENATE(D11,YEAR(TODAY())-YEAR(C11),"lin30m"),_viitearvot!$I$2:$M$205,2,FALSE()),99),5,IF(Z11<=IFERROR(VLOOKUP(CONCATENATE(D11,YEAR(TODAY())-YEAR(C11),"lin30m"),_viitearvot!$I$2:$M$205,3,FALSE()),99),4,IF(Z11<=IFERROR(VLOOKUP(CONCATENATE(D11,YEAR(TODAY())-YEAR(C11),"lin30m"),_viitearvot!$I$2:$M$205,4,FALSE()),99),3,IF(Z11<=IFERROR(VLOOKUP(CONCATENATE(D11,YEAR(TODAY())-YEAR(C11),"lin30m"),_viitearvot!$I$2:$M$205,5,FALSE()),99),2,1))))) | AE11: =IFERROR(MIN(AB11,AC11,AD11),"") | AF11: =IF(OR(AE11="",D11=""),"",IF(AE11<=IFERROR(VLOOKUP(CONCATENATE(D11,YEAR(TODAY())-YEAR(C11),"kasirata"),_viitearvot!$I$2:$M$205,2,FALSE()),99),5,IF(AE11<=IFERROR(VLOOKUP(CONCATENATE(D11,YEAR(TODAY())-YEAR(C11),"kasirata"),_viitearvot!$I$2:$M$205,3,FALSE()),99),4,IF(AE11<=IFERROR(VLOOKUP(CONCATENATE(D11,YEAR(TODAY())-YEAR(C11),"kasirata"),_viitearvot!$I$2:$M$205,4,FALSE()),99),3,IF(AE11<=IFERROR(VLOOKUP(CONCATENATE(D11,YEAR(TODAY())-YEAR(C11),"kasirata"),_viitearvot!$I$2:$M$205,5,FALSE()),99),2,1))))) | AJ11: =IFERROR(MIN(AG11,AH11,AI11),"") | AK11: =IF(OR(AJ11="",D11=""),"",IF(AJ11<=IFERROR(VLOOKUP(CONCATENATE(D11,YEAR(TODAY())-YEAR(C11),"smjuoksu"),_viitearvot!$I$2:$M$205,2,FALSE()),99),5,IF(AJ11<=IFERROR(VLOOKUP(CONCATENATE(D11,YEAR(TODAY())-YEAR(C11),"smjuoksu"),_viitearvot!$I$2:$M$205,3,FALSE()),99),4,IF(AJ11<=IFERROR(VLOOKUP(CONCATENATE(D11,YEAR(TODAY())-YEAR(C11),"smjuoksu"),_viitearvot!$I$2:$M$205,4,FALSE()),99),3,IF(AJ11<=IFERROR(VLOOKUP(CONCATENATE(D11,YEAR(TODAY())-YEAR(C11),"smjuoksu"),_viitearvot!$I$2:$M$205,5,FALSE()),99),2,1))))) | AN11: =IFERROR(MIN(AL11,AM11),"") | AO11: =IF(OR(AN11="",D11=""),"",IF(AN11<=IFERROR(VLOOKUP(CONCATENATE(D11,YEAR(TODAY())-YEAR(C11),"smpallo"),_viitearvot!$I$2:$M$205,2,FALSE()),99),5,IF(AN11<=IFERROR(VLOOKUP(CONCATENATE(D11,YEAR(TODAY())-YEAR(C11),"smpallo"),_viitearvot!$I$2:$M$205,3,FALSE()),99),4,IF(AN11<=IFERROR(VLOOKUP(CONCATENATE(D11,YEAR(TODAY())-YEAR(C11),"smpallo"),_viitearvot!$I$2:$M$205,4,FALSE()),99),3,IF(AN11<=IFERROR(VLOOKUP(CONCATENATE(D11,YEAR(TODAY())-YEAR(C11),"smpallo"),_viitearvot!$I$2:$M$205,5,FALSE()),99),2,1))))) | AS11: =IFERROR(MAX(AP11,AQ11,AR11),"") | AT11: =IF(OR(AS11="",D11=""),"",IF(AS11>=IFERROR(VLOOKUP(CONCATENATE(D11,YEAR(TODAY())-YEAR(C11),"cmj"),_viitearvot!$I$2:$M$205,2,FALSE()),0),5,IF(AS11>=IFERROR(VLOOKUP(CONCATENATE(D11,YEAR(TODAY())-YEAR(C11),"cmj"),_viitearvot!$I$2:$M$205,3,FALSE()),0),4,IF(AS11>=IFERROR(VLOOKUP(CONCATENATE(D11,YEAR(TODAY())-YEAR(C11),"cmj"),_viitearvot!$I$2:$M$205,4,FALSE()),0),3,IF(AS11>=IFERROR(VLOOKUP(CONCATENATE(D11,YEAR(TODAY())-YEAR(C11),"cmj"),_viitearvot!$I$2:$M$205,5,FALSE()),0),2,1))))) | AV11: =IFERROR(MAX(AU11),"") | AW11: =IF(OR(AV11="",D11=""),"",IF(AV11>=IFERROR(VLOOKUP(CONCATENATE(D11,YEAR(TODAY())-YEAR(C11),"bronco"),_viitearvot!$I$2:$M$205,2,FALSE()),0),5,IF(AV11>=IFERROR(VLOOKUP(CONCATENATE(D11,YEAR(TODAY())-YEAR(C11),"bronco"),_viitearvot!$I$2:$M$205,3,FALSE()),0),4,IF(AV11>=IFERROR(VLOOKUP(CONCATENATE(D11,YEAR(TODAY())-YEAR(C11),"bronco"),_viitearvot!$I$2:$M$205,4,FALSE()),0),3,IF(AV11>=IFERROR(VLOOKUP(CONCATENATE(D11,YEAR(TODAY())-YEAR(C11),"bronco"),_viitearvot!$I$2:$M$205,5,FALSE()),0),2,1))))) | AZ11: =IFERROR(MIN(AX11,AY11),"") | BA11: =IF(OR(AZ11="",D11=""),"",IF(AZ11<=IFERROR(VLOOKUP(CONCATENATE(D11,YEAR(TODAY())-YEAR(C11),"pujottelu"),_viitearvot!$I$2:$M$205,2,FALSE()),99),5,IF(AZ11<=IFERROR(VLOOKUP(CONCATENATE(D11,YEAR(TODAY())-YEAR(C11),"pujottelu"),_viitearvot!$I$2:$M$205,3,FALSE()),99),4,IF(AZ11<=IFERROR(VLOOKUP(CONCATENATE(D11,YEAR(TODAY())-YEAR(C11),"pujottelu"),_viitearvot!$I$2:$M$205,4,FALSE()),99),3,IF(AZ11<=IFERROR(VLOOKUP(CONCATENATE(D11,YEAR(TODAY())-YEAR(C11),"pujottelu"),_viitearvot!$I$2:$M$205,5,FALSE()),99),2,1))))) | BD11: =IFERROR(MIN(BB11,BC11),"") | BE11: =IF(OR(BD11="",D11=""),"",IF(BD11<=IFERROR(VLOOKUP(CONCATENATE(D11,YEAR(TODAY())-YEAR(C11),"syotto"),_viitearvot!$I$2:$M$205,2,FALSE()),99),5,IF(BD11<=IFERROR(VLOOKUP(CONCATENATE(D11,YEAR(TODAY())-YEAR(C11),"syotto"),_viitearvot!$I$2:$M$205,3,FALSE()),99),4,IF(BD11<=IFERROR(VLOOKUP(CONCATENATE(D11,YEAR(TODAY())-YEAR(C11),"syotto"),_viitearvot!$I$2:$M$205,4,FALSE()),99),3,IF(BD11<=IFERROR(VLOOKUP(CONCATENATE(D11,YEAR(TODAY())-YEAR(C11),"syotto"),_viitearvot!$I$2:$M$205,5,FALSE()),99),2,1))))) | BG11: =IF(OR(BF11="",K11=""),"",(IF(D11="P",IF(K11<=IFERROR(VLOOKUP(CONCATENATE("P",ROUND(BF11,0),"lin5m"),_viitearvot!$A:$H,4,FALSE()),99),5,IF(K11<=IFERROR(VLOOKUP(CONCATENATE("P",ROUND(BF11,0),"lin5m"),_viitearvot!$A:$H,5,FALSE()),99),4,IF(K11<=IFERROR(VLOOKUP(CONCATENATE("P",ROUND(BF11,0),"lin5m"),_viitearvot!$A:$H,6,FALSE()),99),3,IF(K11<=IFERROR(VLOOKUP(CONCATENATE("P",ROUND(BF11,0),"lin5m"),_viitearvot!$A:$H,7,FALSE()),99),2,1)))),IF(K11<=IFERROR(VLOOKUP(CONCATENATE("T",ROUND(BF11,0),"lin5m"),_viitearvot!$A:$H,4,FALSE()),99),5,IF(K11<=IFERROR(VLOOKUP(CONCATENATE("T",ROUND(BF11,0),"lin5m"),_viitearvot!$A:$H,5,FALSE()),99),4,IF(K11<=IFERROR(VLOOKUP(CONCATENATE("T",ROUND(BF11,0),"lin5m"),_viitearvot!$A:$H,6,FALSE()),99),3,IF(K11<=IFERROR(VLOOKUP(CONCATENATE("T",ROUND(BF11,0),"lin5m"),_viitearvot!$A:$H,7,FALSE()),99),2,1))))))-L11)
K12: =IFERROR(MIN(H12,I12,J12),"") | L12: =IF(OR(K12="",D12=""),"",IF(K12<=IFERROR(VLOOKUP(CONCATENATE(D12,YEAR(TODAY())-YEAR(C12),"lin5m"),_viitearvot!$I$2:$M$205,2,FALSE()),99),5,IF(K12<=IFERROR(VLOOKUP(CONCATENATE(D12,YEAR(TODAY())-YEAR(C12),"lin5m"),_viitearvot!$I$2:$M$205,3,FALSE()),99),4,IF(K12<=IFERROR(VLOOKUP(CONCATENATE(D12,YEAR(TODAY())-YEAR(C12),"lin5m"),_viitearvot!$I$2:$M$205,4,FALSE()),99),3,IF(K12<=IFERROR(VLOOKUP(CONCATENATE(D12,YEAR(TODAY())-YEAR(C12),"lin5m"),_viitearvot!$I$2:$M$205,5,FALSE()),99),2,1))))) | P12: =IFERROR(MIN(M12,N12,O12),"") | Q12: =IF(OR(P12="",D12=""),"",IF(P12<=IFERROR(VLOOKUP(CONCATENATE(D12,YEAR(TODAY())-YEAR(C12),"lin10m"),_viitearvot!$I$2:$M$205,2,FALSE()),99),5,IF(P12<=IFERROR(VLOOKUP(CONCATENATE(D12,YEAR(TODAY())-YEAR(C12),"lin10m"),_viitearvot!$I$2:$M$205,3,FALSE()),99),4,IF(P12<=IFERROR(VLOOKUP(CONCATENATE(D12,YEAR(TODAY())-YEAR(C12),"lin10m"),_viitearvot!$I$2:$M$205,4,FALSE()),99),3,IF(P12<=IFERROR(VLOOKUP(CONCATENATE(D12,YEAR(TODAY())-YEAR(C12),"lin10m"),_viitearvot!$I$2:$M$205,5,FALSE()),99),2,1))))) | U12: =IFERROR(MIN(R12,S12,T12),"") | V12: =IF(OR(U12="",D12=""),"",IF(U12<=IFERROR(VLOOKUP(CONCATENATE(D12,YEAR(TODAY())-YEAR(C12),"lin20m"),_viitearvot!$I$2:$M$205,2,FALSE()),99),5,IF(U12<=IFERROR(VLOOKUP(CONCATENATE(D12,YEAR(TODAY())-YEAR(C12),"lin20m"),_viitearvot!$I$2:$M$205,3,FALSE()),99),4,IF(U12<=IFERROR(VLOOKUP(CONCATENATE(D12,YEAR(TODAY())-YEAR(C12),"lin20m"),_viitearvot!$I$2:$M$205,4,FALSE()),99),3,IF(U12<=IFERROR(VLOOKUP(CONCATENATE(D12,YEAR(TODAY())-YEAR(C12),"lin20m"),_viitearvot!$I$2:$M$205,5,FALSE()),99),2,1))))) | Z12: =IFERROR(MIN(W12,X12,Y12),"") | AA12: =IF(OR(Z12="",D12=""),"",IF(Z12<=IFERROR(VLOOKUP(CONCATENATE(D12,YEAR(TODAY())-YEAR(C12),"lin30m"),_viitearvot!$I$2:$M$205,2,FALSE()),99),5,IF(Z12<=IFERROR(VLOOKUP(CONCATENATE(D12,YEAR(TODAY())-YEAR(C12),"lin30m"),_viitearvot!$I$2:$M$205,3,FALSE()),99),4,IF(Z12<=IFERROR(VLOOKUP(CONCATENATE(D12,YEAR(TODAY())-YEAR(C12),"lin30m"),_viitearvot!$I$2:$M$205,4,FALSE()),99),3,IF(Z12<=IFERROR(VLOOKUP(CONCATENATE(D12,YEAR(TODAY())-YEAR(C12),"lin30m"),_viitearvot!$I$2:$M$205,5,FALSE()),99),2,1))))) | AE12: =IFERROR(MIN(AB12,AC12,AD12),"") | AF12: =IF(OR(AE12="",D12=""),"",IF(AE12<=IFERROR(VLOOKUP(CONCATENATE(D12,YEAR(TODAY())-YEAR(C12),"kasirata"),_viitearvot!$I$2:$M$205,2,FALSE()),99),5,IF(AE12<=IFERROR(VLOOKUP(CONCATENATE(D12,YEAR(TODAY())-YEAR(C12),"kasirata"),_viitearvot!$I$2:$M$205,3,FALSE()),99),4,IF(AE12<=IFERROR(VLOOKUP(CONCATENATE(D12,YEAR(TODAY())-YEAR(C12),"kasirata"),_viitearvot!$I$2:$M$205,4,FALSE()),99),3,IF(AE12<=IFERROR(VLOOKUP(CONCATENATE(D12,YEAR(TODAY())-YEAR(C12),"kasirata"),_viitearvot!$I$2:$M$205,5,FALSE()),99),2,1))))) | AJ12: =IFERROR(MIN(AG12,AH12,AI12),"") | AK12: =IF(OR(AJ12="",D12=""),"",IF(AJ12<=IFERROR(VLOOKUP(CONCATENATE(D12,YEAR(TODAY())-YEAR(C12),"smjuoksu"),_viitearvot!$I$2:$M$205,2,FALSE()),99),5,IF(AJ12<=IFERROR(VLOOKUP(CONCATENATE(D12,YEAR(TODAY())-YEAR(C12),"smjuoksu"),_viitearvot!$I$2:$M$205,3,FALSE()),99),4,IF(AJ12<=IFERROR(VLOOKUP(CONCATENATE(D12,YEAR(TODAY())-YEAR(C12),"smjuoksu"),_viitearvot!$I$2:$M$205,4,FALSE()),99),3,IF(AJ12<=IFERROR(VLOOKUP(CONCATENATE(D12,YEAR(TODAY())-YEAR(C12),"smjuoksu"),_viitearvot!$I$2:$M$205,5,FALSE()),99),2,1))))) | AN12: =IFERROR(MIN(AL12,AM12),"") | AO12: =IF(OR(AN12="",D12=""),"",IF(AN12<=IFERROR(VLOOKUP(CONCATENATE(D12,YEAR(TODAY())-YEAR(C12),"smpallo"),_viitearvot!$I$2:$M$205,2,FALSE()),99),5,IF(AN12<=IFERROR(VLOOKUP(CONCATENATE(D12,YEAR(TODAY())-YEAR(C12),"smpallo"),_viitearvot!$I$2:$M$205,3,FALSE()),99),4,IF(AN12<=IFERROR(VLOOKUP(CONCATENATE(D12,YEAR(TODAY())-YEAR(C12),"smpallo"),_viitearvot!$I$2:$M$205,4,FALSE()),99),3,IF(AN12<=IFERROR(VLOOKUP(CONCATENATE(D12,YEAR(TODAY())-YEAR(C12),"smpallo"),_viitearvot!$I$2:$M$205,5,FALSE()),99),2,1))))) | AS12: =IFERROR(MAX(AP12,AQ12,AR12),"") | AT12: =IF(OR(AS12="",D12=""),"",IF(AS12>=IFERROR(VLOOKUP(CONCATENATE(D12,YEAR(TODAY())-YEAR(C12),"cmj"),_viitearvot!$I$2:$M$205,2,FALSE()),0),5,IF(AS12>=IFERROR(VLOOKUP(CONCATENATE(D12,YEAR(TODAY())-YEAR(C12),"cmj"),_viitearvot!$I$2:$M$205,3,FALSE()),0),4,IF(AS12>=IFERROR(VLOOKUP(CONCATENATE(D12,YEAR(TODAY())-YEAR(C12),"cmj"),_viitearvot!$I$2:$M$205,4,FALSE()),0),3,IF(AS12>=IFERROR(VLOOKUP(CONCATENATE(D12,YEAR(TODAY())-YEAR(C12),"cmj"),_viitearvot!$I$2:$M$205,5,FALSE()),0),2,1))))) | AV12: =IFERROR(MAX(AU12),"") | AW12: =IF(OR(AV12="",D12=""),"",IF(AV12>=IFERROR(VLOOKUP(CONCATENATE(D12,YEAR(TODAY())-YEAR(C12),"bronco"),_viitearvot!$I$2:$M$205,2,FALSE()),0),5,IF(AV12>=IFERROR(VLOOKUP(CONCATENATE(D12,YEAR(TODAY())-YEAR(C12),"bronco"),_viitearvot!$I$2:$M$205,3,FALSE()),0),4,IF(AV12>=IFERROR(VLOOKUP(CONCATENATE(D12,YEAR(TODAY())-YEAR(C12),"bronco"),_viitearvot!$I$2:$M$205,4,FALSE()),0),3,IF(AV12>=IFERROR(VLOOKUP(CONCATENATE(D12,YEAR(TODAY())-YEAR(C12),"bronco"),_viitearvot!$I$2:$M$205,5,FALSE()),0),2,1))))) | AZ12: =IFERROR(MIN(AX12,AY12),"") | BA12: =IF(OR(AZ12="",D12=""),"",IF(AZ12<=IFERROR(VLOOKUP(CONCATENATE(D12,YEAR(TODAY())-YEAR(C12),"pujottelu"),_viitearvot!$I$2:$M$205,2,FALSE()),99),5,IF(AZ12<=IFERROR(VLOOKUP(CONCATENATE(D12,YEAR(TODAY())-YEAR(C12),"pujottelu"),_viitearvot!$I$2:$M$205,3,FALSE()),99),4,IF(AZ12<=IFERROR(VLOOKUP(CONCATENATE(D12,YEAR(TODAY())-YEAR(C12),"pujottelu"),_viitearvot!$I$2:$M$205,4,FALSE()),99),3,IF(AZ12<=IFERROR(VLOOKUP(CONCATENATE(D12,YEAR(TODAY())-YEAR(C12),"pujottelu"),_viitearvot!$I$2:$M$205,5,FALSE()),99),2,1))))) | BD12: =IFERROR(MIN(BB12,BC12),"") | BE12: =IF(OR(BD12="",D12=""),"",IF(BD12<=IFERROR(VLOOKUP(CONCATENATE(D12,YEAR(TODAY())-YEAR(C12),"syotto"),_viitearvot!$I$2:$M$205,2,FALSE()),99),5,IF(BD12<=IFERROR(VLOOKUP(CONCATENATE(D12,YEAR(TODAY())-YEAR(C12),"syotto"),_viitearvot!$I$2:$M$205,3,FALSE()),99),4,IF(BD12<=IFERROR(VLOOKUP(CONCATENATE(D12,YEAR(TODAY())-YEAR(C12),"syotto"),_viitearvot!$I$2:$M$205,4,FALSE()),99),3,IF(BD12<=IFERROR(VLOOKUP(CONCATENATE(D12,YEAR(TODAY())-YEAR(C12),"syotto"),_viitearvot!$I$2:$M$205,5,FALSE()),99),2,1))))) | BG12: =IF(OR(BF12="",K12=""),"",(IF(D12="P",IF(K12<=IFERROR(VLOOKUP(CONCATENATE("P",ROUND(BF12,0),"lin5m"),_viitearvot!$A:$H,4,FALSE()),99),5,IF(K12<=IFERROR(VLOOKUP(CONCATENATE("P",ROUND(BF12,0),"lin5m"),_viitearvot!$A:$H,5,FALSE()),99),4,IF(K12<=IFERROR(VLOOKUP(CONCATENATE("P",ROUND(BF12,0),"lin5m"),_viitearvot!$A:$H,6,FALSE()),99),3,IF(K12<=IFERROR(VLOOKUP(CONCATENATE("P",ROUND(BF12,0),"lin5m"),_viitearvot!$A:$H,7,FALSE()),99),2,1)))),IF(K12<=IFERROR(VLOOKUP(CONCATENATE("T",ROUND(BF12,0),"lin5m"),_viitearvot!$A:$H,4,FALSE()),99),5,IF(K12<=IFERROR(VLOOKUP(CONCATENATE("T",ROUND(BF12,0),"lin5m"),_viitearvot!$A:$H,5,FALSE()),99),4,IF(K12<=IFERROR(VLOOKUP(CONCATENATE("T",ROUND(BF12,0),"lin5m"),_viitearvot!$A:$H,6,FALSE()),99),3,IF(K12<=IFERROR(VLOOKUP(CONCATENATE("T",ROUND(BF12,0),"lin5m"),_viitearvot!$A:$H,7,FALSE()),99),2,1))))))-L12)
