Workbook

Sheet Polku
B2: PELAAJAPOLKU – yksilön konsepteista pelipaikkafundamentteihin
B4: 1. YKSILÖVAIHE (6–14 v) | D4: 2. SILTA (U14–U15) | F4: 3. MASTER (U15 →)
B5: 14 yksilön teknistaktista konseptia (Y-H0–H9, Y-P1–P4) joukkuekontekstissa. Egosentrinen 6–9 → summatiivinen 10–13(–14). Yksilövaihe jatkuu U13:n läpi ja tarvittaessa koko U14:n. → Välilehti: Youth-konseptit | C5: → | D5: Tarkistuslista: kaikki 14 konseptia hallussa. Konseptit syvennetään tulevan pelipaikan kontekstissa. Ei aikaista lukitsemista: ensisijainen + toissijainen pelipaikka. → Välilehti: Silta U14-U15 | E5: → | F5: Pelipaikkakohtaiset fundamentit (CB, FB, MID, AMID, ST, WI, GK). 1–4 uutta fundamenttia per kausi, muut ylläpitona. Skouttaus ja kehityskeskustelut fundamenttikoodeilla. → Välilehdet: pelipaikat + Matriisi
B7: Avainperiaate: | D7: Yksilön kehittäminen joukkuekontekstissa – konsepti opetetaan aina pelitilanteen (sisällön) kautta, ei irrallaan.
B8: Siirtymäsääntö 1: | D8: Master-vaiheeseen vasta, kun yksilökonseptit on käyty läpi (tarkistuslista, Silta-välilehti).
B9: Siirtymäsääntö 2: | D9: 1–4 uutta pelipaikkafundamenttia kaudessa. Järjestys: H0 ensin → pelipaikan identiteetti → yleisin puolustustilanne → rakentelurooli.
B10: Koodisto: | D10: Y-H7 = youth, vartioinnista irtaantuminen | CB-P4 = topparin pallollisen puolustaminen. Numerotaso = teema, kirjaintaso (a, b, c…) = konsepti eli pelaajan KPI. Sama koodi kulkee suunnittelusta skouttaukseen.
B12: Rajaus: | D12: Järjestelmä kattaa pelaajan teknistaktisen kehittämisen (pelikäsitys + tekniikka pelissä). Fyysis-motorinen ja psyykkinen kehittäminen kulkevat rinnalla omina polkuinaan (vrt. Ekkonon preference-malli).

Sheet Youth-konseptit
A1: YKSILÖN TEKNISTAKTISET KONSEPTIT (6–14 v) – opetetaan aina joukkuekontekstissa
A2: Taso-asteikko: 1 = ei näy pelissä | 2 = näkyy ohjatusti (valmentajan muistutuksella) | 3 = näkyy pelissä itsenäisesti. Konsepti on hallinnassa tasolla 3.
A3: Koodi | B3: Teema / konseptit (KPI) | C3: Sisältö (pelitilanne) | D3: Ikäpaino | E3: Pelimuoto | F3: Taso (1–3) | G3: Huomiot / kertaustarve
A4: Y-H0 | B4: Havainnointi (tiedon kerääminen) | C4: Kuljetanko vai syötänkö / Pelaaminen omalta pelipaikalta / Pallon pyytäminen | D4: 6–14, läpileikkaava | E4: 5v5 → 11v11
A5: Y-H0a | B5: a. Diagonaalinen sijoittuminen – laajempi näkökenttä
A6: Y-H0b | B6: b. Avoin peliasento
A7: Y-H0c | B7: c. Pään kääntäminen: avoin puoli ja sokea puoli
A8: Y-H0d | B8: d. Pallo kaukana → joukkueen tasapaino, kasvavat/pienenevät tilat
A9: Y-H0e | B9: e. Pallo lähellä → seuraava syöttösuunta ja lähin vastustaja
A10: Y-H0f | B10: f. Pallo tulossa → suora vastustaja
A11: Y-H0g | B11: g. Puolustaessa: kenet vartioin, vaarallisin pelaaja alueella, pallollisen tilanne, uudelleentasapainotus (taakse > eteen, sisään > ulos)
A12: Y-H1 | B12: Haltuunotto (ensimmäinen kosketus) | C12: Pallon haltuunotto (Get the ball) | D12: 6–9 perusta, syvenee 10–13 | E12: 5v5 → 8v8
A13: Y-H1a | B13: a. Käännä päätä pallon ollessa matkalla
A14: Y-H1b | B14: b. Hyökkää palloa vastaan (50/50, tilan voitto) vai odota (ohitus, vapaa tila)
A15: Y-H1c | B15: c. Ota haltuun optimiajalla – ei helpoimmalla hetkellä
A16: Y-H1d | B16: d. Suuntaa pallo tilaan, joka kytkee seuraavaan toimintoon / pois vastustajalta
A17: Y-H1e | B17: e. Molemmat jalat
A18: Y-H1f | B18: f. Isot ja pehmeät pinnat – älä pysäytä palloa (jatkuvuus)
B19: Tilanteet: etene tai ohita / jatkuvuus / suojaa
A20: Y-H2 | B20: Syöttäminen | C20: Syöttäminen (Passing the ball) | D20: 10–13 (tekniikka 6–9) | E20: 8v8 (tekniikka 5v5)
A21: Y-H2a | B21: a. Kerää tieto ennen syöttöä
A22: Y-H2b | B22: b. Päätöksenteon prioriteetit – mentaalinen kartta (etu ensin)
A23: Y-H2c | B23: c. Kova / pehmeä syöttö aikomuksen mukaan (houkuttelu = pehmeä, eteneminen = kova)
A24: Y-H2d | B24: d. Syötä niin, että vastaanottaja saa edun (oikea tila ja jalka, liike huomioiden)
A25: Y-H2e | B25: e. Anna väärää tietoa syötöllä – piilota aikomus
A26: Y-H2f | B26: f. Syötä ja liiku (jatkuvuus syötön jälkeen)
A27: Y-H2g | B27: g. Vaihtele lyhyitä ja pitkiä (pitkä vain edulla)
A28: Y-H2h | B28: h. Syöttö pallon suojaamisen välineenä (seinäsyöttö)
A29: Y-H2i | B29: i. Ajoitus – oikea konsepti oikeaan hetkeen
A30: Y-H2j | B30: j. Tekniset resurssit: perusteet + luovuus
A31: Y-H3 | B31: Tempokuljetus (driving) | C31: Kuljetanko vai syötänkö / Eteneminen pelissä (6–9) | D31: 6–9 ydin, päätökset 8–10 | E31: 5v5 → 8v8
A32: Y-H3a | B32: a. Pää ylhäällä – tieto avainkohteista kuljettaessa
A33: Y-H3b | B33: b. Pallo lähelle (puolustaja lähellä) vai kauas (tyhjää edessä)
A34: Y-H3c | B34: c. Sisä- ja ulkosyrjä taktisen aikomuksen mukaan
A35: Y-H3d | B35: d. Suunnanmuutokset – älä ole ennustettava
A36: Y-H3e | B36: e. Molemmat jalat – suojaava jalka puolustajan mukaan
A37: Y-H3f | B37: f. Leikkaa vastustajan eteen ohituksen jälkeen
A38: Y-H3g | B38: g. Syötä vai kuljeta: syötä jos tila kiinni / kaveri paremmassa asemassa
A39: Y-H3h | B39: h. Kuljeta kohti puolustajaa vapauttaaksesi kaverin (2v1:n lukeminen)
B40: Tilanteet: etene tai ohita / sido vastustaja / viivytä
...

Sheet Kysymyspankki
A1: VALMENTAJAN KYSYMYSPANKKI – kysymys tekee älykkään, käsky tottelevaisen (Ekkono, Block 3)
A2: Koodi | B2: Teema (konseptit Youth-välilehdellä) | C2: Ohjaavat avainkysymykset pelin ja harjoituksen aikana
A3: Y-H0 | B3: Havainnointi (tiedon kerääminen) | C3: Mitä näit ennen kuin pallo tuli sinulle?
C4: Missä lähin vastustaja oli, kun otit pallon?
C5: Milloin viimeksi käänsit päätäsi?
A6: Y-H1 | B6: Haltuunotto (ensimmäinen kosketus) | C6: Minne ensimmäinen kosketuksesi vei pallon – ja miksi?
C7: Olisitko voinut ottaa pallon aikaisemmin/aggressiivisemmin?
C8: Mihin toimintoon kosketuksesi kytkeytyi?
A9: Y-H2 | B9: Syöttäminen | C9: Miksi valitsit juuri tuon syötön?
C10: Kumpaan jalkaan / mihin tilaan kaveri halusi pallon?
C11: Minne liikuit syöttösi jälkeen?
A12: Y-H3 | B12: Tempokuljetus (driving) | C12: Milloin kannattaa kuljettaa ja milloin syöttää?
C13: Ketä kuljetuksesi sitoi – ja kuka vapautui?
C14: Miksi pidit pallon lähellä / työnsit sen kauas?
A15: Y-H4 | B15: Harhauttaminen (dribbling) | C15: Kummalle puolelle puolustaja antoi tilaa?
C16: Mikä sai puolustajan liikkeelle harhautuksessasi?
C17: Mitä teit heti ohituksen jälkeen?
A18: Y-H5 | B18: Pallon suojaaminen | C18: Missä kehosi oli suhteessa vastustajaan?
C19: Näitkö suojatessasi, minne voit syöttää?
C20: Mihin tilaan käännyit – miksi sinne?
A21: Y-H6 | B21: Tuen tarjoaminen | C21: Näkeekö pallollinen sinut nyt?
C22: Kuka muu on samalla syöttölinjalla kanssasi?
C23: Mistä voisit auttaa niin, että ohitat oman vastustajasi?
A24: Y-H7 | B24: Vartioinnista irtaantuminen (unmarking) | C24: Minne puolustaja katsoi, kun lähdit?
C25: Miksi lähdit juuri sillä hetkellä?
C26: Mihin suuntaan liikuit ensin – ja minne halusit pallon?
A27: Y-H8 | B27: Leveyteen/syvyyteen pelaaminen | C27: Kuka venyttää kenttää, jos sinä kavennat?
C28: Kenelle tilasi syntyi?
C29: Milloin leveys auttaa enemmän kuin syvyys?
A30: Y-H9 | B30: Viimeistely (lisätty) | C30: Laukaus vai syöttö – mitä maalivahti ja puolustaja antoivat sinulle?
C31: Minne liikuit laukauksen jälkeen?
C32: Miksi valitsit sijoittamisen / voiman?
A33: Y-P1 | B33: 1v1-puolustaminen ja riisto + viivyttäminen | C33: Milloin pysähdyit – liian aikaisin vai liian myöhään?
C34: Mihin suuntaan ohjasit vastustajaa – miksi?
C35: Mitä teit, kun sinut ohitettiin?
A36: Y-P2 | B36: Vartiointi (marking) | C36: Näitkö pallon ja oman pelaajasi samaan aikaan?
C37: Pääsikö vastustaja selkäsi taakse – miksi?
C38: Miten säädit etäisyyttä, kun pallo liikkui?
A39: Y-P3 | B39: Varmistaminen (coverage) | C39: Missä olit, kun joukkuetoverisi prässäsi?
C40: Ketä sinä vartioit samalla, kun varmistit?
...

Sheet Pelaajakortti
A1: PELAAJAKORTTI – seuranta yksilövaiheesta Master-vaiheeseen (kopioi välilehti jokaiselle pelaajalle)
A3: Pelaajan nimi:
A4: Syntymävuosi:
A5: Ensisijainen pelipaikka:
A6: Toissijainen pelipaikka:
A8: A. YKSILÖVAIHE (6–14 v) – konseptien eteneminen
A9: Taso: 1 = ei näy pelissä, 2 = näkyy ohjatusti, 3 = näkyy pelissä itsenäisesti (= hallinnassa)
A10: Koodi | B10: Konsepti | C10: Taso (1–3) | D10: Pvm | E10: Arvioija | F10: Huomiot
A11: Y-H0 | B11: Havainnointi (tiedon kerääminen)
A12: Y-H1 | B12: Haltuunotto (ensimmäinen kosketus)
A13: Y-H2 | B13: Syöttäminen
A14: Y-H3 | B14: Tempokuljetus (driving)
A15: Y-H4 | B15: Harhauttaminen (dribbling)
A16: Y-H5 | B16: Pallon suojaaminen
A17: Y-H6 | B17: Tuen tarjoaminen
A18: Y-H7 | B18: Vartioinnista irtaantuminen (unmarking)
A19: Y-H8 | B19: Leveyteen/syvyyteen pelaaminen
A20: Y-H9 | B20: Viimeistely (lisätty)
A21: Y-P1 | B21: 1v1-puolustaminen ja riisto + viivyttäminen
A22: Y-P2 | B22: Vartiointi (marking)
... A24: Y-P4 | B24: Tilan puolustaminen ja merkkauksen vaihto
A26: B. SILTA U14–U15
A27: Tarkistuslista käyty (pvm ja arvioija):
A28: Syvennettävät youth-konseptit pelipaikan kontekstissa:
A29: Sovitut kertaukset ennen Master-vaihetta:
A31: C. MASTER-VAIHE (U15 →) – 1–4 uutta fundamenttia / kausi
A32: Kausi | B32: Opetellut fundamentit (koodit) | D32: Skouttausarvio tehty (pvm) | E32: Kehityssopimuksen painopisteet
A33: 1. kausi
A34: 2. kausi
A35: 3. kausi
A36: 4. kausi

Sheet Silta U14-U15
A1: SILTA U14–U15 – yksilövaiheesta pelipaikkafundamentteihin
A2: Periaatteet
A3: 1. Kaikki 14 yksilökonseptia käyty läpi U14:n loppuun mennessä (tarkistuslista alla).
A4: 2. Yksilön kehittäminen joukkuekontekstissa on avainasia – pelipaikka on uusi konteksti, ei uusi sisältö.
A5: 3. Master-vaiheessa 1–4 uutta fundamenttia per kausi (kausimalli alla).
A6: 4. Ei aikaista lukitsemista: ensisijainen + vähintään yksi toissijainen pelipaikka.
A8: A. TARKISTUSLISTA (U14-kehityskeskustelu – yksilövaiheen päätös)
A9: Hallinnassa = taso 3 Youth-konseptit-välilehden asteikolla (1 = ei näy pelissä, 2 = näkyy ohjatusti, 3 = näkyy pelissä itsenäisesti).
A10: Koodi | B10: Konsepti | C10: Hallinnassa (pvm) | D10: Kertaustarve | E10: Huomiot
A11: Y-H0 | B11: Havainnointi (tiedon kerääminen)
A12: Y-H1 | B12: Haltuunotto (ensimmäinen kosketus)
A13: Y-H2 | B13: Syöttäminen
A14: Y-H3 | B14: Tempokuljetus (driving)
A15: Y-H4 | B15: Harhauttaminen (dribbling)
A16: Y-H5 | B16: Pallon suojaaminen
A17: Y-H6 | B17: Tuen tarjoaminen
A18: Y-H7 | B18: Vartioinnista irtaantuminen (unmarking)
A19: Y-H8 | B19: Leveyteen/syvyyteen pelaaminen
A20: Y-H9 | B20: Viimeistely (lisätty)
A21: Y-P1 | B21: 1v1-puolustaminen ja riisto + viivyttäminen
A22: Y-P2 | B22: Vartiointi (marking)
... A24: Y-P4 | B24: Tilan puolustaminen ja merkkauksen vaihto
A26: B. SILTATAULUKKO – pelipaikkakohtaiset painotukset (U14–U15)
A27: Pelipaikka | B27: Syvennettävät youth-konseptit pelipaikan kontekstissa | D27: 1. Master-kauden fundamentit (max 4)
A28: Toppari (CB) | B28: Y-P1, Y-P2, Y-P3, Y-P4, Y-H2 (maasyötöt + pitkä), Y-H0 | D28: CB-H0, CB-P2, CB-P3, CB-H3
A29: Laitapuolustaja (FB) | B29: Y-P1, Y-P2, Y-P4, Y-H8 (leveys), Y-H3, Y-H0 | D29: FB-H0, FB-P4, FB-P6, FB-H5
A30: Keskikenttä (MID) | B30: Y-H0 (korostetusti), Y-H6, Y-H2, Y-H1 (paineessa), Y-P3, Y-P4 | D30: MID-H0, MID-H2, MID-H4, MID-P3
A31: Kymppi (AMID) | B31: Y-H7, Y-H6 (taskut), Y-H0, Y-H1 (kääntyminen), Y-P1 (vastaprässi) | D31: AMID-H0, AMID-H2, AMID-H4, AMID-P4
A32: Keskushyökkääjä (ST) | B32: Y-H7 (selustaan), Y-H5 (selkä maalille), Y-H9, Y-H8 (syvyys) | D32: ST-H0, ST-H1, ST-H2, ST-H5
A33: Laituri (WI) | B33: Y-H4 (1v1), Y-H8 (leveys), Y-H9, Y-H7, Y-P1 | D33: WI-H0, WI-H1, WI-H6, WI-H4
A34: Maalivahti (GK) | B34: Y-H0, Y-H1–H2 (jalkapeli) + MV-tekniikka (youth-polku puuttuu materiaalista) | D34: GK-H0, GK-H1, GK-P4, GK-P5
A36: C. KAUSIMALLI MASTER-VAIHEESSA (1–4 fundamenttia / kausi)
A37: Kausi | B37: Uudet fundamentit | D37: Ylläpito
A38: 1. kausi (U15, tarvittaessa U16) | B38: 4 fundamenttia (siltataulukon oikea sarake) | D38: Youth-konseptien kertaus pelipaikan kontekstissa
A39: 2. kausi | B39: 3–4 seuraavaa (loput puolustusfundamentit + hyökkäyksen ydin) | D39: Edellisen kauden fundamentit peleissä ja arvioinnissa
A40: 3. kausi | B40: Loput fundamentit + heikoimpien syventäminen | D40: Koko paketti käytössä, skouttaustyökalu täysimääräisesti
A41: 4. kausi → | B41: Yksilölliset painopisteet kehityskeskustelusta | D41: Kaikki fundamentit arvioinnissa
A43: Uusien fundamenttien järjestys: 1) H0 aina ensin 2) pelipaikan identiteettifundamentti 3) yleisin puolustustilanne 4) rakentelurooli.

Sheet Valitsin
B2: MASTER – FUNDAMENTTIEN VALINTATYÖKALU
B3: Kohderyhmä: pelipaikkakohtaiset fundamentit noin 14–15-vuotiaista alkaen, kun yksilön teknistaktiset konseptit on opeteltu.
B4: 0. MISSÄ VAIHEESSA PELAAJA ON? → Yksilövaihe 6–14 v: Youth-konseptit | Silta U14–U15: Silta-välilehti | Master U15 →: pelipaikkavälilehdet
B7: Näin valitset oikean fundamentin (3 kysymystä):
B8: 1. KUKA? → Valitse pelipaikka (välilehdet: CB, FB, MID, AMID, ST, WI, GK)
B9: 2. MIKÄ VAIHE? → Puolustus (P) vai hyökkäys (H)
B10: 3. MISSÄ? → RA ulkopuolella / RA sisällä / Siirtymät (puolustuksessa)
B12: Koodisto:
B13: Koodi = pelipaikka + vaihe + numero (+ alakohdan kirjain)
B14: Esim. CB-P4 = Topparin pallollisen puolustaminen
B15: Esim. WI-H6b = Laiturin 1v1 tilaedulla
B16: Käytä koodia muistiinpanoissa: "#14: WI-H6b ✓" (koodi = pelipaikka + vaihe + teeman numero + konseptin kirjain)
... B21: Pisteytysasteikko (skouttaus):
B22: 1 | C22: Merkittävä puute – toistuvia virheitä, konsepti ei näy pelissä
B23: 2 | C23: Kehittyvä – konsepti näkyy satunnaisesti, epäjohdonmukainen
B24: 3 | C24: Tasollaan – suorittaa luotettavasti normaalitilanteissa
B25: 4 | C25: Vahvuus – johdonmukainen myös paineen alla, harvoja virheitä
B26: 5 | C26: Erottuva huipputaso – hallitsee konseptin ja johtaa muita sen avulla
B28: Tarkat pisteytyskriteerit (1/3/5), harjoitesuositukset ja itsearvioinnit löytyvät pelipaikkakohtaisista työkalupaketeista (md-dokumentit).

Sheet Matriisi
A1: MASTER-MATRIISI – fundamentit × pelipaikat
A2: Koodi | B2: Vaihe/vyöhyke | C2: CB – Toppari | D2: FB – Laitapuolustaja | E2: MID – Keskikenttäpelaaja | F2: AMID – Hyökkäävä keskikenttäpelaaja | G2: ST – Keskushyökkääjä | H2: WI – Laituri | I2: GK – Maalivahti
A3: P1 | B3: RA ulkopuolella | C3: Puolustustasapainon ylläpitäminen | D3: Puolustustasapainon ylläpitäminen | E3: Puolustustasapainon ylläpitäminen | F3: Puolustustasapainon ylläpitäminen | G3: Puolustustasapainon ylläpitäminen | H3: Puolustustasapainon ylläpitäminen | I3: Puolustustasapainon ylläpitäminen (sijoittuminen suhteessa peliin)
A4: P2 | B4: RA ulkopuolella | C4: Merkattavan pelaajan tunnistaminen | D4: Merkattavan pelaajan tunnistaminen | E4: Merkattavan pelaajan tunnistaminen | F4: Puolustettavan pelaajan tunnistaminen | G4: Merkattavan pelaajan tunnistaminen | H4: Merkattavan pelaajan tunnistaminen | I4: Selustan tilan puolustaminen (sweeper-rooli)
A5: P3 | B5: RA ulkopuolella | C5: Tilan puolustaminen | D5: Tilan puolustaminen | E5: Tilan puolustaminen | F5: Tilan puolustaminen | G5: Tilan puolustaminen | H5: Tilan puolustaminen | I5: Pelin ohjaaminen ja kommunikaatio
A6: P4 | B6: RA sisällä | C6: Pallollisen puolustaminen | D6: Pallollisen puolustaminen | E6: Pallollisen puolustaminen | F6: Pallollisen puolustaminen | G6: Pallollisen puolustaminen | H6: Pallollisen puolustaminen | I6: Maalinteon estäminen (torjuminen)
A7: P5 | B7: RA sisällä | C7: Boksin vapauttaminen | D7: Rangaistusalueen vapauttaminen | E7: Rangaistusalueen vapauttaminen | F7: Vastahyökkäyksiin valmistautuminen | G7: Vastahyökkäyksiin valmistautuminen | H7: Vastahyökkäyksiin valmistautuminen | I7: Keskitysten ja laitapallojen hallinta
A8: P6 | B8: Siirtymät | C8: Keskityksen puolustaminen | D8: Keskityksen puolustaminen | E8: Keskityksen puolustaminen | F8: Jatkotilanteiden ennakointi | G8: Jatkotilanteiden ennakointi | H8: Jatkotilanteiden ennakointi | I8: Jatkotilanteiden ennakointi
A9: P7 | B9: RA sisällä | C9: Puolustaminen vaara-alueilla | D9: Puolustaminen vaara-alueilla | E9: Puolustaminen vaara-alueilla | F9: – | G9: – | H9: – | I9: –
A10: P8 | B10: Siirtymät | C10: Jatkotilanteiden ennakointi | D10: Jatkotilanteiden ennakointi | E10: Jatkotilanteiden ennakointi | F10: – | G10: – | H10: – | I10: –
A11: H0 | B11: Hyökkäys | C11: Tiedon kerääminen (skannaus) | D11: Tiedon kerääminen (skannaus) | E11: Tiedon kerääminen (skannaus) | F11: Tiedon kerääminen (skannaus) | G11: Tiedon kerääminen (skannaus) | H11: Tiedon kerääminen (skannaus) | I11: Tiedon kerääminen (skannaus)
A12: H1 | B12: Hyökkäys | C12: Hyökkäystasapainon ylläpitäminen (asemahyökkäys) | D12: Hyökkäystasapainon ylläpitäminen | E12: Hyökkäystasapainon ylläpitäminen | F12: Hyökkäystasapainon ylläpitäminen | G12: Tilan luominen ja syvyyden tuottaminen hyökkäykseen (asemahyökkäys) | H12: Leveyden takaaminen | I12: Pelin avaaminen
A13: H2 | B13: Hyökkäys | C13: Tukien tarjoaminen | D13: Tukien tarjoaminen | E13: Tukien tarjoaminen | F13: Tukien tarjoaminen | G13: Hyökkäyksen liikuttaminen | H13: Hyökkäyksen liikuttaminen | I13: Tukien tarjoaminen (ylimääräinen pelaaja rakentelussa)
... A18: H7 | B18: Hyökkäys | C18: – | D18: – | E18: – | F18: – | G18: Jatkotilanteiden ennakointi | H18: Jatkotilanteiden ennakointi | I18: –

Sheet Harjoitepankki
A1: HARJOITEPANKKI – painopisteet ja harjoite-esimerkit kehityskohteittain (lähde: md-työkalupaketit)
A2: Koodi | B2: Pelipaikka | C2: Kehityskohde (teema) | D2: Painopisteet ja harjoite-esimerkit
A3: CB-P1 | B3: Toppari | C3: Puolustustasapaino | D3: Linjapuolustusharjoitteet 4v4–8v8 isolla kentällä; videoklipit omista otteluista (linjan syvyys/leveys); kommunikaatiovastuun antaminen harjoituspeleissä
A4: CB-P2 | B4: Toppari | C4: Merkkaus & skannaus | D4: Pienpelit merkkaussäännöillä (mies–mies boksissa); skannausfrekvenssin laskenta videolta; 2v2+2 välitilapuolustus
A5: CB-P3 | B5: Toppari | C5: Tilan puolustaminen | D5: 2v2/3v3 syvyysjuoksuilla; varmistusharjoitteet (prässi + kouvraus pareittain); alivoimapuolustus 2v3, 3v4 viivyttäen
A6: CB-P4 | B6: Toppari | C6: Pallollisen puolustaminen | D6: Toistuvat 1v1-tilanteet eri lähtöasetelmilla (kasvot/selkä, vauhdista); prässitekniikka: lähestymiskulma, asento, ajoitus
A7: CB-P5 | B7: Toppari | C7: Boksin vapauttaminen | D7: Pelinomaiset linjannostoharjoitteet takaisinsyötöistä ja purkupalloista; paitsiolinjan yhteispeli MV:n kanssa
A8: CB-P6 | B8: Toppari | C8: Keskityksen puolustaminen | D8: Keskityspuolustus 4v4–6v6 boksissa (tolppavastuut); pääpallokamppailut kuormitettuna; MV-yhteistyö väliin tulevissa palloissa
A9: CB-P7 | B9: Toppari | C9: Vaara-alueet | D9: Blokkausharjoitteet; 1v1 boksissa loppuun asti -sääntö pienpeleissä; toistot väsyneenä (pelinomainen kuormitus)
A10: CB-P8 | B10: Toppari | C10: Ennakointi | D10: Reaktio- ja irtopallopelit; video: mitä tapahtuu 2 s laukauksen/pääpallon jälkeen
A11: CB-H0 | B11: Toppari | C11: Tiedon kerääminen (skannaus) | D11: Rondot ja possessiopelit skannaussäännöllä (esim. pään käännyttävä 2× ennen vastaanottoa); värikoodipelit (valmentaja näyttää värin, pelaajan nimettävä se vastaanoton yhteydessä); skannausfrekvenssin laskenta videolta (huipputaso ~0,5 s välein ennen vastaanottoa)
A12: CB-H1 | B12: Toppari | C12: Hyökkäystasapaino & tuet | D12: Rakentelupelit 4v2 → 8v6 prässiä vastaan; sijoittuminen nousussa (rest defence)
A13: CB-H2 | B13: Toppari | C13: Hyökkäystasapaino & tuet | D13: Rakentelupelit 4v2 → 8v6 prässiä vastaan; sijoittuminen nousussa (rest defence)
... A94: GK-H5 | B94: Maalivahti | C94: Sijoittuminen hallinnassa | D94: Rest defence -harjoitteet: MV:n sijainti joukkueen hyökätessä + reaktio menetykseen (sweeper-valmius)

Sheet Ydinkonseptit
A1: YDINKONSEPTIT – mitä pelaajan tulee ymmärtää (kehityskeskustelun tausta-aineisto)
A2: Pelipaikka | B2: Ydinkonsepti | C2: Mitä pelaajan tulee ymmärtää
A3: Toppari (CB) | B3: Tiedon kerääminen (skannaus) | C3: Kaiken perusta: skannaa ennen palloa, älä pallon kanssa. Diagonaalinen sijoittuminen ja avoin peliasento antavat näkymän eteen ja taakse – ratkaisu on tehty jo ennen vastaanottoa.
B4: Puolustuslinjan tasapaino | C4: Linja liikkuu yhtenä yksikkönä pallon, tilan ja vastustajan mukaan. Syvyys määräytyy: onko pallolliseen prässi vai ei.
B5: Merkkaus ja skannaus | C5: "Pallo–vastustaja–tila" -kolmio: näe kaikki kolme jatkuvasti. Asento sivuttain, ei koskaan selkä pelille.
B6: Varmistaminen | C6: Kun pelikaveri prässää, sinä varmistat. Varmistuskulma ja -etäisyys: pystyt puuttumaan sekä ohituskuljetukseen että syöttöön selustaan.
B7: Prässi ohittumatta | C7: Lähesty nopeasti, hidasta viimeiset metrit, matala asento, ohjaa huonompaan suuntaan. Älä sukella.
B8: Boksin vapauttaminen ja linjan nosto | C8: Jokainen taaksepäin menevä pallo = mahdollisuus nostaa. Alas jääminen kutsuu vaaran boksiin.
B9: Keskitysten puolustaminen ja puolustaminen vaara-alueilla | C9: Boksissa merkkaus on 1v1-vastuu: näe pallo ja mies. Ykköstolppa katetaan aina, kakkostolppa MV:n 1v1:ssä.
B10: Jatkotilanteiden ennakointi | C10: Tilanne ei pääty laukaukseen tai pääpalloon – ennakoi torjunta, pudotus, irtopallo.
B11: Rakentelu ja ylivoiman luonti | C11: Toppari on nykyfutiksen ensimmäinen pelintekijä: syöttövalinta, sitova kuljetus ja pelin kääntö rikkovat vastustajan ensimmäisen prässilinjan.
A12: Laitapuolustaja (FB) | B12: Tiedon kerääminen (skannaus) | C12: Kaiken perusta: skannaa ennen palloa, älä pallon kanssa. Laitapuolustajan erityisyys: laita antaa "selkäsuojan", joten avoin peliasento kohti kenttää avaa lähes koko pelin näkymän.
B13: Kaksi roolia laidasta riippuen | C13: Pallonpuoleinen laitapuolustaja puolustaa keskityslinjalla lähellä palloa; vastakkaisen laidan puolustaja kaventaa keskelle ja ottaa miesvartioinnin rangaistusalueelle tulevasta pelaajasta. Roolin tunnistus joka tilanteessa.
B14: Varmistaminen ja pudottaminen | C14: Kun keskustoppari prässää, laitapuolustaja varmistaa. Kun syöttö selustaan on mahdollinen, pudota ennen syöttöä – ei sen jälkeen.
B15: Prässi ja ohjaaminen | C15: Laidalla sivuraja on lisäpuolustaja: ohjaa vastustaja kohti rajaa tai varmistusta, älä päästä sisäkaistalle. Älä anna ohittaa itseäsi.
B16: Merkattavan seuraaminen | C16: Vastustajan laituri on ensisijainen vastuu, mutta valppaus säilyy myös oman joukkueen hyökätessä – tilanteenvaihto alkaa jo ennen menetystä.
B17: Rangaistusalueen vapauttaminen | C17: Älä valu alas turhaan. Jokainen taaksepäin siirtyvä pallo on mahdollisuus nostaa ja vapauttaa alue.
B18: Jatkotilanteiden ennakointi | C18: Laukauksen tai ilmapallokamppailun aikana asema ratkaisee: pudota ja kavenna keskikaistalle jo ennen kuin pallo irtoaa.
B19: Hyökkäyksen tukeminen ja mukaan nouseminen | C19: Laitapuolustaja luo leveyttä tai sisäkaistaylivoimaa pelitavasta riippuen. Mukaan nousun ajoitus: nouse, kun tila on syntynyt ja tasapaino takana on turvattu – ei aina.
A20: Keskikenttäpelaaja (MID) | B20: Tiedon kerääminen (skannaus) | C20: Keskikenttäpelaaja pelaa 360 asteen ympäristössä – skannaus on hänelle kriittisempi kuin kenellekään muulle. Diagonaalinen sijoittuminen ja avoin peliasento; ratkaisu valmiina ennen vastaanottoa.
B21: Keskustan hallinta puolustaessa | C21: Keskusta on kentän arvokkain alue: leveys- ja syvyystasapaino keskikenttälinjassa ratkaisee, pääseekö vastustaja pelaamaan linjojen välistä.
B22: Syöttölinjojen sulkeminen | C22: Prässi ei ole vain juoksemista palloa kohti: oikea peittokulma vähentää vastustajan syöttövaihtoehtoja ja tekee prässistä organisoidun.
B23: Varmistukset ja pudottautuminen | C23: Keskikenttäpelaaja paikkaa kahta linjaa: varmistaa keskikenttälinjassa ja pudottautuu tarvittaessa keskustopparin rooliin (keskitykset, epätasapaino).
B24: Muodon sisässä pelaaminen | C24: Tukien tarjoaminen vastustajan muodon sisällä (linjojen välissä) rikkoo prässin. Hätätuki, jatkuvuustuki ja syöttölinjojen avaaminen ovat saman konseptin eri tasoja.
B25: Pelin avaamisen varmistaminen | C25: Avausvaihe kulkee keskikentän kautta tai epäonnistuu: liike oikeaan tilaan oikeaan aikaan, tarvittaessa oman pelipaikan ulkopuolelle.
B26: Hyökkäyspelin organisointi | C26: Syöttöpeli ennen kuljettamista, eteneminen ennen sivuttaissiirtelyä – mutta riski minimoiden. Syöttö etuun ja liike syötön jälkeen pitävät pelin elävänä.
B27: Jatkotilanteiden ennakointi ja tilanteenvaihto | C27: Ennakoi sekä katkot että oman joukkueen menetykset – keskikenttäpelaaja on vastaprässin ensimmäinen lenkki.
A28: Hyökkäävä keskikenttäpelaaja (AMID) | B28: Tiedon kerääminen (skannaus) | C28: Kympin peli ratkeaa ennen vastaanottoa: taskuissa pelaava saa palloa ahtaimmissa tiloissa, joten skannauksen frekvenssi ja avoin peliasento ratkaisevat, kääntyykö peli eteenpäin.
B29: Linjojen välissä pelaaminen (taskut) | C29: Tuki vastustajan keskikenttä- ja puolustuslinjan välissä rikkoo vastustajan rakenteen. Liiku vastustajan katveessa – näy pallolliselle, pysy piilossa vartijalta.
B30: Pudottautuminen vs. syvyysjuoksu | C30: Kympin kaksi asetta: pudottaudu tueksi tai juokse syvyyteen. Vuorottelu tekee pelistä lukukelvotonta ja luo epätasapainoa.
B31: Sisäkaistojen tasapaino | C31: Hyökkäystasapaino on kympillä tilojen hallintaa: sisäkaistat eivät saa tyhjentyä eivätkä ruuhkautua. Oman pelipaikan jättäminen on sallittua, kun joukkueen organisaatio säilyy.
B32: Aloitteen vieminen ja vastaprässi | C32: Puolustaminen alkaa menetyshetkestä: lähin pelaaja prässää välittömästi. Kymppi on vastaprässin käynnistäjä ylimpänä keskikenttäpelaajana.
B33: Keskustan suojaaminen puolustaessa | C33: Estä syötöt sisäkaistoille ja meitä syvemmälle sekä pelinkäännöt sisätuen kautta – kympin puolustustyö suuntaa vastustajan pelin laitoihin.
B34: Vastahyökkäysten käynnistäminen | C34: Pallonvoiton jälkeen ensimmäinen tuki ja ensimmäinen etenevä syöttö kulkevat kympin kautta. Valmistaudu jo puolustaessasi.
B35: Hyökkäyspelin organisointi ja boksiin liikkuminen | C35: Etenevä peli edullisilla alueilla, syöttö etuun, liike syötön jälkeen – ja keskityksissä juoksu tyhjään tilaan rangaistusalueelle.
A36: Keskushyökkääjä (ST) | B36: Tiedon kerääminen (skannaus) | C36: Kärki pelaa useimmin selkä maalille ja vartija selässä – skannaus ennen vastaanottoa kertoo, voiko kääntyä vai pitääkö pudottaa. Diagonaalinen sijoittuminen suhteessa pallolliseen pitää sekä pallon että selustan näkyvissä.
B37: Syvyyden varmistaminen | C37: Kärjen tärkein rakenteellinen tehtävä: venytä vastustajan puolustuslinjaa. Ilman syvyysuhkaa koko joukkueen tilat katoavat.
B38: Vapaiden juoksujen vaihtelu | C38: Selusta vai jalkoihin, ykköstolppa vai kakkostolppa, pudottautuminen vai syvyys – vaihtelu tekee kärjestä lukukelvottoman. Liike syötön jälkeen on yhtä tärkeä kuin liike ennen syöttöä.
B39: Selkä maalille -peli | C39: Pudottautuminen tueksi, pallon pito paineen alla ja seinäsyötöt liittävät kärjen rakenteluun. Tarvittaessa tuki oman pelipaikan ulkopuolelta.
B40: Ensimmäisen prässilinjan johtaminen | C40: Kärjen prässi ei ole vain juoksemista: ohjaa vastustajan avaus laidalle tai haluttuun suuntaan ja tee siitä ennustettavaa joukkueelle. Yhden ja kahden kärjen ryhmityksissä eri vastuut.
...

Sheet CB Toppari
A1: TOPPARI (CB) – skouttaus + itsearviointi + kehityskeskustelu samalla sivulla
A2: Koodi | B2: Vyöhyke | C2: Teema / konseptit (KPI) | D2: Valm. arvio | E2: Itsearvio | F2: Ero | G2: Kriteerit 1 / 3 / 5 | H2: Harjoitesuositus (automaattinen, kun arvio 1–2) | I2: Huomiot
A3: CB-P1 | B3: RA ulkopuolella | C3: 1. PUOLUSTUSTASAPAINON YLLÄPITÄMINEN | F3: =IF(AND(D3<>"",E3<>""),D3-E3,"") | G3: 1: Linja hajoaa; jää väärään syvyyteen; ei palauta tasapainoa 3: Pitää linjan leveys- ja syvyystasapainon normaalitilanteissa 5: Ohjaa koko linjaa; korjaa tasapainon ennakoivasti ennen kuin vaara syntyy | H3: =IF(OR(D3="1",D3="2",E3="1",E3="2",D3=1,D3=2,E3=1,E3=2),IFERROR(VLOOKUP(A3,Harjoitepankki!$A:$D,4,FALSE()),""),"")
A4: CB-P1a | C4: a. Ylläpidä puolustuslinjan tasapaino leveyssuunnassa
A5: CB-P1b | C5: b. Ylläpidä puolustuslinjan tasapaino syvyyssuunnassa
A6: CB-P1c | C6: c. Palauta tasapaino tilanteen rikkoutuessa
A7: CB-P1d | C7: d. Tasapainota puolustuslinja uudelleen
A8: CB-P2 | B8: RA ulkopuolella | C8: 2. MERKATTAVAN PELAAJAN TUNNISTAMINEN | F8: =IF(AND(D8<>"",E8<>""),D8-E8,"") | G8: 1: Menettää merkattavan; katse vain pallossa; yllättyy välitilasyötöistä 3: Pitää pallon ja hyökkääjän näkökentässä; sijoittuu oikein 5: Ennakoi vastustajan liikkeet; tiivistää välitilat ennen syöttöä; valmiina myös oman hyökkäyksen aikana | H8: =IF(OR(D8="1",D8="2",E8="1",E8="2",D8=1,D8=2,E8=1,E8=2),IFERROR(VLOOKUP(A8,Harjoitepankki!$A:$D,4,FALSE()),""),"")
A9: CB-P2a | C9: a. Sijoitu oikeassa peliasennossa (rintamasuunta ja kehon asento siten, että pystyt reagoimaan nopeasti joka suuntaan) / pidä hyökkääjä ja pallo näkökentässäsi
A10: CB-P2b | C10: b. Sijoitu oikein suhteessa merkattavaan pelaajaan
A11: CB-P2c | C11: c. Tiivistä tila, kun vastustaja voi vastaanottaa pallon linjojen välissä
A12: CB-P2d | C12: d. Säilytä puolustusvalmius oman joukkueen hyökätessä
A13: CB-P3 | B13: RA ulkopuolella | C13: 3. TILAN PUOLUSTAMINEN | F13: =IF(AND(D13<>"",E13<>""),D13-E13,"") | G13: 1: Ei varmista; selusta auki; alivoimassa lähtee vääriin prässiin 3: Varmistaa pelikaveria; puolustaa selustan syötöt luotettavasti 5: Lukee syvyysjuoksut aikaisin; hallitsee sisään–ulos-liikkeiden puolustamisen; viivyttää alivoimassa taitavasti | H13: =IF(OR(D13="1",D13="2",E13="1",E13="2",D13=1,D13=2,E13=1,E13=2),IFERROR(VLOOKUP(A13,Harjoitepankki!$A:$D,4,FALSE()),""),"")
A14: CB-P3a | C14: a. Varmista palloa prässäävää topparia tai laitapuolustajaa
A15: CB-P3b | C15: b. Peräänny nopeasti ennakoiden syöttö topparin taakse jäävään tilaan
A16: CB-P3c | C16: c. Ensimmäinen keskustoppari puolustaa niin, että hän estää vapaat juoksut selustaansa
A17: CB-P3d | C17: d. Toisen keskustopparin miesvartiointi (1v1-puolustaminen), kun hyökkääjä liikkuu topparien väliseen tilaan (sisään–ulos-liike)
A18: CB-P3e | C18: e. Viivytä perääntyen alivoimatilanteessa
A19: CB-P4 | B19: RA ulkopuolella | C19: 4. PALLOLLISEN PUOLUSTAMINEN | F19: =IF(AND(D19<>"",E19<>""),D19-E19,"") | G19: 1: Tulee ohitetuksi 1v1; ei reagoi seinäsyöttöihin 3: Prässää hallitusti ohittumatta normaalitilanteissa 5: Voittaa 1v1-tilanteet toistuvasti; katkaisee yhdistelyt ennakoiden | H19: =IF(OR(D19="1",D19="2",E19="1",E19="2",D19=1,D19=2,E19=1,E19=2),IFERROR(VLOOKUP(A19,Harjoitepankki!$A:$D,4,FALSE()),""),"")
A20: CB-P4a | C20: a. Älä anna vastustajan ohittaa itseäsi, kun prässäät pallollista pelaajaa
A21: CB-P4b | C21: b. Pudota nopeasti alemmas katkaisemaan hyökkääjän mahdollinen eteneminen, jos hän pelaa yhteen joukkuetoverinsa kanssa (esim. seinäsyöttötilanteessa)
A22: CB-P5 | B22: RA sisällä | C22: 5. BOKSIN VAPAUTTAMINEN | F22: =IF(AND(D22<>"",E22<>""),D22-E22,"") | G22: 1: Jää boksiin puolustamaan turhaan; ei nosta linjaa 3: Poistuu boksista oikeissa tilanteissa; nostaa linjan takaisinsyötöistä 5: Johtaa linjan nostot äänellä ja esimerkillä; ajoitus ennakoiva | H22: =IF(OR(D22="1",D22="2",E22="1",E22="2",D22=1,D22=2,E22=1,E22=2),IFERROR(VLOOKUP(A22,Harjoitepankki!$A:$D,4,FALSE()),""),"")
A23: CB-P5a | C23: a. Älä valu puolustamaan rangaistusalueen sisälle, kun pallo on keskellä rangaistusalueen ulkopuolella
A24: CB-P5b | C24: b. Nosta linja vastustajan syöttäessä taaksepäin
A25: CB-P5c | C25: c. Poistu boksista, kun pallo on purettu
A26: CB-P6 | B26: RA sisällä | C26: 6. KESKITYKSEN PUOLUSTAMINEN | F26: =IF(AND(D26<>"",E26<>""),D26-E26,"") | G26: 1: Häviää keskityspaikat; ykköstolppa auki; kadottaa merkattavan 3: Puolustaa keskitykset ja oman alueensa luotettavasti 5: Hallitsee ilmatilan; voittaa 1v1-kamppailut boksissa; suojaa maalivahdin ja välin | H26: =IF(OR(D26="1",D26="2",E26="1",E26="2",D26=1,D26=2,E26=1,E26=2),IFERROR(VLOOKUP(A26,Harjoitepankki!$A:$D,4,FALSE()),""),"")
A27: CB-P6a | C27: a. Pudota nopeasti, kun keskitys puolustuslinjan ja maalivahdin väliin on mahdollinen
A28: CB-P6b | C28: b. Ykköstolpan alueen puolustaminen
A29: CB-P6c | C29: c. Puolusta maalintekijät 1v1 keskitystilanteessa
A30: CB-P7 | B30: RA sisällä | C30: 7. PUOLUSTAMINEN VAARA-ALUEILLA | F30: =IF(AND(D30<>"",E30<>""),D30-E30,"") | G30: 1: Antaa laukoa vapaasti; lopettaa tilanteet kesken 3: Estää laukaukset; puolustaa tilanteet loppuun 5: Erinomainen blokkaaja ja 1v1-puolustaja; kattaa kakkostolpan MV:n 1v1-tilanteissa | H30: =IF(OR(D30="1",D30="2",E30="1",E30="2",D30=1,D30=2,E30=1,E30=2),IFERROR(VLOOKUP(A30,Harjoitepankki!$A:$D,4,FALSE()),""),"")
A31: CB-P7a | C31: a. Puolusta 1v1 vaara-alueilla
A32: CB-P7b | C32: b. Prässää intensiivisesti ja estä laukaukset maalia kohti
A33: CB-P7c | C33: c. Jatka puolustamista, kunnes tilanne on ohi
A34: CB-P7d | C34: d. Kakkostolpan puolustaminen maalivahdin ollessa 1v1-tilanteessa
A35: CB-P8 | B35: Siirtymät | C35: 8. JATKOTILANTEIDEN ENNAKOINTI | F35: =IF(AND(D35<>"",E35<>""),D35-E35,"") | G35: 1: Yllättyy irtopalloista ja torjunnoista 3: Reagoi jatkotilanteisiin ajoissa 5: Ennakoi irtopallot ja pääpallokamppailujen pudotukset ennen muita | H35: =IF(OR(D35="1",D35="2",E35="1",E35="2",D35=1,D35=2,E35=1,E35=2),IFERROR(VLOOKUP(A35,Harjoitepankki!$A:$D,4,FALSE()),""),"")
A36: CB-P8a | C36: a. Ennakoi maalivahdin mahdollinen purkupallo
A37: CB-P8b | C37: b. Pudota alemmas (varmistamaan), kun toinen keskustoppari tai puolustava keskikenttäpelaaja menee pääpallo- tai ilmapallotilanteeseen pallon tullessa keskikaistaa pitkin
A38: CB-H0 | B38: Hyökkäys | C38: 0. TIEDON KERÄÄMINEN (SKANNAUS) | F38: =IF(AND(D38<>"",E38<>""),D38-E38,"") | G38: 1: Katse lukittuu palloon; vastaanotot selkä pelille; päätökset syntyvät vasta pallon kanssa 3: Skannaa säännöllisesti ennen vastaanottoa; peliasento pääosin avoin 5: Skannaa korkealla frekvenssillä myös paineessa; ratkaisu valmiina ennen palloa; peliasento avaa koko kentän | H38: =IF(OR(D38="1",D38="2",E38="1",E38="2",D38=1,D38=2,E38=1,E38=2),IFERROR(VLOOKUP(A38,Harjoitepankki!$A:$D,4,FALSE()),""),"")
A39: CB-H0a | C39: a. Diagonaalinen sijoittuminen suhteessa etu- ja takalinjoihin
A40: CB-H0b | C40: b. Avoin peliasento, joka mahdollistaa maksimaalisen tiedonkeruun
...

Sheet FB Laitapuolustaja
A1: LAITAPUOLUSTAJA (FB) – skouttaus + itsearviointi + kehityskeskustelu samalla sivulla
A2: Koodi | B2: Vyöhyke | C2: Teema / konseptit (KPI) | D2: Valm. arvio | E2: Itsearvio | F2: Ero | G2: Kriteerit 1 / 3 / 5 | H2: Harjoitesuositus (automaattinen, kun arvio 1–2) | I2: Huomiot
A3: FB-P1 | B3: RA ulkopuolella | C3: 1. PUOLUSTUSTASAPAINON YLLÄPITÄMINEN | F3: =IF(AND(D3<>"",E3<>""),D3-E3,"") | G3: 1: Jää irti linjasta; väärä syvyys; ei palauta tasapainoa tilanteen rikkoutuessa 3: Pitää linjan leveys- ja syvyystasapainon normaalitilanteissa 5: Säätää asemaansa jatkuvasti ennakoiden; korjaa linjan tasapainon ennen kuin vaara syntyy | H3: =IF(OR(D3="1",D3="2",E3="1",E3="2",D3=1,D3=2,E3=1,E3=2),IFERROR(VLOOKUP(A3,Harjoitepankki!$A:$D,4,FALSE()),""),"")
A4: FB-P1a | C4: a. Pidä puolustuslinjan tasapaino leveyssuunnassa
A5: FB-P1b | C5: b. Pidä puolustuslinjan tasapaino syvyyssuunnassa
A6: FB-P1c | C6: c. Tasapainota puolustuslinja uudelleen tilanteen rikkoutuessa
A7: FB-P2 | B7: RA ulkopuolella | C7: 2. MERKATTAVAN PELAAJAN TUNNISTAMINEN | F7: =IF(AND(D7<>"",E7<>""),D7-E7,"") | G7: 1: Kadottaa laiturinsa; katse vain pallossa; yllättyy selustaan tulevista liikkeistä 3: Pitää pallon ja vastustajan näkökentässä; tunnistaa merkattavan ja mukauttaa sijoittumistaan 5: Ennakoi vastustajan laiturin liikkeet; tiivistää oikea-aikaisesti; valpas myös oman joukkueen hyökätessä | H7: =IF(OR(D7="1",D7="2",E7="1",E7="2",D7=1,D7=2,E7=1,E7=2),IFERROR(VLOOKUP(A7,Harjoitepankki!$A:$D,4,FALSE()),""),"")
A8: FB-P2a | C8: a. Sijoitu oikeassa peliasennossa (rintamasuunta ja kehon asento siten, että pystyt reagoimaan nopeasti joka suuntaan) / pidä pallo ja vastustaja näkökentässäsi
A9: FB-P2b | C9: b. Tunnista merkattava pelaaja ja korjaa tai mukauta omaa sijoittumistasi
A10: FB-P2c | C10: c. Pienennä tilaa, kun vartioitavalla pelaajalla on mahdollisuus osallistua peliin (vastaanottaa pallon)
A11: FB-P2d | C11: d. Säilytä valppaus merkattavasta pelaajasta oman joukkueen hyökätessä
A12: FB-P3 | B12: RA ulkopuolella | C12: 3. TILAN PUOLUSTAMINEN | F12: =IF(AND(D12<>"",E12<>""),D12-E12,"") | G12: 1: Ei varmista keskustopparia; laidan selusta jää auki; syvyysjuoksut karkaavat 3: Varmistaa keskustopparia ja pudottaa vapaaseen tilaan luotettavasti 5: Lukee syvyysjuoksut aikaisin; varmistuskulmat ja -etäisyydet optimaaliset; laidan selusta ei aukea | H12: =IF(OR(D12="1",D12="2",E12="1",E12="2",D12=1,D12=2,E12=1,E12=2),IFERROR(VLOOKUP(A12,Harjoitepankki!$A:$D,4,FALSE()),""),"")
A13: FB-P3a | C13: a. Varmista keskustopparia, joka prässää pallollista pelaajaa
A14: FB-P3b | C14: b. Pudota nopeasti alemmas ennakoiden syötöt tyhjään tilaan
A15: FB-P3c | C15: c. Seuraa miesvartioinnilla hyökkääjien vapaat juoksut syvyyteen
A16: FB-P4 | B16: RA ulkopuolella | C16: 4. PALLOLLISEN PUOLUSTAMINEN | F16: =IF(AND(D16<>"",E16<>""),D16-E16,"") | G16: 1: Ohitetaan 1v1-tilanteissa; ei ohjaa vastustajaa; syöttäjä karkaa seinäsyöttöön 3: Prässää hallitusti ja ohjaa vastustajan pois vaarallisilta alueilta 5: Voittaa laidan 1v1-tilanteet toistuvasti; ohjaa vastustajan ansaan (sivurajaa/varmistusta kohti); katkaisee yhdistelyt | H16: =IF(OR(D16="1",D16="2",E16="1",E16="2",D16=1,D16=2,E16=1,E16=2),IFERROR(VLOOKUP(A16,Harjoitepankki!$A:$D,4,FALSE()),""),"")
A17: FB-P4a | C17: a. Älä anna vastustajan ohittaa itseäsi, kun prässäät pallollista pelaajaa
A18: FB-P4b | C18: b. Ohjaa vastustaja (puolustuksen kannalta) edullisille alueille
A19: FB-P4c | C19: c. Estä pelaajan eteneminen syötön jälkeen (älä päästä syöttäjää liikkeelle syöttönsä perään)
A20: FB-P5 | B20: RA sisällä | C20: 5. RANGAISTUSALUEEN VAPAUTTAMINEN | F20: =IF(AND(D20<>"",E20<>""),D20-E20,"") | G20: 1: Valuu rangaistusalueelle turhaan; jää alas purkupallojen jälkeen 3: Pysyy poissa rangaistusalueelta ja poistuu sieltä oikeissa tilanteissa 5: Ajoittaa poistumiset ja linjan nostot ennakoivasti; kommunikoi keskustoppareiden kanssa | H20: =IF(OR(D20="1",D20="2",E20="1",E20="2",D20=1,D20=2,E20=1,E20=2),IFERROR(VLOOKUP(A20,Harjoitepankki!$A:$D,4,FALSE()),""),"")
A21: FB-P5a | C21: a. Älä valu puolustamaan rangaistusalueen sisälle, kun pallo on keskikaistalla
A22: FB-P5b | C22: b. Poistu rangaistusalueelta (boksista), kun oma joukkue pystyy siivoamaan pallon pois vaara-alueelta / päätyalueelta
A23: FB-P6 | B23: RA sisällä | C23: 6. KESKITYKSEN PUOLUSTAMINEN | F23: =IF(AND(D23<>"",E23<>""),D23-E23,"") | G23: 1: Selusta aukeaa keskityksille; väärä asema keskityslinjaan nähden; kakkostolpan pelaaja unohtuu 3: Puolustaa keskitykset omalta laidaltaan ja kaventaa vastakkaiselta laidalta luotettavasti 5: Hallitsee molemmat roolit (pallonpuoleinen/vastakkainen laita); voittaa 1v1-tilanteet rangaistusalueella; pelaa irtopallot | H23: =IF(OR(D23="1",D23="2",E23="1",E23="2",D23=1,D23=2,E23=1,E23=2),IFERROR(VLOOKUP(A23,Harjoitepankki!$A:$D,4,FALSE()),""),"")
A24: FB-P6a | C24: a. Laitatilanteissa, joista pallo voidaan keskittää puolustajien selustaan (puolustuslinjan taakse), pudota asemastasi alaspäin niin nopeasti kuin mahdollista auttaaksesi joukkuetoveriasi
A25: FB-P6b | C25: b. Sijoitu keskityslinjalle (pallonpuoleinen laitapuolustaja)
A26: FB-P6c | C26: c. Puolusta miesvartioinnilla viimeistelemään tulevaa pelaajaa (vastakkaisen laidan laitapuolustaja)
A27: FB-P6d | C27: d. Jatka puolustamista, jos keskitys ylittää meidät, ja auta joukkuetovereita mahdollisissa irtopalloissa
A28: FB-P7 | B28: RA sisällä | C28: 7. PUOLUSTAMINEN VAARA-ALUEILLA | F28: =IF(AND(D28<>"",E28<>""),D28-E28,"") | G28: 1: Häviää miesvartioinnit; antaa viimeistellä vapaasti 3: Pitää miesvartiointinsa ja häiritsee viimeistelyt 5: Erinomainen 1v1-puolustaja vaara-alueilla; estää tilanteen päätökset johdonmukaisesti | H28: =IF(OR(D28="1",D28="2",E28="1",E28="2",D28=1,D28=2,E28=1,E28=2),IFERROR(VLOOKUP(A28,Harjoitepankki!$A:$D,4,FALSE()),""),"")
A29: FB-P7a | C29: a. Miesvartiointi (1v1-puolustaminen) vaara-alueilla
A30: FB-P7b | C30: b. Seuraa vastustajaa estääksesi tilanteiden päättämisen (laukaus tai viimeistely)
A31: FB-P8 | B31: Siirtymät | C31: 8. JATKOTILANTEIDEN ENNAKOINTI | F31: =IF(AND(D31<>"",E31<>""),D31-E31,"") | G31: 1: Yllättyy irtopalloista; jää katsomaan kamppailuja 3: Reagoi jatkotilanteisiin ajoissa 5: Ennakoi torjunnasta irtoavat pallot ja kamppailujen pudotukset; siirtyy keskikaistalle automaattisesti | H31: =IF(OR(D31="1",D31="2",E31="1",E31="2",D31=1,D31=2,E31=1,E31=2),IFERROR(VLOOKUP(A31,Harjoitepankki!$A:$D,4,FALSE()),""),"")
A32: FB-P8a | C32: a. Kun hyökkääjä laukoo, ennakoi maalivahdin torjunnasta irtoava pallo
A33: FB-P8b | C33: b. Kun keskustoppari tai puolustava keskikenttäpelaaja hyppää ilmapallokamppailuun vastustajan kanssa, pudota alemmas ja siirry kohti keskikaistaa
A34: FB-H0 | B34: Hyökkäys | C34: 0. TIEDON KERÄÄMINEN (SKANNAUS) | F34: =IF(AND(D34<>"",E34<>""),D34-E34,"") | G34: 1: Katse lukittuu palloon; vastaanotot suljetulla peliasennolla; ratkaisut syntyvät vasta pallon kanssa 3: Skannaa säännöllisesti ennen vastaanottoa; peliasento pääosin avoin 5: Skannaa korkealla frekvenssillä myös paineessa; ratkaisu valmiina ennen palloa; näkee sisäkaistat ja oman laidan | H34: =IF(OR(D34="1",D34="2",E34="1",E34="2",D34=1,D34=2,E34=1,E34=2),IFERROR(VLOOKUP(A34,Harjoitepankki!$A:$D,4,FALSE()),""),"")
A35: FB-H0a | C35: a. Diagonaalinen sijoittuminen suhteessa etu- ja takalinjoihin
A36: FB-H0b | C36: b. Avoin peliasento, joka mahdollistaa maksimaalisen tiedonkeruun
A37: FB-H0c | C37: c. Pään kääntäminen (skannaus) näkökentän täydentämiseksi ennen vastaanottoa ja sen aikana
A38: FB-H1 | B38: Hyökkäys | C38: 1. HYÖKKÄYSTASAPAINON YLLÄPITÄMINEN | F38: =IF(AND(D38<>"",E38<>""),D38-E38,"") | G38: 1: Nousee väärään aikaan; jättää laidan selustan auki menetyksissä 3: Pitää tasapainon joukkueen edetessä; nousut hallittuja 5: Tasapainottaa nousunsa suhteessa laituriin ja keskustoppareihin; tilanteenvaihtovalmius jatkuva | H38: =IF(OR(D38="1",D38="2",E38="1",E38="2",D38=1,D38=2,E38=1,E38=2),IFERROR(VLOOKUP(A38,Harjoitepankki!$A:$D,4,FALSE()),""),"")
A39: FB-H1a | C39: a. Tasapainota puolustuslinja leveyssuunnassa
A40: FB-H1b | C40: b. Pidä syvyystasapaino joukkueen edetessä
...

Sheet MID Keskikenttä
A1: KESKIKENTTÄPELAAJA (MID) – skouttaus + itsearviointi + kehityskeskustelu samalla sivulla
A2: Koodi | B2: Vyöhyke | C2: Teema / konseptit (KPI) | D2: Valm. arvio | E2: Itsearvio | F2: Ero | G2: Kriteerit 1 / 3 / 5 | H2: Harjoitesuositus (automaattinen, kun arvio 1–2) | I2: Huomiot
A3: MID-P1 | B3: RA ulkopuolella | C3: 1. PUOLUSTUSTASAPAINON YLLÄPITÄMINEN | F3: =IF(AND(D3<>"",E3<>""),D3-E3,"") | G3: 1: Keskusta aukeaa; etäisyydet keskikenttälinjassa väärät; ei paikkaa tilanteen rikkoutuessa 3: Pitää keskikenttälinjan tasapainon leveys- ja syvyyssuunnassa normaalitilanteissa 5: Ohjaa keskikenttälinjan etäisyyksiä jatkuvasti; sulkee keskustan ennakoivasti; korjaa myös puolustuslinjan tasapainoa tarvittaessa | H3: =IF(OR(D3="1",D3="2",E3="1",E3="2",D3=1,D3=2,E3=1,E3=2),IFERROR(VLOOKUP(A3,Harjoitepankki!$A:$D,4,FALSE()),""),"")
A4: MID-P1a | C4: a. Pidä tasapaino leveyssuunnassa keskikentän keskialueella
A5: MID-P1b | C5: b. Pidä puolustuksellinen tasapaino syvyyssuunnassa keskikentän keskialueella
A6: MID-P1c | C6: c. Tasapainota puolustuslinja uudelleen tilanteen rikkoutuessa
A7: MID-P2 | B7: RA ulkopuolella | C7: 2. MERKATTAVAN PELAAJAN TUNNISTAMINEN | F7: =IF(AND(D7<>"",E7<>""),D7-E7,"") | G7: 1: Kadottaa suoran vastustajansa; ei näe kärkeä selustassaan; prässi aukaisee syöttölinjat 3: Pitää joukkuetoverit, vastustajan ja kärjen näkökentässään; sijoittuu oikein 5: Sulkee syöttölinjat varjostamalla ennakoivasti; prässi ja sijoittuminen palvelevat joukkueen organisoitua prässiä | H7: =IF(OR(D7="1",D7="2",E7="1",E7="2",D7=1,D7=2,E7=1,E7=2),IFERROR(VLOOKUP(A7,Harjoitepankki!$A:$D,4,FALSE()),""),"")
A8: MID-P2a | C8: a. Sijoitu oikeassa peliasennossa / pidä näkökentässäsi joukkuetoverit, suora vastustajasi ja keskustassa oleva kärkipelaaja
A9: MID-P2b | C9: b. Sijoitu oikein suhteessa vastustajan sijaintiin
A10: MID-P2c | C10: c. Vähennä vastustajan syöttövaihtoehtoja organisoidussa prässissä
A11: MID-P3 | B11: RA ulkopuolella | C11: 3. TILAN PUOLUSTAMINEN | F11: =IF(AND(D11<>"",E11<>""),D11-E11,"") | G11: 1: Ei varmista linjoja; jää ylös kun syöttö ylittää linjan; syvyysjuoksut karkaavat 3: Varmistaa keskikenttä- tai puolustuslinjaa ja pudottaa luotettavasti 5: Lukee tilanteet aikaisin; varmistukset molempiin linjoihin saumattomia; seuraa juoksut laidalle asti | H11: =IF(OR(D11="1",D11="2",E11="1",E11="2",D11=1,D11=2,E11=1,E11=2),IFERROR(VLOOKUP(A11,Harjoitepankki!$A:$D,4,FALSE()),""),"")
A12: MID-P3a | C12: a. Varmistukset keskikenttälinjassa tai puolustuslinjassa pallon puolella
A13: MID-P3b | C13: b. Puolusta taaksepäin (pudota), jos syöttö ylittää oman pelilinjamme
A14: MID-P3c | C14: c. Seuraa keskikenttäpelaajan syvyysjuoksuja tämän liikkuessa laidalle
A15: MID-P4 | B15: RA ulkopuolella | C15: 4. PALLOLLISEN PUOLUSTAMINEN | F15: =IF(AND(D15<>"",E15<>""),D15-E15,"") | G15: 1: Prässi ohitetaan helposti; keskustan välitilasyötöt menevät läpi 3: Prässää hallitusti ja peittää etenemissyötöt keskustassa 5: Prässin ajoitus ja peittokulmat erinomaiset; pakottaa vastustajan taakse- tai sivusuuntaan toistuvasti | H15: =IF(OR(D15="1",D15="2",E15="1",E15="2",D15=1,D15=2,E15=1,E15=2),IFERROR(VLOOKUP(A15,Harjoitepankki!$A:$D,4,FALSE()),""),"")
A16: MID-P4a | C16: a. Prässää pallollista niin, ettei hän saa tilanteen aloitetta itselleen
A17: MID-P4b | C17: b. Estä eteenpäin suuntautuvat syötöt keskustassa
A18: MID-P5 | B18: RA sisällä | C18: 5. RANGAISTUSALUEEN VAPAUTTAMINEN | F18: =IF(AND(D18<>"",E18<>""),D18-E18,"") | G18: 1: Jää rangaistusalueelle puolustamaan turhaan 3: Poistuu rangaistusalueelta oikeissa tilanteissa 5: Ajoittaa poistumiset ennakoivasti ja komentaa linjan nostot mukana | H18: =IF(OR(D18="1",D18="2",E18="1",E18="2",D18=1,D18=2,E18=1,E18=2),IFERROR(VLOOKUP(A18,Harjoitepankki!$A:$D,4,FALSE()),""),"")
A19: MID-P5a | C19: a. Poistu rangaistusalueelta, kun pystymme siivoamaan pallon pois päätyalueelta
A20: MID-P6 | B20: RA sisällä | C20: 6. KESKITYKSEN PUOLUSTAMINEN | F20: =IF(AND(D20<>"",E20<>""),D20-E20,"") | G20: 1: Ei tunnista epätasapainoa; rangaistusalueen reuna (takaviistosyötöt) jää auki 3: Pudottautuu tarvittaessa keskustopparin rooliin; puolustaa takaviistoon tulevat pallot 5: Tunnistaa epätasapainon aikaisin ja paikkaa saumattomasti; hallitsee rangaistusalueen reunan tilanteet | H20: =IF(OR(D20="1",D20="2",E20="1",E20="2",D20=1,D20=2,E20=1,E20=2),IFERROR(VLOOKUP(A20,Harjoitepankki!$A:$D,4,FALSE()),""),"")
A21: MID-P6a | C21: a. Ota keskustopparin rooli keskityspuolustuksessa, jos puolustuslinjassa on epätasapaino
A22: MID-P6b | C22: b. Puolusta takaviistoon tulevat syötöt (rangaistusalueen reunalle), kun vastustaja saa edun päätyrajalla
A23: MID-P7 | B23: RA sisällä | C23: 7. PUOLUSTAMINEN VAARA-ALUEILLA | F23: =IF(AND(D23<>"",E23<>""),D23-E23,"") | G23: 1: Passiivinen rangaistusalueella; ei ota miesvartiointivastuuta 3: Ottaa keskustopparin tehtävät vaara-alueilla luotettavasti 5: Puolustaa vaara-alueilla kuin keskustoppari: miesvartiointi, blokit ja tilanteiden loppuun puolustaminen | H23: =IF(OR(D23="1",D23="2",E23="1",E23="2",D23=1,D23=2,E23=1,E23=2),IFERROR(VLOOKUP(A23,Harjoitepankki!$A:$D,4,FALSE()),""),"")
A24: MID-P7a | C24: a. Toimi kuten keskustoppari (miesvartiointi ja tilanteiden loppuun puolustaminen)
A25: MID-P8 | B25: Siirtymät | C25: 8. JATKOTILANTEIDEN ENNAKOINTI | F25: =IF(AND(D25<>"",E25<>""),D25-E25,"") | G25: 1: Ei katkoja; yllättyy oman joukkueen menetyksistä 3: Katkoo syöttöjä alueellaan ja reagoi menetyksiin ajoissa 5: Ennakoi sekä vastustajan syötöt että oman joukkueen menetykset; ensimmäisenä vastaprässissä | H25: =IF(OR(D25="1",D25="2",E25="1",E25="2",D25=1,D25=2,E25=1,E25=2),IFERROR(VLOOKUP(A25,Harjoitepankki!$A:$D,4,FALSE()),""),"")
A26: MID-P8a | C26: a. Ennakoi syötöt omalla pelialueellasi tai vartioimallesi pelaajalle
A27: MID-P8b | C27: b. Ennakoi pallonmenetyksen mahdollisuus oman joukkueen rakentaessa peliä
A28: MID-H0 | B28: Hyökkäys | C28: 0. TIEDON KERÄÄMINEN (SKANNAUS) | F28: =IF(AND(D28<>"",E28<>""),D28-E28,"") | G28: 1: Katse lukittuu palloon; vastaanotot suljetulla peliasennolla; ratkaisut syntyvät vasta pallon kanssa 3: Skannaa säännöllisesti ennen vastaanottoa; peliasento pääosin avoin 5: Skannaa korkealla frekvenssillä myös paineessa; pelaa yhdellä–kahdella kosketuksella eteenpäin, koska ratkaisu on valmiina | H28: =IF(OR(D28="1",D28="2",E28="1",E28="2",D28=1,D28=2,E28=1,E28=2),IFERROR(VLOOKUP(A28,Harjoitepankki!$A:$D,4,FALSE()),""),"")
A29: MID-H0a | C29: a. Diagonaalinen sijoittuminen suhteessa etu- ja takalinjoihin
A30: MID-H0b | C30: b. Avoin peliasento, joka mahdollistaa maksimaalisen tiedonkeruun
A31: MID-H0c | C31: c. Pään kääntäminen (skannaus) näkökentän täydentämiseksi ennen vastaanottoa ja sen aikana
A32: MID-H1 | B32: Hyökkäys | C32: 1. HYÖKKÄYSTASAPAINON YLLÄPITÄMINEN | F32: =IF(AND(D32<>"",E32<>""),D32-E32,"") | G32: 1: Väärällä korkeudella suhteessa palloon; samassa linjassa syöttäjän kanssa; menetys johtaa suoraan vastahyökkäykseen 3: Säilyttää tasapainoisen ja diagonaalisen sijoittumisen 5: Sijoittuminen luo jatkuvasti syöttölinjan ja turvaa samalla joukkueen tasapainon menetyksen varalta | H32: =IF(OR(D32="1",D32="2",E32="1",E32="2",D32=1,D32=2,E32=1,E32=2),IFERROR(VLOOKUP(A32,Harjoitepankki!$A:$D,4,FALSE()),""),"")
A33: MID-H1a | C33: a. Tasapainon säilyttäminen ryhmityksessä
A34: MID-H1b | C34: b. Diagonaalinen sijoittuminen suhteessa etu- ja takalinjoihin
A35: MID-H1c | C35: c. Varmista joukkueen puolustuksellinen tasapaino hyökkäyksen aikana
A36: MID-H2 | B36: Hyökkäys | C36: 2. TUKIEN TARJOAMINEN | F36: =IF(AND(D36<>"",E36<>""),D36-E36,"") | G36: 1: Piiloutuu vastustajan taakse; ei tarjoa tukea paineessa; syöttölinjat pysyvät kiinni 3: Tarjoaa tuen muodon sisällä ja takaa pelin jatkuvuuden 5: Elää jatkuvasti syöttölinjojen välissä; hätätuki aina saatavilla; avaa liikkeellään linjoja muille | H36: =IF(OR(D36="1",D36="2",E36="1",E36="2",D36=1,D36=2,E36=1,E36=2),IFERROR(VLOOKUP(A36,Harjoitepankki!$A:$D,4,FALSE()),""),"")
A37: MID-H2a | C37: a. Tarjoa tuki pelin sisällä (muodon sisässä pelaaminen)
A38: MID-H2b | C38: b. Tarjoa tuki niin, että saat edun suoraan vastustajaasi nähden
A39: MID-H2c | C39: c. Tarjoa tuki pelin jatkuvuuden takaamiseksi
A40: MID-H2d | C40: d. Tarjoa hätätuki pallolliselle paineen alla
...

Sheet AMID Kymppi
A1: HYÖKKÄÄVÄ KESKIKENTTÄPELAAJA (AMID) – skouttaus + itsearviointi + kehityskeskustelu samalla sivulla
A2: Koodi | B2: Vyöhyke | C2: Teema / konseptit (KPI) | D2: Valm. arvio | E2: Itsearvio | F2: Ero | G2: Kriteerit 1 / 3 / 5 | H2: Harjoitesuositus (automaattinen, kun arvio 1–2) | I2: Huomiot
A3: AMID-P1 | B3: RA ulkopuolella | C3: 1. PUOLUSTUSTASAPAINON YLLÄPITÄMINEN | F3: =IF(AND(D3<>"",E3<>""),D3-E3,"") | G3: 1: Irtoaa keskikenttälinjasta; jättää keskustan auki prässätessään 3: Pitää tasapainon leveys- ja syvyyssuunnassa keskialueella 5: Tasapainottaa linjaa ennakoivasti; prässin ja tasapainon valinta aina perusteltu | H3: =IF(OR(D3="1",D3="2",E3="1",E3="2",D3=1,D3=2,E3=1,E3=2),IFERROR(VLOOKUP(A3,Harjoitepankki!$A:$D,4,FALSE()),""),"")
A4: AMID-P1a | C4: a. Pidä tasapaino leveyssuunnassa keskikentän keskialueella
A5: AMID-P1b | C5: b. Pidä tasapaino syvyyssuunnassa keskikentän keskialueella
A6: AMID-P2 | B6: RA ulkopuolella | C6: 2. PUOLUSTETTAVAN PELAAJAN TUNNISTAMINEN | F6: =IF(AND(D6<>"",E6<>""),D6-E6,"") | G6: 1: Ei tunnista, ketä puolustaa; sijoittuminen avaa syöttölinjoja 3: Tunnistaa puolustusvastuunsa ja sijoittuu oikein 5: Lukee edut ja haitat välittömästi; muuttaa sijoittumistaan ennen vastustajan ratkaisua | H6: =IF(OR(D6="1",D6="2",E6="1",E6="2",D6=1,D6=2,E6=1,E6=2),IFERROR(VLOOKUP(A6,Harjoitepankki!$A:$D,4,FALSE()),""),"")
A7: AMID-P2a | C7: a. Sijoitu oikeassa peliasennossa / tunnista puolustukselliset edut ja haitat
A8: AMID-P2b | C8: b. Hyödynnä saavutettu etu ja vältä puolustuksellisesti epäedulliset tilanteet
A9: AMID-P3 | B9: RA ulkopuolella | C9: 3. TILAN PUOLUSTAMINEN | F9: =IF(AND(D9<>"",E9<>""),D9-E9,"") | G9: 1: Sisäkaistat auki; vastustaja kääntää pelin sisätuen kautta vapaasti 3: Peittää sisäkaistasyötöt ja pudottaa, kun syöttö ylittää 5: Sulkee keskustan ja käännöt johdonmukaisesti; prässin peittokulmat ohjaavat vastustajan haluttuun suuntaan | H9: =IF(OR(D9="1",D9="2",E9="1",E9="2",D9=1,D9=2,E9=1,E9=2),IFERROR(VLOOKUP(A9,Harjoitepankki!$A:$D,4,FALSE()),""),"")
A10: AMID-P3a | C10: a. Estä syötöt pelaajille, jotka pelaavat sisäkaistoilla ja meitä syvempänä
A11: AMID-P3b | C11: b. Estä vastustajan mahdollisuus kääntää peliä sisätuen kautta
A12: AMID-P3c | C12: c. Puolusta taaksepäin (pudota), kun syöttö ylittää meidät
A13: AMID-P4 | B13: RA ulkopuolella | C13: 4. PALLOLLISEN PUOLUSTAMINEN | F13: =IF(AND(D13<>"",E13<>""),D13-E13,"") | G13: 1: Prässi ohitetaan; ei reagoi menetyksiin 3: Seuraa pallollista hallitusti ja vastaprässää lähimenetykset 5: Vastaprässin ensimmäinen ja tehokkain lenkki; vie aloitteen pallolliselta toistuvasti | H13: =IF(OR(D13="1",D13="2",E13="1",E13="2",D13=1,D13=2,E13=1,E13=2),IFERROR(VLOOKUP(A13,Harjoitepankki!$A:$D,4,FALSE()),""),"")
A14: AMID-P4a | C14: a. Seuraa pallollista niin, ettei hän saa tilanteen aloitetta itselleen
A15: AMID-P4b | C15: b. Prässää välittömästi, kun joukkueemme menettää pallon lähellämme (vastaprässi)
A16: AMID-P5 | B16: RA sisällä | C16: 5. VASTAHYÖKKÄYKSIIN VALMISTAUTUMINEN | F16: =IF(AND(D16<>"",E16<>""),D16-E16,"") | G16: 1: Ei tarjoa ulospääsyä purkupalloille 3: Tarjoutuu pelattavaksi tilanteenvaihdossa 5: Käynnistää vastahyökkäykset: tuki syvyyteen ja jatkuvuus välittömästi voiton jälkeen | H16: =IF(OR(D16="1",D16="2",E16="1",E16="2",D16=1,D16=2,E16=1,E16=2),IFERROR(VLOOKUP(A16,Harjoitepankki!$A:$D,4,FALSE()),""),"")
A17: AMID-P5a* | C17: a*. Tarjoa tuki syvyyteen tilanteenvaihdon käynnistämiseksi
A18: AMID-P5b* | C18: b*. Takaa vastahyökkäyksen jatkuvuus (ensimmäinen pelattava syöttösuunta purkupallolle)
A19: AMID-P6 | B19: Siirtymät | C19: 6. JATKOTILANTEIDEN ENNAKOINTI | F19: =IF(AND(D19<>"",E19<>""),D19-E19,"") | G19: 1: Ei katkoja; irtopallot vastustajalle 3: Katkoo syöttöjä ja voittaa irtopalloja alueellaan 5: Ennakoi katkot ja irtopallot oman rangaistusalueen edustalla ennen muita | H19: =IF(OR(D19="1",D19="2",E19="1",E19="2",D19=1,D19=2,E19=1,E19=2),IFERROR(VLOOKUP(A19,Harjoitepankki!$A:$D,4,FALSE()),""),"")
A20: AMID-P6a | C20: a. Ennakoi syötöt (katkot omalla pelialueella)
A21: AMID-P6b | C21: b. Ennakoi irtopallot oman rangaistusalueen edustalla
A22: AMID-H0 | B22: Hyökkäys | C22: 0. TIEDON KERÄÄMINEN (SKANNAUS) | F22: =IF(AND(D22<>"",E22<>""),D22-E22,"") | G22: 1: Katse lukittuu palloon; vastaanotot selkä pelisuuntaan ilman tietoa 3: Skannaa säännöllisesti ennen vastaanottoa; peliasento pääosin avoin 5: Skannaa korkealla frekvenssillä ahtaimmissakin tiloissa; kääntyy paineen alla oikeaan suuntaan, koska ratkaisu on valmiina | H22: =IF(OR(D22="1",D22="2",E22="1",E22="2",D22=1,D22=2,E22=1,E22=2),IFERROR(VLOOKUP(A22,Harjoitepankki!$A:$D,4,FALSE()),""),"")
A23: AMID-H0a | C23: a. Diagonaalinen sijoittuminen suhteessa etu- ja takalinjoihin
A24: AMID-H0b | C24: b. Avoin peliasento, joka mahdollistaa maksimaalisen tiedonkeruun
A25: AMID-H0c | C25: c. Pään kääntäminen (skannaus) näkökentän täydentämiseksi ennen vastaanottoa ja sen aikana
A26: AMID-H1 | B26: Hyökkäys | C26: 1. HYÖKKÄYSTASAPAINON YLLÄPITÄMINEN | F26: =IF(AND(D26<>"",E26<>""),D26-E26,"") | G26: 1: Sisäkaistat tyhjenevät tai ruuhkautuvat hänen takiaan; liikkuu pois paikaltaan ilman perustetta 3: Tasapainottaa sisäkaistojen tilat ja säilyttää diagonaalisuuden 5: Tilojen tasapainotus palvelee koko joukkueen organisaatiota; pelipaikan jättäminen aina harkittu ja perusteltu | H26: =IF(OR(D26="1",D26="2",E26="1",E26="2",D26=1,D26=2,E26=1,E26=2),IFERROR(VLOOKUP(A26,Harjoitepankki!$A:$D,4,FALSE()),""),"")
A27: AMID-H1a | C27: a. Tasapainota sisäkaistojen tilat
A28: AMID-H1b | C28: b. Diagonaalinen sijoittuminen suhteessa etu- ja takalinjoihin
A29: AMID-H1c | C29: c. Tasapainota ensisijaisesti tilat joukkueen oikean organisaation takaamiseksi (harkitse, jätätkö oman pelipaikkasi vai et)
A30: AMID-H2 | B30: Hyökkäys | C30: 2. TUKIEN TARJOAMINEN | F30: =IF(AND(D30<>"",E30<>""),D30-E30,"") | G30: 1: Ei löydä taskuja; tuet ilman etua; ei syvyysuhkaa 3: Tarjoaa tuen linjojen välissä ja tekee syvyysjuoksuja tilanteen salliessa 5: Elää taskuissa vastustajalta piilossa; vuorottelee pudottautumisen ja syvyysjuoksujen välillä lukukelvottomasti; luo epätasapainoa jatkuvasti | H30: =IF(OR(D30="1",D30="2",E30="1",E30="2",D30=1,D30=2,E30=1,E30=2),IFERROR(VLOOKUP(A30,Harjoitepankki!$A:$D,4,FALSE()),""),"")
A31: AMID-H2a | C31: a. Tarjoa tuki vastustajan keskikenttä- ja puolustuslinjan välissä (linjojen välissä, "taskuissa")
A32: AMID-H2b | C32: b. Tarjoa tuki niin, että saat edun lähimpään vastustajaan nähden
A33: AMID-H2c | C33: c. Tarjoa tuki pelin jatkuvuuden takaamiseksi
A34: AMID-H2d | C34: d. Tarjoa hätätuki, tarvittaessa selkä kohti vastustajan maalia
A35: AMID-H2e | C35: e. Tee vapaita juoksuja syvyyteen saadaksesi edun tai luodaksesi epätasapainotilanteita
A36: AMID-H3 | B36: Hyökkäys | C36: 3. PELIN AVAAMISEN VARMISTAMINEN | F36: =IF(AND(D36<>"",E36<>""),D36-E36,"") | G36: 1: Ei osallistu avaukseen; jää linjojen väliin passiiviseksi 3: Pudottautuu tukemaan avausta oikeissa tilanteissa 5: Tunnistaa avausvaiheen tarpeet ja liikkuu tueksi oikeaan tilaan, tarvittaessa oman pelipaikan ulkopuolelle | H36: =IF(OR(D36="1",D36="2",E36="1",E36="2",D36=1,D36=2,E36=1,E36=2),IFERROR(VLOOKUP(A36,Harjoitepankki!$A:$D,4,FALSE()),""),"")
A37: AMID-H3a* | C37: a*. Tarjoa tuki toisen linjan pelaajille pudottautumalla
A38: AMID-H3b* | C38: b*. Tarjoa tuki tarvittaessa oman pelipaikan ulkopuolelta
A39: AMID-H4 | B39: Hyökkäys | C39: 4. HYÖKKÄYSPELIN ORGANISOINTI | F39: =IF(AND(D39<>"",E39<>""),D39-E39,"") | G39: 1: Peli pysähtyy; syötöt ilman etua; ei liikettä syötön jälkeen 3: Hakee etenevää peliä ja ohjaa pelin edullisille alueille 5: Viimeisen kolmanneksen pelinrakentaja: murtavat syötöt etuun, jatkuva liike, ratkaisut nopeuttavat peliä | H39: =IF(OR(D39="1",D39="2",E39="1",E39="2",D39=1,D39=2,E39=1,E39=2),IFERROR(VLOOKUP(A39,Harjoitepankki!$A:$D,4,FALSE()),""),"")
A40: AMID-H4a | C40: a. Hae tai pyri edistämään peliä
...

Sheet ST Keskushyökkääjä
A1: KESKUSHYÖKKÄÄJÄ (ST) – skouttaus + itsearviointi + kehityskeskustelu samalla sivulla
A2: Koodi | B2: Vyöhyke | C2: Teema / konseptit (KPI) | D2: Valm. arvio | E2: Itsearvio | F2: Ero | G2: Kriteerit 1 / 3 / 5 | H2: Harjoitesuositus (automaattinen, kun arvio 1–2) | I2: Huomiot
A3: ST-P1 | B3: RA ulkopuolella | C3: 1. PUOLUSTUSTASAPAINON YLLÄPITÄMINEN | F3: =IF(AND(D3<>"",E3<>""),D3-E3,"") | G3: 1: Irtoaa joukkueen puolustusryhmityksestä; väärä etäisyys keskikenttään 3: Pitää oikean etäisyyden ja sijainnin joukkueen puolustaessa 5: Sitoo puolustusryhmityksen yhteen; etäisyydet optimaaliset kaikissa vaiheissa | H3: =IF(OR(D3="1",D3="2",E3="1",E3="2",D3=1,D3=2,E3=1,E3=2),IFERROR(VLOOKUP(A3,Harjoitepankki!$A:$D,4,FALSE()),""),"")
A4: ST-P1a | C4: a. Pidä hyökkäyksen keskustan tasapaino syvyyssuunnassa
A5: ST-P1b | C5: b. Pidä hyökkäyksen keskustan tasapaino leveyssuunnassa
A6: ST-P2 | B6: RA ulkopuolella | C6: 2. MERKATTAVAN PELAAJAN TUNNISTAMINEN | F6: =IF(AND(D6<>"",E6<>""),D6-E6,"") | G6: 1: Prässi ilman suuntaa; ei yhteispeliä kärkiparin kanssa 3: Ohjaa vastustajan pelin laidalle; toimii kärkiparissa oikein 5: Prässin ohjaus tekee vastustajan avauksesta ennustettavaa; kärkiparin varmistukset saumattomia | H6: =IF(OR(D6="1",D6="2",E6="1",E6="2",D6=1,D6=2,E6=1,E6=2),IFERROR(VLOOKUP(A6,Harjoitepankki!$A:$D,4,FALSE()),""),"")
A7: ST-P2a | C7: a. Perustasapaino + vastustajan pelin ohjaaminen laidalle (yhden kärjen ryhmitys)
A8: ST-P2b | C8: b. Perustasapaino + varmistus kärkiparille (kahden kärjen ryhmitys)
